Workbook
Name Payment_Needed: "Pago necesario"
Name Reimbursement: "Reembolso"

Sheet RESUMEN
D2: Capítulo GDL
D3: Real 2025 | E3: Ppto. 2025 | F3: Real 2024 | G3: Variación Real 2024 vs Real 2025 | H3: Variación Ppto. 2025 vs Real 2025
C5: INCOME | D5: =SUM(D6,D9,D11,D13) -> 7429941.9 | E5: =SUM(E6,E9,E11,E13) -> 7988990.8 | F5: =SUM(F6,F9,F11,F13) -> 6768264 | G5: =IF((IFERROR(D5/F5,0))=0,0,(IFERROR(D5/F5,0)-1)) -> 0.097761837 | H5: =IF((IFERROR(D5/E5,0))=0,0,(IFERROR(D5/E5,0)-1)) -> -0.06997741
C6: Membership | D6: =D7+D8 -> 6021827.2 | E6: =E7+E8 -> 5769308.5 | F6: =F7+F8 -> 5730814 | G6: =IF((IFERROR(D6/F6,0))=0,0,(IFERROR(D6/F6,0)-1)) -> 0.050780435 | H6: =IF((IFERROR(D6/E6,0))=0,0,(IFERROR(D6/E6,0)-1)) -> 0.043769323
B7: 4e+20 | C7: Cuotas Netas | D7: =SUMIF('PPvsREal Summary'!$C:$C,RESUMEN!B7,'PPvsREal Summary'!$AD:$AD) -> 5813127.2 | E7: =SUMIF('PPvsREal Summary'!$C:$C,RESUMEN!B7,'PPvsREal Summary'!$AC:$AC) -> 5262808.5 | F7: 5475214 | G7: =IF((IFERROR(D7/F7,0))=0,0,(IFERROR(D7/F7,0)-1)) -> 0.061716899 | H7: =IF((IFERROR(D7/E7,0))=0,0,(IFERROR(D7/E7,0)-1)) -> 0.1045675
B8: 4.01e+20 | C8: Ingresos socios nuevos | D8: =SUMIF('PPvsREal Summary'!$C:$C,RESUMEN!B8,'PPvsREal Summary'!$AD:$AD) -> 208700 | E8: =SUMIF('PPvsREal Summary'!$C:$C,RESUMEN!B8,'PPvsREal Summary'!$AC:$AC) -> 506500 | F8: 255600 | G8: =IF((IFERROR(D8/F8,0))=0,0,(IFERROR(D8/F8,0)-1)) -> -0.18348983 | H8: =IF((IFERROR(D8/E8,0))=0,0,(IFERROR(D8/E8,0)-1)) -> -0.58795656
C9: Events | D9: =D10 -> 468782.76 | E9: =E10 -> 945000 | F9: =F10 -> 453300 | G9: =IF((IFERROR(D9/F9,0))=0,0,(IFERROR(D9/F9,0)-1)) -> 0.034155659 | H9: =IF((IFERROR(D9/E9,0))=0,0,(IFERROR(D9/E9,0)-1)) -> -0.50393359
B10: 4.05e+20 | C10: Eventos | D10: =SUMIF('PPvsREal Summary'!$C:$C,RESUMEN!B10,'PPvsREal Summary'!$AD:$AD) -> 468782.76 | E10: =SUMIF('PPvsREal Summary'!$C:$C,RESUMEN!B10,'PPvsREal Summary'!$AC:$AC) -> 945000 | F10: 453300 | G10: =IF((IFERROR(D10/F10,0))=0,0,(IFERROR(D10/F10,0)-1)) -> 0.034155659 | H10: =IF((IFERROR(D10/E10,0))=0,0,(IFERROR(D10/E10,0)-1)) -> -0.50393359
C11: Committees | D11: =D12 -> 493931.93 | E11: =E12 -> 943800 | F11: =F12 -> 272150 | G11: =IF((IFERROR(D11/F11,0))=0,0,(IFERROR(D11/F11,0)-1)) -> 0.81492534 | H11: =IF((IFERROR(D11/E11,0))=0,0,(IFERROR(D11/E11,0)-1)) -> -0.47665615
B12: 4.04e+20 | C12: Comités | D12: =SUMIF('PPvsREal Summary'!$C:$C,RESUMEN!B12,'PPvsREal Summary'!$AD:$AD) -> 493931.93 | E12: =SUMIF('PPvsREal Summary'!$C:$C,RESUMEN!B12,'PPvsREal Summary'!$AC:$AC) -> 943800 | F12: 272150 | G12: =IF((IFERROR(D12/F12,0))=0,0,(IFERROR(D12/F12,0)-1)) -> 0.81492534 | H12: =IF((IFERROR(D12/E12,0))=0,0,(IFERROR(D12/E12,0)-1)) -> -0.47665615
C13: Services to Members | D13: =D14+D15 -> 445400 | E13: =E14+E15 -> 330882.3 | F13: =F14+F15 -> 312000 | G13: =IF((IFERROR(D13/F13,0))=0,0,(IFERROR(D13/F13,0)-1)) -> 0.4275641 | H13: =IF((IFERROR(D13/E13,0))=0,0,(IFERROR(D13/E13,0)-1)) -> 0.34609799
B14: 4.03e+20 | C14: Venta Publicaciones | D14: =SUMIF('PPvsREal Summary'!$C:$C,RESUMEN!B14,'PPvsREal Summary'!$AD:$AD) -> 445400 | E14: =SUMIF('PPvsREal Summary'!$C:$C,RESUMEN!B14,'PPvsREal Summary'!$AC:$AC) -> 330882.3 | F14: 312000 | G14: =IF((IFERROR(D14/F14,0))=0,0,(IFERROR(D14/F14,0)-1)) -> 0.4275641 | H14: =IF((IFERROR(D14/E14,0))=0,0,(IFERROR(D14/E14,0)-1)) -> 0.34609799
B15: 4.08e+20 | C15: Visas | D15: =SUMIF('PPvsREal Summary'!$C:$C,RESUMEN!B15,'PPvsREal Summary'!$AD:$AD) -> 0 | E15: =SUMIF('PPvsREal Summary'!$C:$C,RESUMEN!B15,'PPvsREal Summary'!$AC:$AC) -> 0 | F15: 0 | G15: =IF((IFERROR(D15/F15,0))=0,0,(IFERROR(D15/F15,0)-1)) -> 0 | H15: =IF((IFERROR(D15/E15,0))=0,0,(IFERROR(D15/E15,0)-1)) -> 0
C16: EXPENSE | D16: =D17+D20+D22+D24+D27+D30+D31 -> 7802832.5 | E16: =E17+E20+E22+E24+E27+E30+E31 -> 8751333.5 | F16: =F17+F20+F22+F24+F27+F30+F31 -> 6326171.9 | G16: =IF((IFERROR(D16/F16,0))=0,0,(IFERROR(D16/F16,0)-1)) -> 0.23342087 | H16: =IF((IFERROR(D16/E16,0))=0,0,(IFERROR(D16/E16,0)-1)) -> -0.10838359
C17: Membership | D17: =D18+D19 -> 261568.57 | E17: =E18+E19 -> 404257.85 | F17: =F18+F19 -> 291669.44 | G17: =IF((IFERROR(D17/F17,0))=0,0,(IFERROR(D17/F17,0)-1)) -> -0.103202 | H17: =IF((IFERROR(D17/E17,0))=0,0,(IFERROR(D17/E17,0)-1)) -> -0.35296601
B18: 7.02e+20 | C18: Gastos Promoción | D18: =SUMIF('PPvsREal Summary'!$C:$C,RESUMEN!B18,'PPvsREal Summary'!$AD:$AD) -> 8094.57 | E18: =SUMIF('PPvsREal Summary'!$C:$C,RESUMEN!B18,'PPvsREal Summary'!$AC:$AC) -> 80000 | F18: 1380.9 | G18: =IF((IFERROR(D18/F18,0))=0,0,(IFERROR(D18/F18,0)-1)) -> 4.8618075 | H18: =IF((IFERROR(D18/E18,0))=0,0,(IFERROR(D18/E18,0)-1)) -> -0.89881787
B19: 5.0100101e+20 | C19: Comisiones por venta de membresías | D19: =SUMIF('PPvsREal Summary'!$C:$C,RESUMEN!B19,'PPvsREal Summary'!$AD:$AD) -> 253474 | E19: =SUMIF('PPvsREal Summary'!$C:$C,RESUMEN!B19,'PPvsREal Summary'!$AC:$AC) -> 324257.85 | F19: 290288.54 | G19: =IF((IFERROR(D19/F19,0))=0,0,(IFERROR(D19/F19,0)-1)) -> -0.12682051 | H19: =IF((IFERROR(D19/E19,0))=0,0,(IFERROR(D19/E19,0)-1)) -> -0.21829495
C20: Events | D20: =D21 -> 316129.15 | E20: =E21 -> 756045 | F20: =F21 -> 207965.48 | G20: =IF((IFERROR(D20/F20,0))=0,0,(IFERROR(D20/F20,0)-1)) -> 0.52010396 | H20: =IF((IFERROR(D20/E20,0))=0,0,(IFERROR(D20/E20,0)-1)) -> -0.58186464
B21: 7.01e+20 | C21: Costo Eventos | D21: =SUMIF('PPvsREal Summary'!$C:$C,RESUMEN!B21,'PPvsREal Summary'!$AD:$AD) -> 316129.15 | E21: =SUMIF('PPvsREal Summary'!$C:$C,RESUMEN!B21,'PPvsREal Summary'!$AC:$AC) -> 756045 | F21: 207965.48 | G21: =IF((IFERROR(D21/F21,0))=0,0,(IFERROR(D21/F21,0)-1)) -> 0.52010396 | H21: =IF((IFERROR(D21/E21,0))=0,0,(IFERROR(D21/E21,0)-1)) -> -0.58186464
C22: Committees | D22: =D23 -> 436752.04 | E22: =E23 -> 485280 | F22: =F23 -> 174406.29 | G22: =IF((IFERROR(D22/F22,0))=0,0,(IFERROR(D22/F22,0)-1)) -> 1.5042218 | H22: =IF((IFERROR(D22/E22,0))=0,0,(IFERROR(D22/E22,0)-1)) -> -0.099999918
B23: 5.02e+20 | C23: Costo comités | D23: =SUMIF('PPvsREal Summary'!$C:$C,RESUMEN!B23,'PPvsREal Summary'!$AD:$AD) -> 436752.04 | E23: =SUMIF('PPvsREal Summary'!$C:$C,RESUMEN!B23,'PPvsREal Summary'!$AC:$AC) -> 485280 | F23: 174406.29 | G23: =IF((IFERROR(D23/F23,0))=0,0,(IFERROR(D23/F23,0)-1)) -> 1.5042218 | H23: =IF((IFERROR(D23/E23,0))=0,0,(IFERROR(D23/E23,0)-1)) -> -0.099999918
C24: Services to Members | D24: =D25+D26 -> 269801.39 | E24: =E25+E26 -> 225941.15 | F24: =F25+F26 -> 188297.04 | G24: =IF((IFERROR(D24/F24,0))=0,0,(IFERROR(D24/F24,0)-1)) -> 0.43284987 | H24: =IF((IFERROR(D24/E24,0))=0,0,(IFERROR(D24/E24,0)-1)) -> 0.19412241
B25: 6.01e+20 | C25: Gastos directos de publicación | D25: =SUMIF('PPvsREal Summary'!$C:$C,RESUMEN!B25,'PPvsREal Summary'!$AD:$AD) -> 222700 | E25: =SUMIF('PPvsREal Summary'!$C:$C,RESUMEN!B25,'PPvsREal Summary'!$AC:$AC) -> 165441.15 | F25: 156000 | G25: =IF((IFERROR(D25/F25,0))=0,0,(IFERROR(D25/F25,0)-1)) -> 0.4275641 | H25: =IF((IFERROR(D25/E25,0))=0,0,(IFERROR(D25/E25,0)-1)) -> 0.34609799
B26: 9.02e+20 | C26: Gtos promoción y juntas de trabajo | D26: =SUMIF('PPvsREal Summary'!$C:$C,RESUMEN!B26,'PPvsREal Summary'!$AD:$AD) -> 47101.39 | E26: =SUMIF('PPvsREal Summary'!$C:$C,RESUMEN!B26,'PPvsREal Summary'!$AC:$AC) -> 60500 | F26: 32297.04 | G26: =IF((IFERROR(D26/F26,0))=0,0,(IFERROR(D26/F26,0)-1)) -> 0.45838102 | H26: =IF((IFERROR(D26/E26,0))=0,0,(IFERROR(D26/E26,0)-1)) -> -0.22146463
C27: Gastos Administrativos | D27: =D28+D29 -> 1078577.2 | E27: =E28+E29 -> 1255838.4 | F27: =F28+F29 -> 773979.89 | G27: =IF((IFERROR(D27/F27,0))=0,0,(IFERROR(D27/F27,0)-1)) -> 0.39354684 | H27: =IF((IFERROR(D27/E27,0))=0,0,(IFERROR(D27/E27,0)-1)) -> -0.14114966
B28: 8.01e+20 | C28: Gasto de local | D28: =SUMIF('PPvsREal Summary'!$C:$C,RESUMEN!B28,'PPvsREal Summary'!$AD:$AD) -> 230633.03 | E28: =SUMIF('PPvsREal Summary'!$C:$C,RESUMEN!B28,'PPvsREal Summary'!$AC:$AC) -> 332625.02 | F28: 109786.66 | G28: =IF((IFERROR(D28/F28,0))=0,0,(IFERROR(D28/F28,0)-1)) -> 1.1007382 | H28: =IF((IFERROR(D28/E28,0))=0,0,(IFERROR(D28/E28,0)-1)) -> -0.30662754
B29: 9.01e+20 | C29: Gastos de Administracion | D29: =SUMIF('PPvsREal Summary'!$C:$C,RESUMEN!B29,'PPvsREal Summary'!$AD:$AD) -> 847944.2 | E29: =SUMIF('PPvsREal Summary'!$C:$C,RESUMEN!B29,'PPvsREal Summary'!$AC:$AC) -> 923213.38 | F29: 664193.23 | G29: =IF((IFERROR(D29/F29,0))=0,0,(IFERROR(D29/F29,0)-1)) -> 0.27665288 | H29: =IF((IFERROR(D29/E29,0))=0,0,(IFERROR(D29/E29,0)-1)) -> -0.081529558
B30: 5.01e+20 | C30: Nómina | D30: =SUMIF('PPvsREal Summary'!$C:$C,RESUMEN!B30,'PPvsREal Summary'!$AD:$AD) -> 3313718.6 | E30: =SUMIF('PPvsREal Summary'!$C:$C,RESUMEN!B30,'PPvsREal Summary'!$AC:$AC) -> 3336915 | F30: 2638976.5 | G30: =IF((IFERROR(D30/F30,0))=0,0,(IFERROR(D30/F30,0)-1)) -> 0.25568328 | H30: =IF((IFERROR(D30/E30,0))=0,0,(IFERROR(D30/E30,0)-1)) -> -0.0069514357
B31: 9.03e+20 | C31: Gastos Corporativos | D31: =SUMIF('PPvsREal Summary'!$C:$C,RESUMEN!B31,'PPvsREal Summary'!$AD:$AD) -> 2126285.5 | E31: =SUMIF('PPvsREal Summary'!$C:$C,RESUMEN!B31,'PPvsREal Summary'!$AC:$AC) -> 2287056.1 | F31: 2050877.3 | G31: =IF((IFERROR(D31/F31,0))=0,0,(IFERROR(D31/F31,0)-1)) -> 0.036768742 | H31: =IF((IFERROR(D31/E31,0))=0,0,(IFERROR(D31/E31,0)-1)) -> -0.070295872 | I31: cuenta de gastos corporativos
C32: OPERATING RESULTS | D32: =+D5-D16 -> -372890.61 | E32: =+E5-E16 -> -762342.7 | F32: =+F5-F16 -> 442092.05 | G32: =IF((IFERROR(D32/F32,0))=0,0,(IFERROR(D32/F32,0)-1)) -> -1.8434683 | H32: =IF((IFERROR(D32/E32,0))=0,0,(IFERROR(D32/E32,0)-1)) -> -0.51086223
B33: 9.04e+20 | C33: Member Centricity | D33: =SUMIF('PPvsREal Summary'!$C:$C,RESUMEN!B33,'PPvsREal Summary'!$AD:$AD) -> 348146.81 | E33: =SUMIF('PPvsREal Summary'!$C:$C,RESUMEN!B33,'PPvsREal Summary'!$AC:$AC) -> 0 | F33: 212205.32 | G33: =IF((IFERROR(D33/F33,0))=0,0,(IFERROR(D33/F33,0)-1)) -> 0.64061302 | H33: =IF((IFERROR(D33/E33,0))=0,0,(IFERROR(D33/E33,0)-1)) -> 0
C34: Other | D34: =D35+D36 -> 128.96 | E34: =E35+E36 -> 0 | F34: =F35+F36 -> 82234.73 | G34: =IF((IFERROR(D34/F34,0))=0,0,(IFERROR(D34/F34,0)-1)) -> -0.99843181 | H34: =IF((IFERROR(D34/E34,0))=0,0,(IFERROR(D34/E34,0)-1)) -> 0
B35: 4.02e+20 | C35: Otros ingresos | D35: =SUMIF('PPvsREal Summary'!$C:$C,RESUMEN!B35,'PPvsREal Summary'!$AD:$AD) -> 128.96 | E35: =SUMIF('PPvsREal Summary'!$C:$C,RESUMEN!B35,'PPvsREal Summary'!$AC:$AC) -> 0 | F35: 81377.88 | G35: =IF((IFERROR(D35/F35,0))=0,0,(IFERROR(D35/F35,0)-1)) -> -0.99841529 | H35: =IF((IFERROR(D35/E35,0))=0,0,(IFERROR(D35/E35,0)-1)) -> 0
B36: 4.1e+20 | C36: Utilidad cambiaria | D36: =SUMIF('PPvsREal Summary'!$C:$C,RESUMEN!B36,'PPvsREal Summary'!$AD:$AD) -> 0 | E36: =SUMIF('PPvsREal Summary'!$C:$C,RESUMEN!B36,'PPvsREal Summary'!$AC:$AC) -> 0 | F36: 856.85 | G36: =IF((IFERROR(D36/F36,0))=0,0,(IFERROR(D36/F36,0)-1)) -> 0 | H36: =IF((IFERROR(D36/E36,0))=0,0,(IFERROR(D36/E36,0)-1)) -> 0
C37: NET RESULTS | D37: =D32-D33+D34 -> -720908.46 | E37: =E32-E33+E34 -> -762342.7 | F37: =F32-F33+F34 -> 312121.46 | G37: =IF((IFERROR(D37/F37,0))=0,0,(IFERROR(D37/F37,0)-1)) -> -3.3097049 | H37: =IF((IFERROR(D37/E37,0))=0,0,(IFERROR(D37/E37,0)-1)) -> -0.054351201

Sheet Gtos. Corporativos
C1: AMERICAN CHAMBER OF COMMERCE OF MEXICO, A.C.
C3: GASTOS CORPORATIVOS 2025 | D3: Real 2024 GDL | E3: Presupuesto 2024 | F3: Presupuesto 2025 | G3: Criterio | H3: Mensual
B5: 903-034-000-00 | C5: Seguro Gtos Médicos Mayores | D5: 446958.48 | E5: 559381.02 | F5: 551169.52 | G5: Costo Directo | H5: =F5/12 -> 45930.793
B6: 903-033-000-00 | C6: Seguro de Vida | D6: 24288.1 | E6: 16419.403 | F6: 25643.5 | G6: Costo Directo | H6: =F6/12 -> 2136.9583
B7: 903-002-000-00 | C7: Seguro Empresarial | D7: 18039.24 | E7: 22058.218 | F7: 20502.54 | G7: Costo Directo | H7: =F7/12 -> 1708.545
B8: 903-003-000-00 | C8: PAE | D8: 7422.69 | E8: 6898.3215 | F8: 8433.3795 | G8: Costo Directo | H8: =F8/12 -> 702.78163
B9: 903-030-000-00 | C9: Hosting /VPS | D9: 23393.39 | E9: 93489.642 | F9: 19500 | G9: 0.13 | H9: =F9/12 -> 1625
B10: 903-032-000-00 | C10: Outsourcing TI | D10: 56537.49 | E10: 63536.256 | F10: 0 | G10: 0.13 | H10: =F10/12 -> 0
B11: 903-032-000-00 | C11: Póliza soporte y mantenimiento SIA | D11: 0 | E11: 0 | F11: 56180.233 | G11: 0.13 | H11: =F11/12 -> 4681.6861
B12: 903-018-000-00 | C12: MCM/Internet/telefonía IP | D12: 117696 | E12: 118909.63 | F12: 100409.4 | G12: 0.13 | H12: =F12/12 -> 8367.45
B13: 903-023-000-00/903-031-000-00/903-035-000-00 | C13: Actualizaciones de software (COI, office, antivirus, licencias, timbres, etc) | D13: 28507.91 | E13: 26082.022 | F13: 30421.601 | G13: 0.13 | H13: =F13/12 -> 2535.1334
B14: 903-028-000-00 | C14: Licencias Google Apps | D14: 52305.06 | E14: 56337.12 | F14: 62162.1 | G14: 0.13 | H14: =F14/12 -> 5180.175
B15: 903-011-000-00 | C15: Estudio actuarial | D15: 3801.42 | E15: 3730.4299 | F15: 3243.1035 | G15: 0.13 | H15: =F15/12 -> 270.25862
B16: 903-012-000-00 | C16: Gtos Notariales | D16: 1884 | E16: 1883.52 | F16: 1606.878 | G16: 0.13 | H16: =F16/12 -> 133.9065
B17: 903-017-000-00 / 903-013-000-00 / 903-004-000-00 | C17: Honorarios Auditoría financiera, seguro social y fiscal | D17: 67863.84 | E17: 67863.814 | F17: 65005.2 | G17: 0.13 | H17: =F17/12 -> 5417.1
B18: 903-014-000-00 | C18: Registro de Marcas | D18: 5436 | E18: 5440 | F18: 6342.83 | G18: 0.13 | H18: =F18/12 -> 528.56917
B19: 903-015-000-00 | C19: Costo Anual AACCLA | D19: 51943.89 | E19: 63504 | F19: 60196.5 | G19: 0.13 | H19: =F19/12 -> 5016.375
B20: 903-022-000-00 | C20: Almacen de Archivos AAA | D20: 7264.44 | E20: 6971.9933 | F20: 4017 | G20: 0.13 | H20: =F20/12 -> 334.75
B21: 903-024-000-00 | C21: Herramientas T&IC (plataformas, créditos, etc.) | D21: 109672.75 | E21: 107635.08 | F21: 108856.37 | G21: 0.13 | H21: =F21/12 -> 9071.3641
B22: 903-005-000-00 | C22: Linkedln | D22: 53586.893 | E22: 61699.226 | F22: 71982.431 | G22: Costo Directo | H22: =F22/12 -> 5998.5359
B23: 903-005-000-00 | C23: ZOOM | D23: 9101.0766 | E23: 8964.648 | F23: 9125.5887 | G23: 0.13 | H23: =F23/12 -> 760.46573
B24: 903-016-000-00 | C24: Sueldos y Salarios VPE/Nacionales | D24: 2436719.4 | E24: 2436719.4 | F24: 2715869.4 | G24: 0.13 | H24: =F24/12 -> 226322.45
C26: TOTAL CARGOS CORPORATIVOS | D26: =SUM(D5:D24) -> 3522422.1 | E26: =SUM(E5:E24) -> 3727523.7 | F26: =SUM(F5:F24) -> 3920667.6 | H26: =SUM(H5:H24) -> 326722.3

Sheet Gtos. Corporativos (P)
C1: AMERICAN CHAMBER OF COMMERCE OF MEXICO, A.C.
C3: GASTOS CORPORATIVOS 2025 | D3: Forecast 11+1 GDL | E3: Presupuesto 2024 | F3: Presupuesto 2025 | G3: Criterio | H3: Mensual | J3: Ene. 25 | K3: Ppto. Ene. 25 | L3: Feb. 25 | M3: Ppto. Feb. 25 | N3: Mar. 25 | O3: Ppto. Mar. 25 | P3: Abr. 25 | Q3: Ppto. Abr. 25 | R3: May. 25 | S3: Ppto. May. 25 | T3: Jun. 25 | U3: Ppto. Jun.. 25 | V3: Jul. 25 | W3: Ppto. Jul. 25 | AB3: Real Acumulado 2025 | AC3: Ppto. Acumulado 2025
B5: 903-034-000-00 | C5: Seguro Gtos Médicos Mayores | D5: 459301.43 | E5: 559381.02 | F5: 551169.52 | G5: Costo Directo | H5: =F5/12 -> 45930.793 | J5: 29024.43 | K5: 45930.793 | L5: 29024.43 | M5: 45930.793 | N5: 36950.92 | O5: 45930.793 | P5: 29024.43 | Q5: 45930.793 | R5: 37048.21 | S5: 45930.793 | T5: 31699.02 | U5: 45930.793 | V5: 31699.02 | W5: =U5 -> 45930.793 | AB5: =J5+L5+N5+P5+R5+T5+V5+X5+Z5 -> 224470.46 | AC5: =K5+M5+O5+Q5+S5+U5+W5+Y5+AA5 -> 321515.55
B6: 903-033-000-00 | C6: Seguro de Vida | D6: 24033.68 | E6: 16419.403 | F6: 25643.5 | G6: Costo Directo | H6: =F6/12 -> 2136.9583 | J6: 2137 | K6: 2136.9583 | L6: 699.32 | M6: 2136.9583 | N6: 2355.08 | O6: 2136.9583 | P6: 1247.95 | Q6: 2136.9583 | R6: 1660.28 | S6: 2136.9583 | T6: 1385.39 | U6: 2136.9583 | V6: 1385.39 | W6: =U6 -> 2136.9583 | AB6: =J6+L6+N6+P6+R6+T6+V6+X6+Z6 -> 10870.41 | AC6: =K6+M6+O6+Q6+S6+U6+W6+Y6+AA6 -> 14958.708
B7: 903-002-000-00 | C7: Seguro Empresarial | D7: 18374.15 | E7: 22058.218 | F7: 20502.54 | G7: Costo Directo | H7: =F7/12 -> 1708.545 | J7: 1457 | K7: 1708.545 | L7: 1457 | M7: 1708.545 | N7: 1457 | O7: 1708.545 | P7: 1457 | Q7: 1708.545 | R7: 1457 | S7: 1708.545 | T7: 1457 | U7: 1708.545 | V7: 1457 | W7: =U7 -> 1708.545 | AB7: =J7+L7+N7+P7+R7+T7+V7+X7+Z7 -> 10199 | AC7: =K7+M7+O7+Q7+S7+U7+W7+Y7+AA7 -> 11959.815
B8: 903-003-000-00 | C8: PAE | D8: 7328.23 | E8: 6898.3215 | F8: 8433.3795 | G8: Costo Directo | H8: =F8/12 -> 702.78163 | J8: 669.32 | K8: 702.78163 | L8: 669.32 | M8: 702.78163 | N8: 669.32 | O8: 702.78163 | P8: 669.32 | Q8: 702.78163 | R8: 669.32 | S8: 702.78163 | T8: 878.08 | U8: 702.78163 | V8: 878.08 | W8: =U8 -> 702.78163 | AB8: =J8+L8+N8+P8+R8+T8+V8+X8+Z8 -> 5102.76 | AC8: =K8+M8+O8+Q8+S8+U8+W8+Y8+AA8 -> 4919.4714
B9: 903-030-000-00 | C9: Hosting /VPS | D9: 31158.5 | E9: 93489.642 | F9: 19500 | G9: 0.13 | H9: =F9/12 -> 1625 | J9: 20.87 | K9: 1625 | L9: 20.87 | M9: 1625 | N9: 20.87 | O9: 1625 | P9: 20.87 | Q9: 1625 | R9: 20.87 | S9: 1625 | T9: 20.87 | U9: 1625 | V9: 20.87 | W9: =U9 -> 1625 | AB9: =J9+L9+N9+P9+R9+T9+V9+X9+Z9 -> 146.09 | AC9: =K9+M9+O9+Q9+S9+U9+W9+Y9+AA9 -> 11375
B10: 903-032-000-00 | C10: Outsourcing TI | D10: 57091.13 | E10: 63536.256 | F10: 0 | G10: 0.13 | H10: =F10/12 -> 0 | J10: 0 | K10: 0 | L10: 0 | M10: 0 | N10: 0 | O10: 0 | P10: 0 | Q10: 0 | R10: 0 | S10: 0 | T10: 0 | U10: 0 | V10: 0 | W10: =U10 -> 0 | AB10: =J10+L10+N10+P10+R10+T10+V10+X10+Z10 -> 0 | AC10: =K10+M10+O10+Q10+S10+U10+W10+Y10+AA10 -> 0
B11: 903-032-000-00 | C11: Póliza soporte y mantenimiento SIA | D11: 0 | E11: 0 | F11: 56180.233 | G11: 0.13 | H11: =F11/12 -> 4681.6861 | J11: 0 | K11: 4681.6861 | L11: 0 | M11: 4681.6861 | N11: 0 | O11: 4681.6861 | P11: 0 | Q11: 4681.6861 | R11: 0 | S11: 4681.6861 | T11: 0 | U11: 4681.6861 | V11: 0 | W11: =U11 -> 4681.6861 | AB11: =J11+L11+N11+P11+R11+T11+V11+X11+Z11 -> 0 | AC11: =K11+M11+O11+Q11+S11+U11+W11+Y11+AA11 -> 32771.803
B12: 903-018-000-00 | C12: MCM/Internet/telefonía IP | D12: 117797.14 | E12: 118909.63 | F12: 100409.4 | G12: 0.13 | H12: =F12/12 -> 8367.45 | J12: 7969 | K12: 8367.45 | L12: 7969 | M12: 8367.45 | N12: 7969 | O12: 8367.45 | P12: 7969 | Q12: 8367.45 | R12: 7969 | S12: 8367.45 | T12: 7969 | U12: 8367.45 | V12: 7969 | W12: =U12 -> 8367.45 | AB12: =J12+L12+N12+P12+R12+T12+V12+X12+Z12 -> 55783 | AC12: =K12+M12+O12+Q12+S12+U12+W12+Y12+AA12 -> 58572.15
B13: 903-023-000-00/903-031-000-00/903-035-000-00 | C13: Actualizaciones de software (COI, office, antivirus, licencias, timbres, etc) | D13: 27997.97 | E13: 26082.022 | F13: 30421.601 | G13: 0.13 | H13: =F13/12 -> 2535.1334 | J13: 2917.4 | K13: 2535.1334 | L13: 2917.4 | M13: 2535.1334 | N13: 3001.43 | O13: 2535.1334 | P13: 3496.17 | Q13: 2535.1334 | R13: 4106.82 | S13: 2535.1334 | T13: 4000.13 | U13: 2535.1334 | V13: 4582.89 | W13: =U13 -> 2535.1334 | AB13: =J13+L13+N13+P13+R13+T13+V13+X13+Z13 -> 25022.24 | AC13: =K13+M13+O13+Q13+S13+U13+W13+Y13+AA13 -> 17745.934
B14: 903-028-000-00 | C14: Licencias Google Apps | D14: 52569.18 | E14: 56337.12 | F14: 62162.1 | G14: 0.13 | H14: =F14/12 -> 5180.175 | J14: 3578.47 | K14: 5180.175 | L14: 3578.47 | M14: 5180.175 | N14: 3578.47 | O14: 5180.175 | P14: 3578.47 | Q14: 5180.175 | R14: 5468.47 | S14: 5180.175 | T14: 3578.43 | U14: 5180.175 | V14: 4328.03 | W14: =U14 -> 5180.175 | AB14: =J14+L14+N14+P14+R14+T14+V14+X14+Z14 -> 27688.81 | AC14: =K14+M14+O14+Q14+S14+U14+W14+Y14+AA14 -> 36261.225
B15: 903-011-000-00 | C15: Estudio actuarial | D15: 3795.56 | E15: 3730.4299 | F15: 3243.1035 | G15: 0.13 | H15: =F15/12 -> 270.25862 | J15: 269.23 | K15: 270.25862 | L15: 269.23 | M15: 270.25862 | N15: 269.23 | O15: 270.25862 | P15: 269.23 | Q15: 270.25862 | R15: 269.23 | S15: 270.25862 | T15: 269.23 | U15: 270.25862 | V15: 269.23 | W15: =U15 -> 270.25862 | AB15: =J15+L15+N15+P15+R15+T15+V15+X15+Z15 -> 1884.61 | AC15: =K15+M15+O15+Q15+S15+U15+W15+Y15+AA15 -> 1891.8104
B16: 903-012-000-00 | C16: Gtos Notariales | D16: 1883.96 | E16: 1883.52 | F16: 1606.878 | G16: 0.13 | H16: =F16/12 -> 133.9065 | J16: 134 | K16: 133.9065 | L16: 134 | M16: 133.9065 | N16: 134 | O16: 133.9065 | P16: 134 | Q16: 133.9065 | R16: 134 | S16: 133.9065 | T16: 134 | U16: 133.9065 | V16: 134 | W16: =U16 -> 133.9065 | AB16: =J16+L16+N16+P16+R16+T16+V16+X16+Z16 -> 938 | AC16: =K16+M16+O16+Q16+S16+U16+W16+Y16+AA16 -> 937.3455
B17: 903-017-000-00 / 903-013-000-00 / 903-004-000-00 | C17: Honorarios Auditoría financiera, seguro social y fiscal | D17: 67863.84 | E17: 67863.814 | F17: 65005.2 | G17: 0.13 | H17: =F17/12 -> 5417.1 | J17: 5417.1 | K17: 5417.1 | L17: 5417.1 | M17: 5417.1 | N17: 5417.1 | O17: 5417.1 | P17: 5417.1 | Q17: 5417.1 | R17: 5417.1 | S17: 5417.1 | T17: 5417.1 | U17: 5417.1 | V17: 5417.1 | W17: =U17 -> 5417.1 | AB17: =J17+L17+N17+P17+R17+T17+V17+X17+Z17 -> 37919.7 | AC17: =K17+M17+O17+Q17+S17+U17+W17+Y17+AA17 -> 37919.7
B18: 903-014-000-00 | C18: Registro de Marcas | D18: 5436.33 | E18: 5440 | F18: 6342.83 | G18: 0.13 | H18: =F18/12 -> 528.56917 | J18: 529 | K18: 528.56917 | L18: 529 | M18: 528.56917 | N18: 529 | O18: 528.56917 | P18: 529 | Q18: 528.56917 | R18: 529 | S18: 528.56917 | T18: 529 | U18: 528.56917 | V18: 529 | W18: =U18 -> 528.56917 | AB18: =J18+L18+N18+P18+R18+T18+V18+X18+Z18 -> 3703 | AC18: =K18+M18+O18+Q18+S18+U18+W18+Y18+AA18 -> 3699.9842
B19: 903-015-000-00 | C19: Costo Anual AACCLA | D19: 52461.14 | E19: 63504 | F19: 60196.5 | G19: 0.13 | H19: =F19/12 -> 5016.375 | J19: 3879.49 | K19: 5016.375 | L19: 3879.49 | M19: 5016.375 | N19: 3879.49 | O19: 5016.375 | P19: 4267.44 | Q19: 5016.375 | R19: 4267.44 | S19: 5016.375 | T19: 4267.44 | U19: 5016.375 | V19: 4267.44 | W19: =U19 -> 5016.375 | AB19: =J19+L19+N19+P19+R19+T19+V19+X19+Z19 -> 28708.23 | AC19: =K19+M19+O19+Q19+S19+U19+W19+Y19+AA19 -> 35114.625
B20: 903-022-000-00 | C20: Almacen de Archivos AAA | D20: 7466.41 | E20: 6971.9933 | F20: 4017 | G20: 0.13 | H20: =F20/12 -> 334.75 | J20: 344.77 | K20: 334.75 | L20: 344.77 | M20: 334.75 | N20: 344.77 | O20: 334.75 | P20: 493.92 | Q20: 334.75 | R20: 521.29 | S20: 334.75 | T20: 305.32 | U20: 334.75 | V20: 305.32 | W20: =U20 -> 334.75 | AB20: =J20+L20+N20+P20+R20+T20+V20+X20+Z20 -> 2660.16 | AC20: =K20+M20+O20+Q20+S20+U20+W20+Y20+AA20 -> 2343.25
B21: 903-024-000-00 | C21: Herramientas T&IC (plataformas, créditos, etc.) | D21: 107191.8 | E21: 107635.08 | F21: 108856.37 | G21: 0.13 | H21: =F21/12 -> 9071.3641 | J21: 9303.57 | K21: 9071.3641 | L21: 9303.57 | M21: 9071.3641 | N21: 9303.57 | O21: 9071.3641 | P21: 9303.57 | Q21: 9071.3641 | R21: 10153.87 | S21: 9071.3641 | T21: 10153.87 | U21: 9071.3641 | V21: 10153.87 | W21: =U21 -> 9071.3641 | AB21: =J21+L21+N21+P21+R21+T21+V21+X21+Z21 -> 67675.89 | AC21: =K21+M21+O21+Q21+S21+U21+W21+Y21+AA21 -> 63499.549
B22: 903-005-000-00 | C22: Linkedln | D22: 53835.4 | E22: 61699.226 | F22: 71982.431 | G22: Costo Directo | H22: =F22/12 -> 5998.5359 | J22: 4893.1 | K22: 5998.5359 | L22: 4893.1 | M22: 5998.5359 | N22: 4893.1 | O22: 5998.5359 | P22: 4893.1 | Q22: 5998.5359 | R22: 4893.1 | S22: 5998.5359 | T22: 4893.1 | U22: 5998.5359 | V22: 4893.1 | W22: =U22 -> 5998.5359 | AB22: =J22+L22+N22+P22+R22+T22+V22+X22+Z22 -> 34251.7 | AC22: =K22+M22+O22+Q22+S22+U22+W22+Y22+AA22 -> 41989.751
B23: 903-005-000-00 | C23: ZOOM | D23: 8967.69 | E23: 8964.648 | F23: 9125.5887 | G23: 0.13 | H23: =F23/12 -> 760.46573 | J23: 715.35 | K23: 760.46573 | L23: 715.35 | M23: 760.46573 | N23: 715.35 | O23: 760.46573 | P23: 715.35 | Q23: 760.46573 | R23: 715.35 | S23: 760.46573 | T23: 715.35 | U23: 760.46573 | V23: 715.35 | W23: =U23 -> 760.46573 | AB23: =J23+L23+N23+P23+R23+T23+V23+X23+Z23 -> 5007.45 | AC23: =K23+M23+O23+Q23+S23+U23+W23+Y23+AA23 -> 5323.2601
B24: 903-016-000-00 | C24: Sueldos y Salarios VPE/Nacionales | D24: 2436719.4 | E24: 2436719.4 | F24: 2715869.4 | G24: 0.13 | H24: =F24/12 -> 226322.45 | J24: 226322 | K24: 226322.45 | L24: 226322 | M24: 226322.45 | N24: 226322 | O24: 226322.45 | P24: 226322 | Q24: 226322.45 | R24: 226322 | S24: 226322.45 | T24: 226322 | U24: 226322.45 | V24: 226322 | W24: =U24 -> 226322.45 | AB24: =J24+L24+N24+P24+R24+T24+V24+X24+Z24 -> 1584254 | AC24: =K24+M24+O24+Q24+S24+U24+W24+Y24+AA24 -> 1584257.2
C26: TOTAL CARGOS CORPORATIVOS | D26: =SUM(D5:D24) -> 3541272.9 | E26: =SUM(E5:E24) -> 3727523.7 | F26: =SUM(F5:F24) -> 3920667.6 | H26: =SUM(H5:H24) -> 326722.3 | J26: =SUM(J5:J24) -> 299581.1 | K26: =SUM(K5:K24) -> 326722.3 | L26: =SUM(L5:L24) -> 298143.42 | M26: =SUM(M5:M24) -> 326722.3 | N26: =SUM(N5:N24) -> 307809.7 | O26: =SUM(O5:O24) -> 326722.3 | P26: =SUM(P5:P24) -> 299807.92 | Q26: =SUM(Q5:Q24) -> 326722.3 | ... W26: =SUM(W5:W24) -> 326722.3 | AB26: =SUM(AB5:AB24) -> 2126285.5 | AC26: =SUM(AC5:AC24) -> 2287056.1

Sheet DN
AD1: Ppto. | AE1: Real
C2: DESARROLLO DE NEGOCIOS | D2: 45658 | E2: 45658 | F2: 45689 | G2: 45689 | H2: 45717 | I2: 45717 | J2: 45748 | K2: 45748 | L2: 45778 | M2: 45778 | N2: 45809 | O2: 45809 | P2: 45839 | Q2: 45839 | R2: 45870 | S2: 45870 | T2: 45901 | U2: 45901 | V2: 45931 | W2: 45931 | X2: 45962 | Y2: 45962 | Z2: 45992 | AA2: 45992 | AB2: 2025 | AD2: Acumulado | AE2: Acumulado
C4: Ingresos Desarrollo de Negocios
B5: 400-000-000-00 | C5: Membresías | D5: =SUM(D6:D8) -> 686830.87 | E5: =SUM(E6:E8) -> 796918.16 | F5: =SUM(F6:F8) -> 703360.05 | G5: =SUM(G6:G8) -> 827529.92 | H5: =SUM(H6:H8) -> 734319.71 | I5: =SUM(I6:I8) -> 835486.43 | J5: =SUM(J6:J8) -> 755012.55 | K5: =SUM(K6:K8) -> 828972.86 | ... R5: =SUM(R6:R8) -> 842496.92 | T5: =SUM(T6:T8) -> 880129.5 | V5: =SUM(V6:V8) -> 925545.42 | X5: =SUM(X6:X8) -> 1032212.1 | Z5: =SUM(Z6:Z8) -> 1108896.7 | AB5: =D5+F5+H5+J5+L5+N5+P5+R5+T5+V5+X5+Z5 -> 10052089 | AD5: =D5+F5+H5+J5+L5+N5+P5 -> 5262808.5 | AE5: =E5+G5+I5+K5+M5+O5+Q5 -> 5813127.2
C6: Renovaciones | D6: 557052.16 | E6: 603047.58 | F6: 571890.92 | G6: 630347.34 | H6: 560844.67 | I6: 632544.59 | J6: 561057.83 | K6: 621674.98 | L6: 547515.67 | M6: 634980.76 | N6: 536928.17 | O6: 622281.79 | P6: 542396.08 | Q6: 613596.86 | R6: 535304.83 | T6: 560153.17 | V6: 579474.42 | X6: 648224.42 | Z6: 694250 | AB6: =D6+F6+H6+J6+L6+N6+P6+R6+T6+V6+X6+Z6 -> 6895092.3 | AD6: =D6+F6+H6+J6+L6+N6+P6 -> 3877685.5 | AE6: =E6+G6+I6+K6+M6+O6+Q6 -> 4358473.9
C7: Descuentos | D7: -10205.539 | E7: -16322.5 | F7: -10222.285 | G7: -16304.42 | H7: -10123.62 | I7: -16285.75 | J7: -10140.537 | K7: -16366.01 | L7: -10148.036 | M7: -17470.17 | N7: -10253.202 | O7: -16275.35 | P7: -10586.202 | Q7: -16285.02 | R7: -10817.083 | T7: -10866.416 | V7: -10845.666 | X7: -10845.666 | Z7: -10853.333 | AB7: =D7+F7+H7+J7+L7+N7+P7+R7+T7+V7+X7+Z7 -> -125907.59 | AD7: =D7+F7+H7+J7+L7+N7+P7 -> -71679.421 | AE7: =E7+G7+I7+K7+M7+O7+Q7 -> -115309.22
C8: Socios Nuevos | D8: 139984.25 | E8: 210193.08 | F8: 141691.42 | G8: 213487 | H8: 183598.67 | I8: 219227.59 | J8: 204095.25 | K8: 223663.89 | L8: 234188.67 | M8: 215840.63 | N8: 264012.58 | O8: 246790.67 | P8: 289231.58 | Q8: 240759.68 | R8: 318009.17 | T8: 330842.75 | V8: 356916.67 | X8: 394833.33 | Z8: 425500 | AB8: =D8+F8+H8+J8+L8+N8+P8+R8+T8+V8+X8+Z8 -> 3282904.3 | AD8: =D8+F8+H8+J8+L8+N8+P8 -> 1456802.4 | AE8: =E8+G8+I8+K8+M8+O8+Q8 -> 1569962.5
B9: 401-001-000-00 | C9: Cuotas Suscripción | D9: 54000 | E9: 37200 | F9: 65000 | G9: 65500 | H9: 72500 | I9: 22500 | J9: 82000 | K9: 24500 | L9: 89500 | M9: 0 | N9: 65000 | O9: 29500 | P9: 78500 | Q9: 29500 | R9: 100500 | T9: 54000 | V9: 60000 | X9: 71000 | Z9: 65000 | AB9: =D9+F9+H9+J9+L9+N9+P9+R9+T9+V9+X9+Z9 -> 857000 | AD9: =D9+F9+H9+J9+L9+N9+P9 -> 506500 | AE9: =E9+G9+I9+K9+M9+O9+Q9 -> 208700
C10: Suma de Ingresos Desarrollo de Negocios | D10: =D5+D9 -> 740830.87 | E10: =E5+E9 -> 834118.16 | F10: =F5+F9 -> 768360.05 | G10: =G5+G9 -> 893029.92 | H10: =H5+H9 -> 806819.71 | I10: =I5+I9 -> 857986.43 | J10: =J5+J9 -> 837012.55 | K10: =K5+K9 -> 853472.86 | ... R10: =R5+R9 -> 942996.92 | T10: =T5+T9 -> 934129.5 | V10: =V5+V9 -> 985545.42 | X10: =X5+X9 -> 1103212.1 | Z10: =Z5+Z9 -> 1173896.7 | AB10: =AB5+AB9 -> 10909089 | AD10: =AD5+AD9 -> 5769308.5 | AE10: =AE5+AE9 -> 6021827.2
C12: Gastos Desarrollo de Negocios
B13: 902-002-000-00 | C13: Herramienta Sales Force | D13: 0 | E13: 0 | F13: 0 | G13: 0 | H13: 0 | I13: 0 | J13: 0 | K13: 0 | L13: 0 | M13: 0 | N13: 0 | O13: 0 | P13: 0 | Q13: 0 | R13: 0 | T13: 0 | V13: 0 | X13: 0 | Z13: 0 | AB13: =D13+F13+H13+J13+L13+N13+P13+R13+T13+V13+X13+Z13 -> 0 | AD13: =D13+F13+H13+J13+L13+N13+P13 -> 0 | AE13: =E13+G13+I13+K13+M13+O13+Q13 -> 0
B14: 501-001-009-00 | C14: Comisiones KAM´s | D14: 46322.55 | E14: 3000 | F14: 46322.55 | G14: 66863 | H14: 46322.55 | I14: 41841 | J14: 46322.55 | K14: 13745 | L14: 46322.55 | M14: 36975 | N14: 46322.55 | O14: 5400 | P14: 46322.55 | Q14: 85650 | R14: 46322.55 | T14: 46322.55 | V14: 46322.55 | X14: 46322.55 | Z14: 46322.55 | AB14: =D14+F14+H14+J14+L14+N14+P14+R14+T14+V14+X14+Z14 -> 555870.6 | AD14: =D14+F14+H14+J14+L14+N14+P14 -> 324257.85 | AE14: =E14+G14+I14+K14+M14+O14+Q14 -> 253474
B15: 702-001-000-00 | C15: Desayunos promoción - On boarding | D15: 20000 | E15: 1563.21 | F15: 0 | G15: 1815.06 | H15: 20000 | I15: 0 | J15: 0 | K15: 811.35 | L15: 20000 | M15: 0 | N15: 0 | O15: 3904.95 | P15: 20000 | Q15: 0 | R15: 0 | T15: 20000 | V15: 0 | X15: 20000 | Z15: 0 | AB15: =D15+F15+H15+J15+L15+N15+P15+R15+T15+V15+X15+Z15 -> 120000 | AD15: =D15+F15+H15+J15+L15+N15+P15 -> 80000 | AE15: =E15+G15+I15+K15+M15+O15+Q15 -> 8094.57
C16: Suma de Gastos Desarrollo de Negocios | D16: =SUM(D13:D15) -> 66322.55 | E16: =SUM(E13:E15) -> 4563.21 | F16: =SUM(F13:F15) -> 46322.55 | G16: =SUM(G13:G15) -> 68678.06 | H16: =SUM(H13:H15) -> 66322.55 | I16: =SUM(I13:I15) -> 41841 | J16: =SUM(J13:J15) -> 46322.55 | K16: =SUM(K13:K15) -> 14556.35 | ... R16: =SUM(R13:R15) -> 46322.55 | T16: =SUM(T13:T15) -> 66322.55 | V16: =SUM(V13:V15) -> 46322.55 | X16: =SUM(X13:X15) -> 66322.55 | Z16: =SUM(Z13:Z15) -> 46322.55 | AB16: =SUM(AB13:AB15) -> 675870.6 | AD16: =SUM(AD13:AD15) -> 404257.85 | AE16: =SUM(AE13:AE15) -> 261568.57
C19: Resultado Desarrollo de Negocios | D19: =+D10-D16 -> 674508.32 | E19: =+E10-E16 -> 829554.95 | F19: =+F10-F16 -> 722037.5 | G19: =+G10-G16 -> 824351.86 | H19: =+H10-H16 -> 740497.16 | I19: =+I10-I16 -> 816145.43 | J19: =+J10-J16 -> 790690 | K19: =+K10-K16 -> 838916.51 | ... R19: =+R10-R16 -> 896674.37 | T19: =+T10-T16 -> 867806.95 | V19: =+V10-V16 -> 939222.87 | X19: =+X10-X16 -> 1036889.5 | Z19: =+Z10-Z16 -> 1127574.1 | AB19: =+AB10-AB16 -> 10233218 | AD19: =+AD10-AD16 -> 5365050.6 | AE19: =+AE10-AE16 -> 5760258.7

Sheet Comités
AD1: Ppto. | AE1: Real
C2: COMITÉS Y RELACIONES EXTERNAS | D2: 45658 | E2: 45658 | F2: 45689 | G2: 45689 | H2: 45717 | I2: 45717 | J2: 45748 | K2: 45748 | L2: 45778 | M2: 45778 | N2: 45809 | O2: 45809 | P2: 45839 | Q2: 45839 | R2: 45870 | S2: 45870 | T2: 45901 | U2: 45901 | V2: 45931 | W2: 45931 | X2: 45962 | Y2: 45962 | Z2: 45992 | AA2: 45992 | AB2: 2025 | AD2: Acumulado | AE2: Acumulado
C4: Ingresos Comités
B5: 404-017-000-00 | C5: Agroindustria (Virtual ) | D5: 0 | E5: 0 | F5: 8400 | G5: 0 | H5: 0 | I5: 0 | J5: 8400 | K5: 0 | L5: 0 | M5: 0 | N5: 8400 | O5: 1120.7 | P5: 0 | Q5: 9525.95 | R5: 8400 | T5: 0 | V5: 8400 | X5: 0 | Z5: 8400 | AB5: =D5+F5+H5+J5+L5+N5+P5+R5+T5+V5+X5+Z5 -> 50400 | AD5: =D5+F5+H5+J5+L5+N5+P5 -> 25200 | AE5: =E5+G5+I5+K5+M5+O5+Q5 -> 10646.65
B6: 404-005-000-00 | C6: Asuntos Fiscales | D6: 11200 | E6: 0 | F6: 11200 | G6: 0 | H6: 11200 | I6: 0 | J6: 11200 | K6: 0 | L6: 11200 | M6: 12006.98 | N6: 11200 | O6: 1120.7 | P6: 11200 | Q6: 0 | R6: 11200 | T6: 11200 | V6: 11200 | X6: 11200 | Z6: 11200 | AB6: =D6+F6+H6+J6+L6+N6+P6+R6+T6+V6+X6+Z6 -> 134400 | AD6: =D6+F6+H6+J6+L6+N6+P6 -> 78400 | AE6: =E6+G6+I6+K6+M6+O6+Q6 -> 13127.68
B7: 404-001-000-00 | C7: Capital Humano y Asuntos Laborales | D7: 19600 | E7: 0 | F7: 19600 | G7: 0 | H7: 19600 | I7: 0 | J7: 19600 | K7: 0 | L7: =560*35 -> 19600 | M7: 5603.5 | N7: =560*35 -> 19600 | O7: 12327.7 | P7: =560*35 -> 19600 | Q7: 3922.45 | R7: =560*35 -> 19600 | T7: =560*35 -> 19600 | V7: =560*35 -> 19600 | X7: =560*35 -> 19600 | Z7: =560*35 -> 19600 | AB7: =D7+F7+H7+J7+L7+N7+P7+R7+T7+V7+X7+Z7 -> 235200 | AD7: =D7+F7+H7+J7+L7+N7+P7 -> 137200 | AE7: =E7+G7+I7+K7+M7+O7+Q7 -> 21853.65
B8: 404-003-000-00 | C8: Comercio Exterior y Logística | D8: 8400 | E8: 0 | F8: 8400 | G8: 0 | H8: 8400 | I8: 0 | J8: 8400 | K8: 0 | L8: 8400 | M8: 6724.2 | N8: 8400 | O8: 1120.7 | P8: 8400 | Q8: 2241.4 | R8: 8400 | T8: 8400 | V8: 8400 | X8: 8400 | Z8: 8400 | AB8: =D8+F8+H8+J8+L8+N8+P8+R8+T8+V8+X8+Z8 -> 100800 | AD8: =D8+F8+H8+J8+L8+N8+P8 -> 58800 | AE8: =E8+G8+I8+K8+M8+O8+Q8 -> 10086.3
B9: 404-013-000-00 | C9: Innovación y TICs | D9: 0 | E9: 0 | F9: 0 | G9: 0 | H9: 0 | I9: 0 | J9: 0 | K9: 0 | L9: 0 | M9: 2094.33 | N9: 0 | O9: 0 | P9: 0 | Q9: 0 | R9: 0 | T9: 0 | V9: 0 | X9: 0 | Z9: 0 | AB9: =D9+F9+H9+J9+L9+N9+P9+R9+T9+V9+X9+Z9 -> 0 | AD9: =D9+F9+H9+J9+L9+N9+P9 -> 0 | AE9: =E9+G9+I9+K9+M9+O9+Q9 -> 2094.33
B10: 404-007-000-00 | C10: Legalidad y Estado de Derecho | D10: 11200 | E10: 0 | F10: 11200 | G10: 0 | H10: 11200 | I10: 0 | J10: 11200 | K10: 0 | L10: 11200 | M10: 0 | N10: 11200 | O10: 0 | P10: 11200 | Q10: 0 | R10: 11200 | T10: 11200 | V10: 11200 | X10: 11200 | Z10: 11200 | AB10: =D10+F10+H10+J10+L10+N10+P10+R10+T10+V10+X10+Z10 -> 134400 | AD10: =D10+F10+H10+J10+L10+N10+P10 -> 78400 | AE10: =E10+G10+I10+K10+M10+O10+Q10 -> 0
B11: 404-016-000-00 | C11: Salud | D11: 0 | E11: 0 | F11: 0 | G11: 0 | H11: 0 | I11: 0 | J11: 0 | K11: 0 | L11: 0 | M11: 0 | N11: 0 | O11: 0 | P11: 0 | Q11: 0 | R11: 0 | T11: 0 | V11: 0 | X11: 0 | Z11: 0 | AB11: =D11+F11+H11+J11+L11+N11+P11+R11+T11+V11+X11+Z11 -> 0 | AD11: =D11+F11+H11+J11+L11+N11+P11 -> 0 | AE11: =E11+G11+I11+K11+M11+O11+Q11 -> 0
B12: 404-004-000-00 | C12: Seguridad | D12: 8400 | E12: 0 | F12: 8400 | G12: 0 | H12: 8400 | I12: 0 | J12: 8400 | K12: 0 | L12: 8400 | M12: 0 | N12: 8400 | O12: 0 | P12: 8400 | Q12: 0 | R12: 8400 | T12: 8400 | V12: 8400 | X12: 8400 | Z12: 8400 | AB12: =D12+F12+H12+J12+L12+N12+P12+R12+T12+V12+X12+Z12 -> 100800 | AD12: =D12+F12+H12+J12+L12+N12+P12 -> 58800 | AE12: =E12+G12+I12+K12+M12+O12+Q12 -> 0
C13: Sustentabilidad y Responsabilidad Social | D13: 0 | E13: 0 | F13: 0 | G13: 0 | H13: 0 | I13: 0 | J13: 0 | K13: 0 | L13: 0 | M13: 0 | N13: 0 | O13: 0 | P13: 0 | Q13: 0 | R13: 0 | T13: 0 | V13: 0 | X13: 0 | Z13: 0 | AB13: =D13+F13+H13+J13+L13+N13+P13+R13+T13+V13+X13+Z13 -> 0 | AD13: =D13+F13+H13+J13+L13+N13+P13 -> 0 | AE13: =E13+G13+I13+K13+M13+O13+Q13 -> 0
B14: 404-009-000-00 | C14: Turismo | D14: 0 | E14: 0 | F14: 0 | G14: 0 | H14: 0 | I14: 0 | J14: 0 | K14: 0 | L14: 0 | M14: 0 | N14: 0 | O14: 0 | P14: 0 | Q14: 0 | R14: 0 | T14: 0 | V14: 0 | X14: 0 | Z14: 0 | AB14: =D14+F14+H14+J14+L14+N14+P14+R14+T14+V14+X14+Z14 -> 0 | AD14: =D14+F14+H14+J14+L14+N14+P14 -> 0 | AE14: =E14+G14+I14+K14+M14+O14+Q14 -> 0
B15: 404-018-000-00 | C15: Programa de Mentoría (EWDP) | D15: 0 | E15: 0 | F15: 0 | G15: 0 | H15: 0 | I15: 0 | J15: 0 | K15: 0 | L15: 0 | M15: 65000 | N15: 162500 | O15: 195833.33 | P15: 162500 | Q15: 152499.99 | R15: 162500 | T15: 162500 | V15: 0 | X15: 0 | Z15: 0 | AB15: =D15+F15+H15+J15+L15+N15+P15+R15+T15+V15+X15+Z15 -> 650000 | AD15: =D15+F15+H15+J15+L15+N15+P15 -> 325000 | AE15: =E15+G15+I15+K15+M15+O15+Q15 -> 413333.32
C16: Suma de Ingresos Comités | D16: =SUM(D5:D15) -> 58800 | E16: =SUM(E5:E15) -> 0 | F16: =SUM(F5:F15) -> 67200 | G16: =SUM(G5:G15) -> 0 | H16: =SUM(H5:H15) -> 58800 | I16: =SUM(I5:I15) -> 0 | J16: =SUM(J5:J15) -> 67200 | K16: =SUM(K5:K15) -> 0 | ... R16: =SUM(R5:R15) -> 229700 | T16: =SUM(T5:T15) -> 221300 | V16: =SUM(V5:V15) -> 67200 | X16: =SUM(X5:X15) -> 58800 | Z16: =SUM(Z5:Z15) -> 67200 | AB16: =SUM(AB5:AB15) -> 1406000 | AD16: =SUM(AD5:AD15) -> 761800 | AE16: =SUM(AE5:AE15) -> 471141.93
C18: Gastos Comités
B19: 502-014-000-00 | C19: Agroindustria | D19: 0 | E19: 0 | F19: 6000 | G19: 0 | H19: 0 | I19: 0 | J19: 6000 | K19: 0 | L19: 0 | M19: 0 | N19: 6000 | O19: 45.56 | P19: 0 | Q19: 5651.27 | R19: 6000 | T19: 0 | V19: 6000 | X19: 0 | Z19: 6000 | AB19: =D19+F19+H19+J19+L19+N19+P19+R19+T19+V19+X19+Z19 -> 36000 | AD19: =D19+F19+H19+J19+L19+N19+P19 -> 18000 | AE19: =E19+G19+I19+K19+M19+O19+Q19 -> 5696.83
B20: 502-005-000-00 | C20: Asuntos Fiscales | D20: 8000 | E20: 0 | F20: 8000 | G20: 0 | H20: 8000 | I20: 0 | J20: 8000 | K20: 0 | L20: 8000 | M20: 10815.12 | N20: 8000 | O20: 0 | P20: 8000 | Q20: 420 | R20: 8000 | T20: 8000 | V20: 8000 | X20: 8000 | Z20: 8000 | AB20: =D20+F20+H20+J20+L20+N20+P20+R20+T20+V20+X20+Z20 -> 96000 | AD20: =D20+F20+H20+J20+L20+N20+P20 -> 56000 | AE20: =E20+G20+I20+K20+M20+O20+Q20 -> 11235.12
B21: 502-001-000-00 | C21: Capital Humano y Asuntos Laborales | D21: 0 | E21: 0 | F21: 0 | G21: 0 | H21: 0 | I21: 0 | J21: 0 | K21: 0 | L21: 0 | M21: 113.9 | N21: 0 | O21: 30001.66 | P21: 0 | Q21: 375.03 | R21: 0 | T21: 0 | V21: 0 | X21: 0 | Z21: 0 | AB21: =D21+F21+H21+J21+L21+N21+P21+R21+T21+V21+X21+Z21 -> 0 | AD21: =D21+F21+H21+J21+L21+N21+P21 -> 0 | AE21: =E21+G21+I21+K21+M21+O21+Q21 -> 30490.59
B22: 502-003-000-00 | C22: Comercio Exterior y Logística | D22: 6000 | E22: 0 | F22: 6000 | G22: 0 | H22: 6000 | I22: 768 | J22: 6000 | K22: 0 | L22: 6000 | M22: 91.12 | N22: 6000 | O22: 11512.78 | P22: 6000 | Q22: 0 | R22: 6000 | T22: 6000 | V22: 6000 | X22: 6000 | Z22: 6000 | AB22: =D22+F22+H22+J22+L22+N22+P22+R22+T22+V22+X22+Z22 -> 72000 | AD22: =D22+F22+H22+J22+L22+N22+P22 -> 42000 | AE22: =E22+G22+I22+K22+M22+O22+Q22 -> 12371.9
B23: 502-013-000-00 | C23: Innovación y TICs | D23: 0 | E23: 0 | F23: 0 | G23: 916 | H23: 0 | I23: 0 | J23: 0 | K23: 0 | L23: 0 | M23: 623.36 | N23: 0 | O23: 0 | P23: 0 | Q23: 0 | R23: 0 | T23: 0 | V23: 0 | X23: 0 | Z23: 0 | AB23: =D23+F23+H23+J23+L23+N23+P23+R23+T23+V23+X23+Z23 -> 0 | AD23: =D23+F23+H23+J23+L23+N23+P23 -> 0 | AE23: =E23+G23+I23+K23+M23+O23+Q23 -> 1539.36
B24: 502-007-000-00 | C24: Legalidad y Estado de Derecho | D24: 11200 | E24: 0 | F24: 11200 | G24: 0 | H24: 11200 | I24: 0 | J24: 11200 | K24: 0 | L24: 11200 | M24: 745.43 | N24: 11200 | O24: 0 | P24: 11200 | Q24: 0 | R24: 11200 | T24: 11200 | V24: 11200 | X24: 11200 | Z24: 11200 | AB24: =D24+F24+H24+J24+L24+N24+P24+R24+T24+V24+X24+Z24 -> 134400 | AD24: =D24+F24+H24+J24+L24+N24+P24 -> 78400 | AE24: =E24+G24+I24+K24+M24+O24+Q24 -> 745.43
B25: 502-016-000-00 | C25: Salud | D25: 0 | E25: 0 | F25: 0 | G25: 0 | H25: 0 | I25: 0 | J25: 0 | K25: 185.01 | L25: 0 | M25: 0 | N25: 0 | O25: 0 | P25: 0 | Q25: 0 | R25: 0 | T25: 0 | V25: 0 | X25: 0 | Z25: 0 | AB25: =D25+F25+H25+J25+L25+N25+P25+R25+T25+V25+X25+Z25 -> 0 | AD25: =D25+F25+H25+J25+L25+N25+P25 -> 0 | AE25: =E25+G25+I25+K25+M25+O25+Q25 -> 185.01
B26: 502-004-000-00 | C26: Seguridad | D26: 6000 | E26: 0 | F26: 6000 | G26: 0 | H26: 6000 | I26: 109.38 | J26: 6000 | K26: 0 | L26: 6000 | M26: 0 | N26: 6000 | O26: 769.91 | P26: 6000 | Q26: 0 | R26: 6000 | T26: 6000 | V26: 6000 | X26: 6000 | Z26: 6000 | AB26: =D26+F26+H26+J26+L26+N26+P26+R26+T26+V26+X26+Z26 -> 72000 | AD26: =D26+F26+H26+J26+L26+N26+P26 -> 42000 | AE26: =E26+G26+I26+K26+M26+O26+Q26 -> 879.29
B27: 502-002-000-00 | C27: Sustentabilidad y Responsabilidad Social | D27: 0 | E27: 0 | F27: 0 | G27: 0 | H27: 0 | I27: 0 | J27: 0 | K27: 0 | L27: 0 | M27: 0 | N27: 0 | O27: 0 | P27: 0 | Q27: 511.66 | R27: 0 | T27: 0 | V27: 0 | X27: 0 | Z27: 0 | AB27: =D27+F27+H27+J27+L27+N27+P27+R27+T27+V27+X27+Z27 -> 0 | AD27: =D27+F27+H27+J27+L27+N27+P27 -> 0 | AE27: =E27+G27+I27+K27+M27+O27+Q27 -> 511.66
B28: 502-009-000-00 | C28: Turismo | D28: 0 | E28: 0 | F28: 0 | G28: 0 | H28: 0 | I28: 0 | J28: 0 | K28: 0 | L28: 0 | M28: 0 | N28: 0 | O28: 0 | P28: 0 | Q28: 0 | R28: 0 | T28: 0 | V28: 0 | X28: 0 | Z28: 0 | AB28: =D28+F28+H28+J28+L28+N28+P28+R28+T28+V28+X28+Z28 -> 0 | AD28: =D28+F28+H28+J28+L28+N28+P28 -> 0 | AE28: =E28+G28+I28+K28+M28+O28+Q28 -> 0
B29: 502-017-000-00 | C29: Programa de Mentoría (EWDP) | D29: 0 | E29: 0 | F29: 0 | G29: 0 | H29: 0 | I29: 0 | J29: 0 | K29: 0 | L29: 0 | M29: 325059 | N29: 36000 | O29: 3047.95 | P29: 32000 | Q29: 3693.21 | R29: 36000 | T29: 32000 | V29: 0 | X29: 0 | Z29: 40000 | AB29: =D29+F29+H29+J29+L29+N29+P29+R29+T29+V29+X29+Z29 -> 176000 | AD29: =D29+F29+H29+J29+L29+N29+P29 -> 68000 | AE29: =E29+G29+I29+K29+M29+O29+Q29 -> 331800.16
C30: Suma de Gastos Comités | D30: =SUM(D19:D29) -> 31200 | E30: =SUM(E19:E29) -> 0 | F30: =SUM(F19:F29) -> 37200 | G30: =SUM(G19:G29) -> 916 | H30: =SUM(H19:H29) -> 31200 | I30: =SUM(I19:I29) -> 877.38 | J30: =SUM(J19:J29) -> 37200 | K30: =SUM(K19:K29) -> 185.01 | ... R30: =SUM(R19:R29) -> 73200 | T30: =SUM(T19:T29) -> 63200 | V30: =SUM(V19:V29) -> 37200 | X30: =SUM(X19:X29) -> 31200 | Z30: =SUM(Z19:Z29) -> 77200 | AB30: =SUM(AB19:AB29) -> 586400 | AD30: =SUM(AD19:AD29) -> 304400 | AE30: =SUM(AE19:AE29) -> 395455.35
C33: Resultado Comités | D33: =+D16-D30 -> 27600 | E33: =+E16-E30 -> 0 | F33: =+F16-F30 -> 30000 | G33: =+G16-G30 -> -916 | H33: =+H16-H30 -> 27600 | I33: =+I16-I30 -> -877.38 | J33: =+J16-J30 -> 30000 | K33: =+K16-K30 -> -185.01 | ... R33: =+R16-R30 -> 156500 | T33: =+T16-T30 -> 158100 | V33: =+V16-V30 -> 30000 | X33: =+X16-X30 -> 27600 | Z33: =+Z16-Z30 -> -10000 | AB33: =+AB16-AB30 -> 819600 | AD33: =+AD16-AD30 -> 457400 | AE33: =+AE16-AE30 -> 75686.58
AB35: 100301.72
C37: Instrucciones: Favor de llenar solo los espacios en blanco, lo que está sombreado en gris será llenado por AYF
C38: Nota: Los eventos y comités deberán presupuestarse al menos en punto de equilibrio.

Sheet Eventos
AD1: Ppto. | AE1: Real
C2: EVENTOS Y SERVICIOS A LA MEMBRESÍA | D2: 45658 | E2: 45658 | F2: 45689 | G2: 45689 | H2: 45717 | I2: 45717 | J2: 45748 | K2: 45748 | L2: 45778 | M2: 45778 | N2: 45809 | O2: 45809 | P2: 45839 | Q2: 45839 | R2: 45870 | S2: 45870 | T2: 45901 | U2: 45901 | V2: 45931 | W2: 45931 | X2: 45962 | Y2: 45962 | Z2: 45992 | AA2: 45992 | AB2: 2025 | AD2: Acumulado | AE2: Acumulado
C4: Ingresos Eventos
C5: Boletaje
B6: 405-012-000-00 | C6: Meet the consulate | D6: 0 | E6: 0 | F6: 0 | G6: 0 | H6: 0 | I6: 0 | J6: 0 | K6: 0 | L6: 0 | M6: 0 | N6: 0 | O6: 0 | P6: 0 | Q6: 0 | R6: 0 | T6: 0 | V6: 0 | X6: 0 | Z6: 0 | AB6: =D6+F6+H6+J6+L6+N6+P6+R6+T6+V6+X6+Z6 -> 0 | AD6: =D6+F6+H6+J6+L6+N6+P6 -> 0 | AE6: =E6+G6+I6+K6+M6+O6+Q6 -> 0
B7: 405-010-000-00 | C7: Empower Your People | D7: 0 | E7: 0 | F7: 35000 | G7: 23800 | H7: 0 | I7: 7650 | J7: 0 | K7: 3400 | L7: 0 | M7: 0 | N7: 0 | O7: 0 | P7: 0 | Q7: 0 | R7: 0 | T7: 0 | V7: 0 | X7: 0 | Z7: 0 | AB7: =D7+F7+H7+J7+L7+N7+P7+R7+T7+V7+X7+Z7 -> 35000 | AD7: =D7+F7+H7+J7+L7+N7+P7 -> 35000 | AE7: =E7+G7+I7+K7+M7+O7+Q7 -> 34850
B8: 405-007-000-00 | C8: Extend Our Reach | D8: 0 | E8: 0 | F8: 0 | G8: 0 | H8: 0 | I8: 0 | J8: 0 | K8: 0 | L8: 0 | M8: 0 | N8: 0 | O8: 0 | P8: 0 | Q8: 0 | R8: 0 | T8: 0 | V8: 0 | X8: 0 | Z8: 0 | AB8: =D8+F8+H8+J8+L8+N8+P8+R8+T8+V8+X8+Z8 -> 0 | AD8: =D8+F8+H8+J8+L8+N8+P8 -> 0 | AE8: =E8+G8+I8+K8+M8+O8+Q8 -> 0
B9: 405-012-000-00 | C9: Punto de encuentro | D9: 0 | E9: 0 | F9: 0 | G9: 0 | H9: 45000 | I9: 0 | J9: 0 | K9: 0 | L9: 0 | M9: 0 | N9: 0 | O9: 0 | P9: 0 | Q9: 0 | R9: 0 | T9: 0 | V9: 0 | X9: 0 | Z9: 0 | AB9: =D9+F9+H9+J9+L9+N9+P9+R9+T9+V9+X9+Z9 -> 45000 | AD9: =D9+F9+H9+J9+L9+N9+P9 -> 45000 | AE9: =E9+G9+I9+K9+M9+O9+Q9 -> 0
B10: 405-013-000-00 | C10: The North America Week | D10: 0 | E10: 0 | F10: 0 | G10: 0 | H10: 0 | I10: 0 | J10: 55000 | K10: 0 | L10: 0 | M10: 0 | N10: 0 | O10: 20200 | P10: 0 | Q10: 6800 | R10: 0 | T10: 0 | V10: 0 | X10: 0 | Z10: 0 | AB10: =D10+F10+H10+J10+L10+N10+P10+R10+T10+V10+X10+Z10 -> 55000 | AD10: =D10+F10+H10+J10+L10+N10+P10 -> 55000 | AE10: =E10+G10+I10+K10+M10+O10+Q10 -> 27000
B11: 405-007-000-00 | C11: Reunion de Directores | D11: 0 | E11: 0 | F11: 0 | G11: 0 | H11: 0 | I11: 0 | J11: 0 | K11: 0 | L11: 50000 | M11: 0 | N11: 0 | O11: 0 | P11: 0 | Q11: 0 | R11: 0 | T11: 0 | V11: 0 | X11: 0 | Z11: 0 | AB11: =D11+F11+H11+J11+L11+N11+P11+R11+T11+V11+X11+Z11 -> 50000 | AD11: =D11+F11+H11+J11+L11+N11+P11 -> 50000 | AE11: =E11+G11+I11+K11+M11+O11+Q11 -> 0
B12: 405-012-000-00 | C12: Jalisco Travel Fest | D12: 0 | E12: 0 | F12: 0 | G12: 0 | H12: 0 | I12: 0 | J12: 0 | K12: 0 | L12: 0 | M12: 0 | N12: 70000 | O12: 0 | P12: 0 | Q12: 0 | R12: 0 | T12: 0 | V12: 0 | X12: 0 | Z12: 0 | AB12: =D12+F12+H12+J12+L12+N12+P12+R12+T12+V12+X12+Z12 -> 70000 | AD12: =D12+F12+H12+J12+L12+N12+P12 -> 70000 | AE12: =E12+G12+I12+K12+M12+O12+Q12 -> 0
B13: 405-008-000-00 | C13: Secretarias | D13: 0 | E13: 0 | F13: 0 | G13: 0 | H13: 0 | I13: 0 | J13: 0 | K13: 0 | L13: 0 | M13: 0 | N13: 0 | O13: 0 | P13: 0 | Q13: 0 | R13: 0 | T13: 0 | V13: 0 | X13: 0 | Z13: 0 | AB13: =D13+F13+H13+J13+L13+N13+P13+R13+T13+V13+X13+Z13 -> 0 | AD13: =D13+F13+H13+J13+L13+N13+P13 -> 0 | AE13: =E13+G13+I13+K13+M13+O13+Q13 -> 0
B14: 405-003-000-00 | C14: Foros (Economico, Jalisco Visión, etc.) | D14: 0 | E14: 42382.76 | F14: 0 | G14: 17850 | H14: 0 | I14: 850 | J14: 0 | K14: 0 | L14: 0 | M14: 0 | N14: 0 | O14: 0 | P14: 0 | Q14: 0 | R14: 45000 | T14: 0 | V14: 0 | X14: 0 | Z14: 0 | AB14: =D14+F14+H14+J14+L14+N14+P14+R14+T14+V14+X14+Z14 -> 45000 | AD14: =D14+F14+H14+J14+L14+N14+P14 -> 0 | AE14: =E14+G14+I14+K14+M14+O14+Q14 -> 61082.76
B15: 405-009-000-00 | C15: Cumbre Empresarios | D15: 0 | E15: 0 | F15: 0 | G15: 0 | H15: 0 | I15: 0 | J15: 0 | K15: 0 | L15: 0 | M15: 0 | N15: 0 | O15: 0 | P15: 0 | Q15: 0 | R15: 0 | T15: 210000 | V15: 0 | X15: 0 | Z15: 0 | AB15: =D15+F15+H15+J15+L15+N15+P15+R15+T15+V15+X15+Z15 -> 210000 | AD15: =D15+F15+H15+J15+L15+N15+P15 -> 0 | AE15: =E15+G15+I15+K15+M15+O15+Q15 -> 0
B16: 405-001-000-00 | C16: Torneo Golf | D16: 0 | E16: 0 | F16: 0 | G16: 0 | H16: 0 | I16: 0 | J16: 0 | K16: 0 | L16: 0 | M16: 0 | N16: 0 | O16: 0 | P16: 0 | Q16: 0 | R16: 0 | T16: 0 | V16: 480000 | X16: 0 | Z16: 0 | AB16: =D16+F16+H16+J16+L16+N16+P16+R16+T16+V16+X16+Z16 -> 480000 | AD16: =D16+F16+H16+J16+L16+N16+P16 -> 0 | AE16: =E16+G16+I16+K16+M16+O16+Q16 -> 0
B17: 405-002-000-00 | C17: Asamblea Anual | D17: 0 | E17: 0 | F17: 0 | G17: 0 | H17: 0 | I17: 0 | J17: 0 | K17: 0 | L17: 0 | M17: 0 | N17: 0 | O17: 0 | P17: 0 | Q17: 0 | R17: 0 | T17: 0 | V17: 0 | X17: 300000 | Z17: 0 | AB17: =D17+F17+H17+J17+L17+N17+P17+R17+T17+V17+X17+Z17 -> 300000 | AD17: =D17+F17+H17+J17+L17+N17+P17 -> 0 | AE17: =E17+G17+I17+K17+M17+O17+Q17 -> 0
C18: Ingresos Boletaje | D18: =SUM(D6:D17) -> 0 | E18: =SUM(E6:E17) -> 42382.76 | F18: =SUM(F6:F17) -> 35000 | G18: =SUM(G6:G17) -> 41650 | H18: =SUM(H6:H17) -> 45000 | I18: =SUM(I6:I17) -> 8500 | J18: =SUM(J6:J17) -> 55000 | K18: =SUM(K6:K17) -> 3400 | ... R18: =SUM(R6:R17) -> 45000 | T18: =SUM(T6:T17) -> 210000 | V18: =SUM(V6:V17) -> 480000 | X18: =SUM(X6:X17) -> 300000 | Z18: =SUM(Z6:Z17) -> 0 | AB18: =SUM(AB6:AB17) -> 1290000 | AD18: =SUM(AD6:AD17) -> 255000 | AE18: =SUM(AE6:AE17) -> 122932.76
C20: Patrocinios
B21: 405-012-000-00 | C21: Meet the consulate | D21: 60000 | E21: 0 | F21: 0 | G21: 0 | H21: 0 | I21: 0 | J21: 0 | K21: 0 | L21: 0 | M21: 0 | N21: 0 | O21: 0 | P21: 0 | Q21: 0 | R21: 0 | T21: 0 | V21: 0 | X21: 0 | Z21: 0 | AB21: =D21+F21+H21+J21+L21+N21+P21+R21+T21+V21+X21+Z21 -> 60000 | AD21: =D21+F21+H21+J21+L21+N21+P21 -> 60000 | AE21: =E21+G21+I21+K21+M21+O21+Q21 -> 0
B22: 405-010-000-00 | C22: Empower Your People | D22: 0 | E22: 0 | F22: 35000 | G22: 50000 | H22: 0 | I22: 0 | J22: 0 | K22: 0 | L22: 0 | M22: 0 | N22: 0 | O22: 850 | P22: 0 | Q22: 0 | R22: 0 | T22: 0 | V22: 0 | X22: 0 | Z22: 0 | AB22: =D22+F22+H22+J22+L22+N22+P22+R22+T22+V22+X22+Z22 -> 35000 | AD22: =D22+F22+H22+J22+L22+N22+P22 -> 35000 | AE22: =E22+G22+I22+K22+M22+O22+Q22 -> 50850
B23: 405-007-000-00 | C23: Extend Our Reach | D23: 0 | E23: 0 | F23: 25000 | G23: 0 | H23: 0 | I23: 0 | J23: 25000 | K23: 0 | L23: 0 | M23: 0 | N23: 25000 | O23: 0 | P23: 0 | Q23: 0 | R23: 0 | T23: 25000 | AB23: =D23+F23+H23+J23+L23+N23+P23+R23+T23+V23+X23+Z23 -> 100000 | AD23: =D23+F23+H23+J23+L23+N23+P23 -> 75000 | AE23: =E23+G23+I23+K23+M23+O23+Q23 -> 0
B24: 405-012-000-00 | C24: Punto de encuentro | D24: 0 | E24: 0 | F24: 0 | G24: 0 | H24: 35000 | I24: 0 | J24: 0 | K24: 0 | L24: 0 | M24: 0 | N24: 0 | O24: 0 | P24: 0 | Q24: 0 | R24: 0 | T24: 0 | V24: 0 | X24: 0 | Z24: 0 | AB24: =D24+F24+H24+J24+L24+N24+P24+R24+T24+V24+X24+Z24 -> 35000 | AD24: =D24+F24+H24+J24+L24+N24+P24 -> 35000 | AE24: =E24+G24+I24+K24+M24+O24+Q24 -> 0
B25: 405-013-000-00 | C25: The North America Week | D25: 0 | E25: 0 | F25: 0 | G25: 0 | H25: 0 | I25: 0 | J25: 180000 | K25: 0 | L25: 0 | M25: 0 | N25: 0 | O25: 140000 | P25: 0 | Q25: 40000 | R25: 0 | T25: 0 | V25: 0 | X25: 0 | Z25: 0 | AB25: =D25+F25+H25+J25+L25+N25+P25+R25+T25+V25+X25+Z25 -> 180000 | AD25: =D25+F25+H25+J25+L25+N25+P25 -> 180000 | AE25: =E25+G25+I25+K25+M25+O25+Q25 -> 180000
B26: 405-007-000-00 | C26: Reunion de Directores | D26: 0 | E26: 0 | F26: 0 | G26: 0 | H26: 0 | I26: 0 | J26: 0 | K26: 0 | L26: 100000 | M26: 0 | N26: 0 | O26: 0 | P26: 0 | Q26: 0 | R26: 0 | T26: 0 | V26: 0 | X26: 0 | Z26: 0 | AB26: =D26+F26+H26+J26+L26+N26+P26+R26+T26+V26+X26+Z26 -> 100000 | AD26: =D26+F26+H26+J26+L26+N26+P26 -> 100000 | AE26: =E26+G26+I26+K26+M26+O26+Q26 -> 0
B27: 405-012-000-00 | C27: Jalisco Travel Fest | D27: 0 | E27: 0 | F27: 0 | G27: 0 | H27: 0 | I27: 0 | J27: 0 | K27: 0 | L27: 0 | M27: 80000 | N27: 120000 | O27: 0 | P27: 0 | Q27: 0 | R27: 0 | T27: 0 | V27: 0 | X27: 0 | Z27: 0 | AB27: =D27+F27+H27+J27+L27+N27+P27+R27+T27+V27+X27+Z27 -> 120000 | AD27: =D27+F27+H27+J27+L27+N27+P27 -> 120000 | AE27: =E27+G27+I27+K27+M27+O27+Q27 -> 80000
B28: 405-008-000-00 | C28: Secretarias | D28: 0 | E28: 0 | F28: 0 | G28: 0 | H28: 0 | I28: 0 | J28: 0 | K28: 0 | L28: 0 | M28: 0 | N28: 0 | O28: 0 | P28: 85000 | Q28: 0 | R28: 0 | T28: 0 | V28: 0 | X28: 0 | Z28: 0 | AB28: =D28+F28+H28+J28+L28+N28+P28+R28+T28+V28+X28+Z28 -> 85000 | AD28: =D28+F28+H28+J28+L28+N28+P28 -> 85000 | AE28: =E28+G28+I28+K28+M28+O28+Q28 -> 0
B29: 405-003-000-00 | C29: Foros (Economico, Jalisco Visión, etc.) | D29: 0 | E29: 0 | F29: 0 | G29: 35000 | H29: 0 | I29: 0 | J29: 0 | K29: 0 | L29: 0 | M29: 0 | N29: 0 | O29: 0 | P29: 0 | Q29: 0 | R29: 95000 | T29: 0 | V29: 0 | X29: 0 | Z29: 0 | AB29: =D29+F29+H29+J29+L29+N29+P29+R29+T29+V29+X29+Z29 -> 95000 | AD29: =D29+F29+H29+J29+L29+N29+P29 -> 0 | AE29: =E29+G29+I29+K29+M29+O29+Q29 -> 35000
B30: 405-009-000-00 | C30: Cumbre Empresarios | D30: 0 | E30: 0 | F30: 0 | G30: 0 | H30: 0 | I30: 0 | J30: 0 | K30: 0 | L30: 0 | M30: 0 | N30: 0 | O30: 0 | P30: 0 | Q30: 0 | R30: 0 | T30: 650000 | V30: 0 | X30: 0 | Z30: 0 | AB30: =D30+F30+H30+J30+L30+N30+P30+R30+T30+V30+X30+Z30 -> 650000 | AD30: =D30+F30+H30+J30+L30+N30+P30 -> 0 | AE30: =E30+G30+I30+K30+M30+O30+Q30 -> 0
B31: 405-001-000-00 | C31: Torneo Golf | D31: 0 | E31: 0 | F31: 0 | G31: 0 | H31: 0 | I31: 0 | J31: 0 | K31: 0 | L31: 0 | M31: 0 | N31: 0 | O31: 0 | P31: 0 | Q31: 0 | R31: 0 | T31: 0 | V31: 550000 | X31: 0 | Z31: 0 | AB31: =D31+F31+H31+J31+L31+N31+P31+R31+T31+V31+X31+Z31 -> 550000 | AD31: =D31+F31+H31+J31+L31+N31+P31 -> 0 | AE31: =E31+G31+I31+K31+M31+O31+Q31 -> 0
B32: 405-002-000-00 | C32: Asamblea Anual | D32: 0 | E32: 0 | F32: 0 | G32: 0 | H32: 0 | I32: 0 | J32: 0 | K32: 0 | L32: 0 | M32: 0 | N32: 0 | O32: 0 | P32: 0 | Q32: 0 | R32: 0 | T32: 0 | V32: 0 | X32: 800000 | Z32: 0 | AB32: =D32+F32+H32+J32+L32+N32+P32+R32+T32+V32+X32+Z32 -> 800000 | AD32: =D32+F32+H32+J32+L32+N32+P32 -> 0 | AE32: =E32+G32+I32+K32+M32+O32+Q32 -> 0
C33: Ingresos Patrocinios | D33: =SUM(D21:D32) -> 60000 | E33: =SUM(E21:E32) -> 0 | F33: =SUM(F21:F32) -> 60000 | G33: =SUM(G21:G32) -> 85000 | H33: =SUM(H21:H32) -> 35000 | I33: =SUM(I21:I32) -> 0 | J33: =SUM(J21:J32) -> 205000 | K33: =SUM(K21:K32) -> 0 | ... R33: =SUM(R21:R32) -> 95000 | T33: =SUM(T21:T32) -> 675000 | V33: =SUM(V21:V32) -> 550000 | X33: =SUM(X21:X32) -> 800000 | Z33: =SUM(Z21:Z32) -> 0 | AB33: =SUM(AB21:AB32) -> 2810000 | AD33: =SUM(AD21:AD32) -> 690000 | AE33: =SUM(AE21:AE32) -> 345850
C35: Suma Ingresos Eventos | D35: =+D18+D33 -> 60000 | E35: =+E18+E33 -> 42382.76 | F35: =+F18+F33 -> 95000 | G35: =+G18+G33 -> 126650 | H35: =+H18+H33 -> 80000 | I35: =+I18+I33 -> 8500 | J35: =+J18+J33 -> 260000 | K35: =+K18+K33 -> 3400 | ... R35: =+R18+R33 -> 140000 | T35: =+T18+T33 -> 885000 | V35: =+V18+V33 -> 1030000 | X35: =+X18+X33 -> 1100000 | Z35: =+Z18+Z33 -> 0 | AB35: =+AB18+AB33 -> 4100000 | AD35: =+AD18+AD33 -> 945000 | AE35: =+AE18+AE33 -> 468782.76
C37: Costos y Gastos Eventos
B38: 701-010-000-00 | C38: Meet the consulate | D38: 40000 | E38: 0 | F38: 53045 | G38: 0 | H38: 0 | I38: 14340 | J38: 0 | K38: 0 | L38: 0 | N38: 0 | O38: 0 | P38: 0 | Q38: 0 | R38: 0 | T38: 0 | V38: 0 | X38: 0 | Z38: 0 | AB38: =D38+F38+H38+J38+L38+N38+P38+R38+T38+V38+X38+Z38 -> 93045 | AD38: =D38+F38+H38+J38+L38+N38+P38 -> 93045 | AE38: =E38+G38+I38+K38+M38+O38+Q38 -> 14340
B39: 701-014-000-00 | C39: Empower Your People | D39: 0 | E39: 0 | F39: 38000 | G39: 46790.9 | H39: 0 | I39: -517.24 | J39: 0 | K39: 0 | L39: 0 | M39: 0 | N39: 0 | O39: 0 | P39: 0 | Q39: 0 | R39: 0 | T39: 0 | V39: 0 | X39: 0 | Z39: 0 | AB39: =D39+F39+H39+J39+L39+N39+P39+R39+T39+V39+X39+Z39 -> 38000 | AD39: =D39+F39+H39+J39+L39+N39+P39 -> 38000 | AE39: =E39+G39+I39+K39+M39+O39+Q39 -> 46273.66
B40: 701-009-000-00 | C40: Extend Our Reach | D40: 0 | E40: 0 | F40: 60000 | G40: 0 | H40: 0 | I40: 0 | J40: 60000 | K40: 0 | L40: 0 | M40: 1419.03 | N40: 60000 | O40: 0 | P40: 0 | Q40: 1857.23 | R40: 0 | T40: 60000 | V40: 0 | X40: 0 | Z40: 0 | AB40: =D40+F40+H40+J40+L40+N40+P40+R40+T40+V40+X40+Z40 -> 240000 | AD40: =D40+F40+H40+J40+L40+N40+P40 -> 180000 | AE40: =E40+G40+I40+K40+M40+O40+Q40 -> 3276.26
B41: 701-010-000-00 | C41: Punto de encuentro | D41: 0 | E41: 0 | G41: 0 | H41: 35000 | I41: 0 | J41: 0 | K41: 0 | L41: 0 | M41: 0 | N41: 0 | O41: 0 | P41: 0 | Q41: 0 | R41: 0 | T41: 0 | V41: 0 | X41: 0 | Z41: 0 | AB41: =D41+F41+H41+J41+L41+N41+P41+R41+T41+V41+X41+Z41 -> 35000 | AD41: =D41+F41+H41+J41+L41+N41+P41 -> 35000 | AE41: =E41+G41+I41+K41+M41+O41+Q41 -> 0
B42: 701-012-000-00 | C42: The North America Week | D42: 0 | E42: 0 | F42: 0 | G42: 0 | H42: 0 | I42: 0 | J42: 130000 | K42: 0 | L42: 0 | M42: 0 | N42: 0 | O42: 67650.68 | P42: 0 | Q42: 68842.52 | R42: 0 | T42: 0 | V42: 0 | X42: 0 | Z42: 0 | AB42: =D42+F42+H42+J42+L42+N42+P42+R42+T42+V42+X42+Z42 -> 130000 | AD42: =D42+F42+H42+J42+L42+N42+P42 -> 130000 | AE42: =E42+G42+I42+K42+M42+O42+Q42 -> 136493.2
B43: 701-009-000-00 | C43: Reunion de Directores | D43: 0 | E43: 0 | F43: 0 | G43: 0 | H43: 0 | I43: 0 | J43: 0 | K43: 0 | L43: 100000 | M43: 0 | N43: 0 | O43: 0 | P43: 0 | Q43: 0 | R43: 0 | T43: 0 | V43: 0 | X43: 0 | Z43: 0 | AB43: =D43+F43+H43+J43+L43+N43+P43+R43+T43+V43+X43+Z43 -> 100000 | AD43: =D43+F43+H43+J43+L43+N43+P43 -> 100000 | AE43: =E43+G43+I43+K43+M43+O43+Q43 -> 0
B44: 701-010-000-00 | C44: Jalisco Travel Fest | D44: 0 | E44: 0 | F44: 0 | G44: 0 | H44: 0 | I44: 0 | J44: 0 | K44: 0 | L44: 0 | M44: 10309.84 | N44: 125000 | O44: 0 | P44: 0 | Q44: 0 | R44: 0 | T44: 0 | V44: 0 | X44: 0 | Z44: 0 | AB44: =D44+F44+H44+J44+L44+N44+P44+R44+T44+V44+X44+Z44 -> 125000 | AD44: =D44+F44+H44+J44+L44+N44+P44 -> 125000 | AE44: =E44+G44+I44+K44+M44+O44+Q44 -> 10309.84
...

Sheet Dirección
AD1: Ppto. | AE1: Real
C2: DIRECCIÓN CAPÍTULO | D2: 45658 | E2: 45658 | F2: 45689 | G2: 45689 | H2: 45717 | I2: 45717 | J2: 45748 | K2: 45748 | L2: 45778 | M2: 45778 | N2: 45809 | O2: 45809 | P2: 45839 | Q2: 45839 | R2: 45870 | S2: 45870 | T2: 45901 | U2: 45901 | V2: 45931 | W2: 45931 | X2: 45962 | Y2: 45962 | Z2: 45992 | AA2: 45992 | AB2: 2025 | AD2: Acumulado | AE2: Acumulado
C4: Ingresos CE/Board
B5: 404-006-000-00 | C5: Board Of Directors | D5: =650*25 -> 16250 | E5: 0 | F5: 16250 | G5: 0 | H5: 16250 | I5: 0 | J5: 16250 | K5: 0 | L5: =650*25 -> 16250 | M5: 0 | N5: =650*25 -> 16250 | O5: 0 | P5: =650*25 -> 16250 | Q5: 0 | R5: =650*25 -> 16250 | T5: =650*25 -> 16250 | V5: =650*25 -> 16250 | X5: =650*25 -> 16250 | Z5: =650*25 -> 16250 | AB5: =D5+F5+H5+J5+L5+N5+P5+R5+T5+V5+X5+Z5 -> 195000 | AD5: =D5+F5+H5+J5+L5+N5+P5 -> 113750 | AE5: =E5+G5+I5+K5+M5+O5+Q5 -> 0
B6: 404-011-000-00 | C6: Executive Committee | D6: =650*15 -> 9750 | E6: 0 | F6: 9750 | G6: 0 | H6: 9750 | I6: 5850 | J6: 9750 | K6: 3600 | L6: =650*15 -> 9750 | M6: 740 | N6: =650*15 -> 9750 | O6: 5850 | P6: =650*15 -> 9750 | Q6: 6750 | R6: =650*15 -> 9750 | T6: =650*15 -> 9750 | V6: =650*15 -> 9750 | X6: =650*15 -> 9750 | Z6: =650*15 -> 9750 | AB6: =D6+F6+H6+J6+L6+N6+P6+R6+T6+V6+X6+Z6 -> 117000 | AD6: =D6+F6+H6+J6+L6+N6+P6 -> 68250 | AE6: =E6+G6+I6+K6+M6+O6+Q6 -> 22790
C7: Suma de Ingresos CE/Board | D7: =SUM(D5:D6) -> 26000 | E7: =SUM(E5:E6) -> 0 | F7: =SUM(F5:F6) -> 26000 | G7: =SUM(G5:G6) -> 0 | H7: =SUM(H5:H6) -> 26000 | I7: =SUM(I5:I6) -> 5850 | J7: =SUM(J5:J6) -> 26000 | K7: =SUM(K5:K6) -> 3600 | ... R7: =SUM(R5:R6) -> 26000 | T7: =SUM(T5:T6) -> 26000 | V7: =SUM(V5:V6) -> 26000 | X7: =SUM(X5:X6) -> 26000 | Z7: =SUM(Z5:Z6) -> 26000 | AB7: =SUM(AB5:AB6) -> 312000 | AD7: =SUM(AD5:AD6) -> 182000 | AE7: =SUM(AE5:AE6) -> 22790
C9: Gastos CE/Board
B10: 502-006-000-00 | C10: Board of Directors | D10: 18000 | E10: 0 | F10: 18000 | G10: 0 | H10: 18000 | I10: 0 | J10: 18000 | K10: 0 | L10: 18000 | M10: 0 | N10: 18000 | O10: 0 | P10: 18000 | Q10: 372.75 | R10: 18000 | T10: 18000 | V10: 18000 | X10: 18000 | Z10: 18000 | AB10: =D10+F10+H10+J10+L10+N10+P10+R10+T10+V10+X10+Z10 -> 216000 | AD10: =D10+F10+H10+J10+L10+N10+P10 -> 126000 | AE10: =E10+G10+I10+K10+M10+O10+Q10 -> 372.75
B11: 502-012-000-00 | C11: Executive Committee | D11: =560*14 -> 7840 | E11: 0 | F11: 7840 | G11: 0 | H11: 7840 | I11: 656.5 | J11: 7840 | K11: 20698.44 | L11: =560*14 -> 7840 | M11: 8908.76 | N11: =560*14 -> 7840 | O11: 8460.24 | P11: =560*14 -> 7840 | Q11: 2200 | R11: =560*14 -> 7840 | T11: =560*14 -> 7840 | V11: =560*14 -> 7840 | X11: =560*14 -> 7840 | Z11: =560*14 -> 7840 | AB11: =D11+F11+H11+J11+L11+N11+P11+R11+T11+V11+X11+Z11 -> 94080 | AD11: =D11+F11+H11+J11+L11+N11+P11 -> 54880 | AE11: =E11+G11+I11+K11+M11+O11+Q11 -> 40923.94
C12: Suma de Gastos CE/Board | D12: =SUM(D10:D11) -> 25840 | E12: =SUM(E10:E11) -> 0 | F12: =SUM(F10:F11) -> 25840 | G12: =SUM(G10:G11) -> 0 | H12: =SUM(H10:H11) -> 25840 | I12: =SUM(I10:I11) -> 656.5 | J12: =SUM(J10:J11) -> 25840 | K12: =SUM(K10:K11) -> 20698.44 | ... R12: =SUM(R10:R11) -> 25840 | T12: =SUM(T10:T11) -> 25840 | V12: =SUM(V10:V11) -> 25840 | X12: =SUM(X10:X11) -> 25840 | Z12: =SUM(Z10:Z11) -> 25840 | AB12: =SUM(AB10:AB11) -> 310080 | AD12: =SUM(AD10:AD11) -> 180880 | AE12: =SUM(AE10:AE11) -> 41296.69
C14: Resultado Board y Executive | D14: =+D7-D12 -> 160 | E14: =+E7-E12 -> 0 | F14: =+F7-F12 -> 160 | G14: =+G7-G12 -> 0 | H14: =+H7-H12 -> 160 | I14: =+I7-I12 -> 5193.5 | J14: =+J7-J12 -> 160 | K14: =+K7-K12 -> -17098.44 | ... R14: =+R7-R12 -> 160 | T14: =+T7-T12 -> 160 | V14: =+V7-V12 -> 160 | X14: =+X7-X12 -> 160 | Z14: =+Z7-Z12 -> 160 | AB14: =+AB7-AB12 -> 1920 | AD14: =+AD7-AD12 -> 1120 | AE14: =+AE7-AE12 -> -18506.69
C17: Gastos de Administración
B19: 901-004-003-00 | C19: Gastos de Viaje | D19: =SUM(D20) -> 0 | E19: 0 | F19: 14500 | G19: 0 | H19: 14500 | I19: 4093.19 | J19: 0 | K19: -232 | L19: =SUM(L20) -> 0 | M19: 33715.3 | N19: =SUM(N20) -> 14500 | O19: 0 | P19: =SUM(P20) -> 0 | Q19: 11069.43 | R19: =SUM(R20) -> 0 | T19: =SUM(T20) -> 0 | V19: =SUM(V20) -> 14500 | X19: =SUM(X20) -> 0 | Z19: =SUM(Z20) -> 0 | AB19: =D19+F19+H19+J19+L19+N19+P19+R19+T19+V19+X19+Z19 -> 58000 | AD19: =D19+F19+H19+J19+L19+N19+P19 -> 43500 | AE19: =E19+G19+I19+K19+M19+O19+Q19 -> 48645.92
C20: Dirección | D20: 0 | E20: 0 | F20: 14500 | G20: 0 | H20: 14500 | I20: 4093.19 | J20: 0 | K20: -232 | L20: 0 | M20: 33715.3 | N20: 14500 | O20: 0 | P20: 0 | Q20: 11069.43 | R20: 0 | T20: 0 | V20: 14500 | X20: 0 | Z20: 0 | AB20: =D20+F20+H20+J20+L20+N20+P20+R20+T20+V20+X20+Z20 -> 58000 | AD20: =D20+F20+H20+J20+L20+N20+P20 -> 43500 | AE20: =E20+G20+I20+K20+M20+O20+Q20 -> 48645.92
B21: 901-007-000-00 | C21: Viajes Presidente Capítulo | D21: 0 | E21: 0 | F21: 0 | G21: 0 | H21: 15000 | I21: 9472.26 | J21: 0 | K21: 0 | L21: 0 | M21: 0 | N21: 0 | O21: 0 | P21: 15000 | Q21: 9570.15 | R21: 0 | T21: 0 | V21: 0 | X21: 0 | Z21: 0 | AB21: =D21+F21+H21+J21+L21+N21+P21+R21+T21+V21+X21+Z21 -> 30000 | AD21: =D21+F21+H21+J21+L21+N21+P21 -> 30000 | AE21: =E21+G21+I21+K21+M21+O21+Q21 -> 19042.41
