Workbook
Name Payment_Needed: "Pago necesario"
Name Reimbursement: "Reembolso"

Sheet OneAmCham
A1: CONCEPTO | B1: Real 2025 | C1: Ppto. 2026 | D1: Ppto. 2025 | E1: Variación Ppto. 2026 vs Real 2025 | F1: Variación Ppto. 2025 vs Ppto. 2026
A3: CDMX Income | B3: ='Resumen (Caps)'!D4 -> 64619514 | C3: ='Resumen (Caps)'!E4 -> 71683976 | D3: ='Resumen (Caps)'!F4 -> 62529782 | E3: =IF((IFERROR(C3/B3,0))=0,0,(IFERROR(C3/B3,0)-1)) -> 0.10932398 | F3: =IF((IFERROR(C3/D3,0))=0,0,(IFERROR(C3/D3,0)-1)) -> 0.14639734
A4: Guadalajara Income | B4: ='Resumen (Caps)'!J4 -> 14195973 | C4: ='Resumen (Caps)'!K4 -> 17961606 | D4: ='Resumen (Caps)'!L4 -> 17294316 | E4: =IF((IFERROR(C4/B4,0))=0,0,(IFERROR(C4/B4,0)-1)) -> 0.26526067 | F4: =IF((IFERROR(C4/D4,0))=0,0,(IFERROR(C4/D4,0)-1)) -> 0.038584369
A5: Northeast Income | B5: ='Resumen (Caps)'!P4 -> 32744833 | C5: ='Resumen (Caps)'!Q4 -> 36605251 | D5: ='Resumen (Caps)'!R4 -> 34972433 | E5: =IF((IFERROR(C5/B5,0))=0,0,(IFERROR(C5/B5,0)-1)) -> 0.11789396 | F5: =IF((IFERROR(C5/D5,0))=0,0,(IFERROR(C5/D5,0)-1)) -> 0.046688705
A6: Northwests Income | B6: ='Resumen (Caps)'!V4 -> 5116359.8 | C6: ='Resumen (Caps)'!W4 -> 6765685 | D6: ='Resumen (Caps)'!X4 -> 8173413.7 | E6: =IF((IFERROR(C6/B6,0))=0,0,(IFERROR(C6/B6,0)-1)) -> 0.32236303 | F6: =IF((IFERROR(C6/D6,0))=0,0,(IFERROR(C6/D6,0)-1)) -> -0.17223265
A7: CONSOLIDATED INCOME | B7: =B3+B4+B5+B6 -> 1.1667668e+08 | C7: =C3+C4+C5+C6 -> 133016518 | D7: =D3+D4+D5+D6 -> 1.2296994e+08 | E7: =IF((IFERROR(C7/B7,0))=0,0,(IFERROR(C7/B7,0)-1)) -> 0.14004374 | F7: =IF((IFERROR(C7/D7,0))=0,0,(IFERROR(C7/D7,0)-1)) -> 0.08169942
A8: CDMX Expense | B8: ='Resumen (Caps)'!D24 -> 61247285 | C8: ='Resumen (Caps)'!E24 -> 69120006 | D8: ='Resumen (Caps)'!F24 -> 61625391 | E8: =IF((IFERROR(C8/B8,0))=0,0,(IFERROR(C8/B8,0)-1)) -> 0.12853991 | F8: =IF((IFERROR(C8/D8,0))=0,0,(IFERROR(C8/D8,0)-1)) -> 0.12161569
A9: Guadalajara Expense | B9: ='Resumen (Caps)'!J24 -> 14658996 | C9: ='Resumen (Caps)'!K24 -> 17851585 | D9: ='Resumen (Caps)'!L24 -> 16453320 | E9: =IF((IFERROR(C9/B9,0))=0,0,(IFERROR(C9/B9,0)-1)) -> 0.21779036 | F9: =IF((IFERROR(C9/D9,0))=0,0,(IFERROR(C9/D9,0)-1)) -> 0.084983721
A10: Northeast Expense | B10: ='Resumen (Caps)'!P24 -> 32320735 | C10: ='Resumen (Caps)'!Q24 -> 35744174 | D10: ='Resumen (Caps)'!R24 -> 33410428 | E10: =IF((IFERROR(C10/B10,0))=0,0,(IFERROR(C10/B10,0)-1)) -> 0.10592082 | F10: =IF((IFERROR(C10/D10,0))=0,0,(IFERROR(C10/D10,0)-1)) -> 0.069850825
A11: Northwests Expense | B11: ='Resumen (Caps)'!V24 -> 4574611.7 | C11: ='Resumen (Caps)'!W24 -> 6026890 | D11: ='Resumen (Caps)'!X24 -> 5864476.4 | E11: =IF((IFERROR(C11/B11,0))=0,0,(IFERROR(C11/B11,0)-1)) -> 0.31746482 | F11: =IF((IFERROR(C11/D11,0))=0,0,(IFERROR(C11/D11,0)-1)) -> 0.027694472
A12: CONSOLIDATED EXPENSES | B12: =B8+B9+B10+B11 -> 1.1280163e+08 | C12: =C8+C9+C10+C11 -> 1.2874265e+08 | D12: =D8+D9+D10+D11 -> 1.1735362e+08 | E12: =IF((IFERROR(C12/B12,0))=0,0,(IFERROR(C12/B12,0)-1)) -> 0.14131911 | F12: =IF((IFERROR(C12/D12,0))=0,0,(IFERROR(C12/D12,0)-1)) -> 0.097048894
A13: OPERATING RESULTS CDMX | B13: =+B3-B8 -> 3372228.3 | C13: =+C3-C8 -> 2563969.8 | D13: =+D3-D8 -> 904390.62 | E13: =IF((IFERROR(C13/B13,0))=0,0,(IFERROR(C13/B13,0)-1)) -> -0.23968085 | F13: =IF((IFERROR(C13/D13,0))=0,0,(IFERROR(C13/D13,0)-1)) -> 1.8350247
A14: OPERATING RESULTS Guadalajara | B14: =+B4-B9 -> -463023.6 | C14: =+C4-C9 -> 110021.59 | D14: =+D4-D9 -> 840995.7 | E14: =IF((IFERROR(C14/B14,0))=0,0,(IFERROR(C14/B14,0)-1))*-1 -> 1.2376155 | F14: =IF((IFERROR(C14/D14,0))=0,0,(IFERROR(C14/D14,0)-1))*-1 -> 0.86917699
A15: OPERATING RESULTS Northeast | B15: =+B5-B10 -> 424098.19 | C15: =+C5-C10 -> 861077.45 | D15: =+D5-D10 -> 1562005.8 | E15: =IF((IFERROR(C15/B15,0))=0,0,(IFERROR(C15/B15,0)-1)) -> 1.0303728 | F15: =IF((IFERROR(C15/D15,0))=0,0,(IFERROR(C15/D15,0)-1)) -> -0.44873606
A16: OPERATING RESULTS Northwests | B16: =+B6-B11 -> 541748.02 | C16: =+C6-C11 -> 738794.98 | D16: =+D6-D11 -> 2308937.2 | E16: =IF((IFERROR(C16/B16,0))=0,0,(IFERROR(C16/B16,0)-1)) -> 0.36372437 | F16: =IF((IFERROR(C16/D16,0))=0,0,(IFERROR(C16/D16,0)-1)) -> -0.68002812
A17: CONSOLIDATED OPERATING RESULTS | B17: =B13+B14+B15+B16 -> 3875050.9 | C17: =C13+C14+C15+C16 -> 4273863.8 | D17: =D13+D14+D15+D16 -> 5616329.3 | E17: =IF((IFERROR(C17/B17,0))=0,0,(IFERROR(C17/B17,0)-1)) -> 0.10291809 | F17: =IF((IFERROR(C17/D17,0))=0,0,(IFERROR(C17/D17,0)-1)) -> -0.23902899
A18: México Member Centricity | B18: ='Resumen (Caps)'!D75 -> 0 | C18: ='Resumen (Caps)'!E75 -> 0 | D18: ='Resumen (Caps)'!F75 -> 0 | E18: =IF((IFERROR(C18/B18,0))=0,0,(IFERROR(C18/B18,0)-1)) -> 0 | F18: =IF((IFERROR(C18/D18,0))=0,0,(IFERROR(C18/D18,0)-1)) -> 0
A19: Guadalajara Member Centricity | B19: ='Resumen (Caps)'!J75 -> 0 | C19: ='Resumen (Caps)'!K75 -> 0 | D19: ='Resumen (Caps)'!L75 -> 0 | E19: =IF((IFERROR(C19/B19,0))=0,0,(IFERROR(C19/B19,0)-1)) -> 0 | F19: =IF((IFERROR(C19/D19,0))=0,0,(IFERROR(C19/D19,0)-1)) -> 0
A20: Northeast Member Centricity | B20: ='Resumen (Caps)'!P75 -> 0 | C20: ='Resumen (Caps)'!Q75 -> 0 | D20: ='Resumen (Caps)'!R75 -> 0 | E20: =IF((IFERROR(C20/B20,0))=0,0,(IFERROR(C20/B20,0)-1)) -> 0 | F20: =IF((IFERROR(C20/D20,0))=0,0,(IFERROR(C20/D20,0)-1)) -> 0
A21: Northwests Member Centricity | B21: ='Resumen (Caps)'!V75 -> 0 | C21: ='Resumen (Caps)'!W75 -> 0 | D21: ='Resumen (Caps)'!X75 -> 0 | E21: =IF((IFERROR(C21/B21,0))=0,0,(IFERROR(C21/B21,0)-1)) -> 0 | F21: =IF((IFERROR(C21/D21,0))=0,0,(IFERROR(C21/D21,0)-1)) -> 0
A22: México Other Income | B22: ='Resumen (Caps)'!D77 -> 6005514 | C22: ='Resumen (Caps)'!E77 -> 0 | D22: ='Resumen (Caps)'!F77 -> 0 | E22: =IF((IFERROR(C22/B22,0))=0,0,(IFERROR(C22/B22,0)-1)) -> 0 | F22: =IF((IFERROR(C22/D22,0))=0,0,(IFERROR(C22/D22,0)-1)) -> 0
A23: Guadalajara Other Income | B23: ='Resumen (Caps)'!J77 -> 215.81 | C23: ='Resumen (Caps)'!K77 -> 0 | D23: ='Resumen (Caps)'!L77 -> 0 | E23: =IF((IFERROR(C23/B23,0))=0,0,(IFERROR(C23/B23,0)-1)) -> 0 | F23: =IF((IFERROR(C23/D23,0))=0,0,(IFERROR(C23/D23,0)-1)) -> 0
A24: Northeast Other Income | B24: ='Resumen (Caps)'!P77 -> 150141.67 | C24: ='Resumen (Caps)'!Q77 -> 0 | D24: ='Resumen (Caps)'!R77 -> 0 | E24: =IF((IFERROR(C24/B24,0))=0,0,(IFERROR(C24/B24,0)-1)) -> 0 | F24: =IF((IFERROR(C24/D24,0))=0,0,(IFERROR(C24/D24,0)-1)) -> 0
A25: Northwests Other Income | B25: ='Resumen (Caps)'!V77 -> 0 | C25: ='Resumen (Caps)'!W77 -> 0 | D25: ='Resumen (Caps)'!X77 -> 0 | E25: =IF((IFERROR(C25/B25,0))=0,0,(IFERROR(C25/B25,0)-1)) -> 0 | F25: =IF((IFERROR(C25/D25,0))=0,0,(IFERROR(C25/D25,0)-1)) -> 0
A26: NET RESULTS CDMX | B26: =B13-B18+B22 -> 9377742.4 | C26: =C13-C18+C22 -> 2563969.8 | D26: =D13-D18+D22 -> 904390.62 | E26: =IF((IFERROR(C26/B26,0))=0,0,(IFERROR(C26/B26,0)-1)) -> -0.72658987 | F26: =IF((IFERROR(C26/D26,0))=0,0,(IFERROR(C26/D26,0)-1)) -> 1.8350247
A27: NET RESULTS Guadalajara | B27: =B14-B19+B23 -> -462807.79 | C27: =C14-C19+C23 -> 110021.59 | D27: =D14-D19+D23 -> 840995.7 | E27: =IF((IFERROR(C27/B27,0))=0,0,(IFERROR(C27/B27,0)-1))*-1 -> 1.2377263 | F27: =IF((IFERROR(C27/D27,0))=0,0,(IFERROR(C27/D27,0)-1))*-1 -> 0.86917699
A28: NET RESULTS Northeast | B28: =B15-B20+B24 -> 574239.86 | C28: =C15-C20+C24 -> 861077.45 | D28: =D15-D20+D24 -> 1562005.8 | E28: =IF((IFERROR(C28/B28,0))=0,0,(IFERROR(C28/B28,0)-1)) -> 0.49950832 | F28: =IF((IFERROR(C28/D28,0))=0,0,(IFERROR(C28/D28,0)-1)) -> -0.44873606
A29: NET RESULTS Northwests | B29: =B16-B21+B25 -> 541748.02 | C29: =C16-C21+C25 -> 738794.98 | D29: =D16-D21+D25 -> 2308937.2 | E29: =IF((IFERROR(C29/B29,0))=0,0,(IFERROR(C29/B29,0)-1)) -> 0.36372437 | F29: =IF((IFERROR(C29/D29,0))=0,0,(IFERROR(C29/D29,0)-1)) -> -0.68002812
A30: CONSOLIDATED NET RESULTS | B30: =SUM(B26:B29) -> 10030922 | C30: =SUM(C26:C29) -> 4273863.8 | D30: =SUM(D26:D29) -> 5616329.3 | E30: =IF((IFERROR(C30/B30,0))=0,0,(IFERROR(C30/B30,0)-1)) -> -0.57393113 | F30: =IF((IFERROR(C30/D30,0))=0,0,(IFERROR(C30/D30,0)-1)) -> -0.23902899
B33: ='Resumen (Caps)'!D87 -> 9377742.4 | C33: ='Resumen (Caps)'!E87 -> 2563969.8 | D33: ='Resumen (Caps)'!F87 -> 904390.62
B34: ='Resumen (Caps)'!J87 -> -462807.79 | C34: ='Resumen (Caps)'!K87 -> 110021.59 | D34: ='Resumen (Caps)'!L87 -> 840995.7
B35: ='Resumen (Caps)'!P87 -> 574239.86 | C35: ='Resumen (Caps)'!Q87 -> 861077.45 | D35: ='Resumen (Caps)'!R87 -> 1562005.8
B36: ='Resumen (Caps)'!V87 -> 541748.02 | C36: ='Resumen (Caps)'!W87 -> 738794.98 | D36: ='Resumen (Caps)'!X87 -> 2308937.2
B37: =B26-B33 -> 0 | C37: =C26-C33 -> 0 | D37: =D26-D33 -> 0
B38: =B27-B34 -> 0 | C38: =C27-C34 -> 0 | D38: =D27-D34 -> 0
B39: =B28-B35 -> 0 | C39: =C28-C35 -> 0 | D39: =D28-D35 -> 0
B40: =B29-B36 -> 0 | C40: =C29-C36 -> 0 | D40: =D29-D36 -> 0

Sheet Resumen (Caps)
D1: MX | J1: GDL | P1: NE | V1: NO
D2: Real 2025 | E2: Ppto. 2026 | F2: Ppto. 2025 | G2: Variación Ppto. 2026 vs Real 2025 | H2: Variación Ppto. 2025 vs Ppto. 2026 | J2: Real 2025 | K2: Ppto. 2026 | L2: Ppto. 2025 | M2: Variación Ppto. 2026 vs Real 2025 | N2: Variación Ppto. 2025 vs Ppto. 2026 | P2: Real 2025 | Q2: Ppto. 2026 | R2: Ppto. 2025 | S2: Variación Ppto. 2026 vs Real 2025 | T2: Variación Ppto. 2025 vs Ppto. 2026 | V2: Real 2025 | W2: Ppto. 2026 | X2: Ppto. 2025 | Y2: Variación Ppto. 2026 vs Real 2025 | Z2: Variación Ppto. 2025 vs Ppto. 2026
C4: INCOME | D4: =SUM(D5,D8,D11,D16,D14) -> 64619514 | E4: =SUM(E5,E8,E11,E16,E14) -> 71683976 | F4: =SUM(F5,F8,F11,F16,F14) -> 62529782 | G4: =IF((IFERROR(E4/D4,0))=0,0,(IFERROR(E4/D4,0)-1)) -> 0.10932398 | H4: =IF((IFERROR(E4/F4,0))=0,0,(IFERROR(E4/F4,0)-1)) -> 0.14639734 | J4: =J5+J8+J11+J14+J16 -> 14195973 | K4: =K5+K8+K11+K14+K16 -> 17961606 | L4: =L5+L8+L11+L14+L16 -> 17294316 | M4: =IF((IFERROR(K4/J4,0))=0,0,(IFERROR(K4/J4,0)-1)) -> 0.26526067 | N4: =IF((IFERROR(K4/L4,0))=0,0,(IFERROR(K4/L4,0)-1)) -> 0.038584369 | P4: =P5+P8+P11+P14+P16 -> 32744833 | Q4: =Q5+Q8+Q11+Q14+Q16 -> 36605251 | R4: =R5+R8+R11+R14+R16 -> 34972433 | S4: =IF((IFERROR(Q4/P4,0))=0,0,(IFERROR(Q4/P4,0)-1)) -> 0.11789396 | T4: =IF((IFERROR(Q4/R4,0))=0,0,(IFERROR(Q4/R4,0)-1)) -> 0.046688705 | V4: =V5+V8+V11+V14+V16 -> 5116359.8 | W4: =W5+W8+W11+W14+W16 -> 6765685 | X4: =X5+X8+X11+X14+X16 -> 8173413.7 | Y4: =IF((IFERROR(W4/V4,0))=0,0,(IFERROR(W4/V4,0)-1)) -> 0.32236303 | Z4: =IF((IFERROR(W4/X4,0))=0,0,(IFERROR(W4/X4,0)-1)) -> -0.17223265
C5: Membership | D5: =D6+D7 -> 42611318 | E5: =E6+E7 -> 46872450 | F5: =F6+F7 -> 37282030 | G5: =IF((IFERROR(E5/D5,0))=0,0,(IFERROR(E5/D5,0)-1)) -> 0.1 | H5: =IF((IFERROR(E5/F5,0))=0,0,(IFERROR(E5/F5,0)-1)) -> 0.25723974 | J5: 10543077 | K5: 11782798 | L5: 10909089 | M5: =IF((IFERROR(K5/J5,0))=0,0,(IFERROR(K5/J5,0)-1)) -> 0.11758631 | N5: =IF((IFERROR(K5/L5,0))=0,0,(IFERROR(K5/L5,0)-1)) -> 0.080090036 | P5: 25323170 | Q5: 28947770 | R5: =24786483.33 -> 24786483 | S5: =IF((IFERROR(Q5/P5,0))=0,0,(IFERROR(Q5/P5,0)-1)) -> 0.14313377 | T5: =IF((IFERROR(Q5/R5,0))=0,0,(IFERROR(Q5/R5,0)-1)) -> 0.16788533 | V5: 4754009.8 | W5: 5828618 | X5: 7502413.7 | Y5: =IF((IFERROR(W5/V5,0))=0,0,(IFERROR(W5/V5,0)-1)) -> 0.2260425 | Z5: =IF((IFERROR(W5/X5,0))=0,0,(IFERROR(W5/X5,0)-1)) -> -0.22310096
B6: 401-000-000-00 | C6: Cuotas Netas | D6: =Resumen!I7 -> 41346034 | E6: =SUMIF('México Summary'!$C:$C,'Resumen (Caps)'!B6,'México Summary'!$AC:$AC) -> 45370058 | F6: 36117362 | G6: =IF((IFERROR(E6/D6,0))=0,0,(IFERROR(E6/D6,0)-1)) -> 0.097325506 | H6: =IF((IFERROR(E6/F6,0))=0,0,(IFERROR(E6/F6,0)-1)) -> 0.25618416 | P6: 24416653 | Q6: 28705760 | R6: 22877983 | V6: 4420176.4 | W6: 6426568.2 | X6: 6677913.7
B7: 402-000-000-00 | C7: Ingresos socios nuevos | D7: =Resumen!I8 -> 1265283.3 | E7: =SUMIF('México Summary'!$C:$C,'Resumen (Caps)'!B7,'México Summary'!$AC:$AC) -> 1502391.4 | F7: 1164667.8 | G7: =IF((IFERROR(E7/D7,0))=0,0,(IFERROR(E7/D7,0)-1)) -> 0.18739523 | H7: =IF((IFERROR(E7/F7,0))=0,0,(IFERROR(E7/F7,0)-1)) -> 0.2899742 | P7: 906516.99 | Q7: 1242010 | R7: 1908500 | V7: 333833.33 | W7: 402050 | X7: 824500
C8: Events | D8: =D9+D10 -> 12859605 | E8: =E9+E10 -> 11511191 | F8: =F9+F10 -> 12957002 | G8: =IF((IFERROR(E8/D8,0))=0,0,(IFERROR(E8/D8,0)-1)) -> -0.10485653 | H8: =IF((IFERROR(E8/F8,0))=0,0,(IFERROR(E8/F8,0)-1)) -> -0.1115853 | J8: 2311332.8 | K8: 3820000 | L8: 4100000 | M8: =IF((IFERROR(K8/J8,0))=0,0,(IFERROR(K8/J8,0)-1)) -> 0.65272611 | N8: =IF((IFERROR(K8/L8,0))=0,0,(IFERROR(K8/L8,0)-1)) -> -0.068292683 | P8: 3788994.6 | Q8: 4070000 | R8: 5632000 | S8: =IF((IFERROR(Q8/P8,0))=0,0,(IFERROR(Q8/P8,0)-1)) -> 0.074163579 | T8: =IF((IFERROR(Q8/R8,0))=0,0,(IFERROR(Q8/R8,0)-1)) -> -0.27734375 | V8: 294450 | W8: 710000 | X8: 440000 | Y8: =IF((IFERROR(W8/V8,0))=0,0,(IFERROR(W8/V8,0)-1)) -> 1.4112753 | Z8: =IF((IFERROR(W8/X8,0))=0,0,(IFERROR(W8/X8,0)-1)) -> 0.61363636
B9: 407-000-000-00 | C9: Eventos | D9: =Resumen!I10 -> 1856490.2 | E9: =SUMIF('México Summary'!$C:$C,'Resumen (Caps)'!B9,'México Summary'!$AC:$AC) -> 1460000 | F9: 2250000 | G9: =IF((IFERROR(E9/D9,0))=0,0,(IFERROR(E9/D9,0)-1)) -> -0.21356976 | H9: =IF((IFERROR(E9/F9,0))=0,0,(IFERROR(E9/F9,0)-1)) -> -0.35111111 | P9: 3788994.6 | Q9: 1476239.8 | R9: 5632000 | V9: 294450 | W9: 208395 | X9: 440000
B10: 408-000-000-00 | C10: Patrocinios | D10: =Resumen!I11 -> 11003115 | E10: =SUMIF('México Summary'!$C:$C,'Resumen (Caps)'!B10,'México Summary'!$AC:$AC) -> 10051191 | F10: 10707002 | G10: =IF((IFERROR(E10/D10,0))=0,0,(IFERROR(E10/D10,0)-1)) -> -0.086513996 | H10: =IF((IFERROR(E10/F10,0))=0,0,(IFERROR(E10/F10,0)-1)) -> -0.061250657 | P10: 0 | Q10: 4898758.1 | R10: 0 | V10: 0 | W10: 352000 | X10: 0
C11: Committees | D11: =D12+D13 -> 6702991 | E11: =E12+E13 -> 9775090 | F11: =F12+F13 -> 11450750 | G11: =IF((IFERROR(E11/D11,0))=0,0,(IFERROR(E11/D11,0)-1)) -> 0.45831765 | H11: =IF((IFERROR(E11/F11,0))=0,0,(IFERROR(E11/F11,0)-1)) -> -0.14633627 | J11: 756663.16 | K11: 1594590.7 | L11: 1718000 | M11: =IF((IFERROR(K11/J11,0))=0,0,(IFERROR(K11/J11,0)-1)) -> 1.1073983 | N11: =IF((IFERROR(K11/L11,0))=0,0,(IFERROR(K11/L11,0)-1)) -> -0.071833132 | P11: 1740806.7 | Q11: 2209360.8 | R11: 2593050 | S11: =IF((IFERROR(Q11/P11,0))=0,0,(IFERROR(Q11/P11,0)-1)) -> 0.26915913 | T11: =IF((IFERROR(Q11/R11,0))=0,0,(IFERROR(Q11/R11,0)-1)) -> -0.14796832 | V11: 0 | W11: 48000 | X11: 100000 | Y11: =IF((IFERROR(W11/V11,0))=0,0,(IFERROR(W11/V11,0)-1)) -> 0 | Z11: =IF((IFERROR(W11/X11,0))=0,0,(IFERROR(W11/X11,0)-1)) -> -0.52
B12: 417-000-000-00 | C12: Comités | D12: =Resumen!I13 -> 5748342.6 | E12: =SUMIF('México Summary'!$C:$C,'Resumen (Caps)'!B12,'México Summary'!$AC:$AC) -> 8675090 | F12: 10800750 | G12: =IF((IFERROR(E12/D12,0))=0,0,(IFERROR(E12/D12,0)-1)) -> 0.5091463 | H12: =IF((IFERROR(E12/F12,0))=0,0,(IFERROR(E12/F12,0)-1)) -> -0.1968067 | P12: 1740806.7 | Q12: 1663666.9 | R12: 2593050 | V12: 0 | W12: 22000 | X12: 100000
B13: 412-000-000-00 | C13: Economex | D13: =Resumen!I14 -> 954648.32 | E13: =SUMIF('México Summary'!$C:$C,'Resumen (Caps)'!B13,'México Summary'!$AC:$AC) -> 1100000 | F13: 650000 | G13: =IF((IFERROR(E13/D13,0))=0,0,(IFERROR(E13/D13,0)-1)) -> 0.15225678 | H13: =IF((IFERROR(E13/F13,0))=0,0,(IFERROR(E13/F13,0)-1)) -> 0.69230769 | P13: 1001862.1 | Q13: 403754 | R13: 1450000 | V13: 0 | W13: 74539.2 | X13: 0
C14: T&IC | D14: =D15 -> 0 | E14: =E15 -> 840000 | F14: =F15 -> 0 | G14: =IF((IFERROR(E14/D14,0))=0,0,(IFERROR(E14/D14,0)-1)) -> 0 | H14: =IF((IFERROR(E14/F14,0))=0,0,(IFERROR(E14/F14,0)-1)) -> 0 | J14: 0 | K14: 50000 | L14: 0 | M14: 1 | N14: =IF((IFERROR(K14/L14,0))=0,0,(IFERROR(K14/L14,0)-1)) -> 0 | P14: 1001862 | Q14: 460000 | R14: 1450000 | S14: =IF((IFERROR(Q14/P14,0))=0,0,(IFERROR(Q14/P14,0)-1)) -> -0.54085493 | T14: =IF((IFERROR(Q14/R14,0))=0,0,(IFERROR(Q14/R14,0)-1)) -> -0.68275862 | V14: 0 | W14: 80000 | X14: 0 | Y14: =IF((IFERROR(W14/V14,0))=0,0,(IFERROR(W14/V14,0)-1)) -> 0 | Z14: =IF((IFERROR(W14/X14,0))=0,0,(IFERROR(W14/X14,0)-1)) -> 0
B15: 405-000-000-00 | C15: Trade & Investment Center | D15: =Resumen!I16 -> 0 | E15: =SUMIF('México Summary'!$C:$C,'Resumen (Caps)'!B15,'México Summary'!$AC:$AC) -> 840000 | F15: 0 | G15: =IF((IFERROR(E15/D15,0))=0,0,(IFERROR(E15/D15,0)-1)) -> 0 | H15: =IF((IFERROR(E15/F15,0))=0,0,(IFERROR(E15/F15,0)-1)) -> 0
C16: Services to Members | D16: =D17+D19+D18 -> 2445600 | E16: =E17+E19+E18 -> 2685245 | F16: =F17+F19+F18 -> 840000 | G16: =IF((IFERROR(E16/D16,0))=0,0,(IFERROR(E16/D16,0)-1)) -> 0.097990268 | H16: =IF((IFERROR(E16/F16,0))=0,0,(IFERROR(E16/F16,0)-1)) -> 2.1967202 | J16: 584900 | K16: 714217.04 | L16: 567226.8 | M16: =IF((IFERROR(K16/J16,0))=0,0,(IFERROR(K16/J16,0)-1)) -> 0.22109256 | N16: =IF((IFERROR(K16/L16,0))=0,0,(IFERROR(K16/L16,0)-1)) -> 0.25913839 | P16: 890000 | Q16: 918120 | R16: 510900 | S16: =IF((IFERROR(Q16/P16,0))=0,0,(IFERROR(Q16/P16,0)-1)) -> 0.031595506 | T16: =IF((IFERROR(Q16/R16,0))=0,0,(IFERROR(Q16/R16,0)-1)) -> 0.797064 | V16: 67900 | W16: 99067 | X16: 131000 | Y16: =IF((IFERROR(W16/V16,0))=0,0,(IFERROR(W16/V16,0)-1)) -> 0.45901325 | Z16: =IF((IFERROR(W16/X16,0))=0,0,(IFERROR(W16/X16,0)-1)) -> -0.24376336
B17: 406-001-000-00 | C17: Venta Publicaciones | D17: =Resumen!I18 -> 1292600 | E17: =SUMIF('México Summary'!$C:$C,'Resumen (Caps)'!B17,'México Summary'!$AC:$AC) -> 1232595 | F17: 840000 | G17: =IF((IFERROR(E17/D17,0))=0,0,(IFERROR(E17/D17,0)-1)) -> -0.04642194 | H17: =IF((IFERROR(E17/F17,0))=0,0,(IFERROR(E17/F17,0)-1)) -> 0.467375
B18: 406-002-000-00 | C18: Digital Training | D18: =Resumen!I19 -> 1153000 | E18: =SUMIF('México Summary'!$C:$C,'Resumen (Caps)'!B18,'México Summary'!$AC:$AC) -> 1452650 | F18: 0 | G18: =IF((IFERROR(E18/D18,0))=0,0,(IFERROR(E18/D18,0)-1)) -> 0.25988725 | H18: =IF((IFERROR(E18/F18,0))=0,0,(IFERROR(E18/F18,0)-1)) -> 0
B19: 409-000-000-00 | C19: Visas | D19: =Resumen!I20 -> 0 | E19: =SUMIF('México Summary'!$C:$C,'Resumen (Caps)'!B19,'México Summary'!$AC:$AC) -> 0 | F19: 0 | G19: =IF((IFERROR(E19/D19,0))=0,0,(IFERROR(E19/D19,0)-1)) -> 0 | H19: =IF((IFERROR(E19/F19,0))=0,0,(IFERROR(E19/F19,0)-1)) -> 0
B20: 450-001-000-00 | C20: Guadalajara Income | D20: =Resumen!I21 -> 14196189 | E20: =SUMIF('México Summary'!$C:$C,'Resumen (Caps)'!B20,'México Summary'!$AC:$AC) -> 0 | F20: 0 | G20: =IF((IFERROR(E20/D20,0))=0,0,(IFERROR(E20/D20,0)-1)) -> 0 | H20: =IF((IFERROR(E20/F20,0))=0,0,(IFERROR(E20/F20,0)-1)) -> 0
B21: 450-002-000-00 | C21: Monterrey Income | D21: =Resumen!I22 -> 32894975 | E21: =SUMIF('México Summary'!$C:$C,'Resumen (Caps)'!B21,'México Summary'!$AC:$AC) -> 0 | F21: 0 | G21: =IF((IFERROR(E21/D21,0))=0,0,(IFERROR(E21/D21,0)-1)) -> 0 | H21: =IF((IFERROR(E21/F21,0))=0,0,(IFERROR(E21/F21,0)-1)) -> 0
B22: 450-003-000-00 | C22: Northwest Income | D22: =Resumen!I23 -> 5116359.8 | E22: =SUMIF('México Summary'!$C:$C,'Resumen (Caps)'!B22,'México Summary'!$AC:$AC) -> 0 | F22: 0 | G22: =IF((IFERROR(E22/D22,0))=0,0,(IFERROR(E22/D22,0)-1)) -> 0 | H22: =IF((IFERROR(E22/F22,0))=0,0,(IFERROR(E22/F22,0)-1)) -> 0
C23: CONSOLIDATED INCOME | D23: =D22+D21+D20+D4 -> 1.1682704e+08 | E23: =E22+E21+E20+E4 -> 71683976 | F23: =F22+F21+F20+F4 -> 62529782 | G23: =IF((IFERROR(E23/D23,0))=0,0,(IFERROR(E23/D23,0)-1)) -> -0.38640936 | H23: =IF((IFERROR(E23/F23,0))=0,0,(IFERROR(E23/F23,0)-1)) -> 0.14639734
C24: EXPENSE | D24: =D25+D28+D30+D36+D39+D53+D54+D62 -> 61247285 | E24: =E25+E28+E30+E36+E39+E53+E54+E62+E34 -> 69120006 | F24: =F25+F28+F30+F36+F39+F53+F54+F62 -> 61625391 | G24: =IF((IFERROR(E24/D24,0))=0,0,(IFERROR(E24/D24,0)-1)) -> 0.12853991 | H24: =IF((IFERROR(E24/F24,0))=0,0,(IFERROR(E24/F24,0)-1)) -> 0.12161569 | J24: =J25+J28+J30+J34+J36+J39+J53+J54+J62 -> 14658996 | K24: =K25+K28+K30+K34+K36+K39+K53+K54+K62 -> 17851585 | L24: =L25+L28+L30+L34+L36+L39+L53+L54+L62 -> 16453320 | M24: =IF((IFERROR(K24/J24,0))=0,0,(IFERROR(K24/J24,0)-1)) -> 0.21779036 | N24: =IF((IFERROR(K24/L24,0))=0,0,(IFERROR(K24/L24,0)-1)) -> 0.084983721 | P24: =P25+P28+P30+P34+P36+P39+P53+P54+P62 -> 32320735 | Q24: =Q25+Q28+Q30+Q34+Q36+Q39+Q53+Q54+Q62 -> 35744174 | R24: =R25+R28+R30+R34+R36+R39+R53+R54+R62 -> 33410428 | S24: =IF((IFERROR(Q24/P24,0))=0,0,(IFERROR(Q24/P24,0)-1)) -> 0.10592082 | T24: =IF((IFERROR(Q24/R24,0))=0,0,(IFERROR(Q24/R24,0)-1)) -> 0.069850825 | V24: =V25+V28+V30+V34+V36+V39+V53+V54+V62 -> 4574611.7 | W24: =W25+W28+W30+W34+W36+W39+W53+W54+W62 -> 6026890 | X24: =X25+X28+X30+X34+X36+X39+X53+X54+X62 -> 5864476.4 | Y24: =IF((IFERROR(W24/V24,0))=0,0,(IFERROR(W24/V24,0)-1)) -> 0.31746482 | Z24: =IF((IFERROR(W24/X24,0))=0,0,(IFERROR(W24/X24,0)-1)) -> 0.027694472
C25: Membership | D25: =D26+D27 -> 2207503.3 | E25: =E26+E27 -> 2949107.9 | F25: =F26+F27 -> 2584139.3 | G25: =IF((IFERROR(E25/D25,0))=0,0,(IFERROR(E25/D25,0)-1)) -> 0.33594723 | H25: =IF((IFERROR(E25/F25,0))=0,0,(IFERROR(E25/F25,0)-1)) -> 0.14123409 | J25: 567446.96 | K25: 493042.52 | L25: 675870.6 | M25: =IF((IFERROR(K25/J25,0))=0,0,(IFERROR(K25/J25,0)-1)) -> -0.1311214 | N25: =IF((IFERROR(K25/L25,0))=0,0,(IFERROR(K25/L25,0)-1)) -> -0.27050752 | P25: 1650853.2 | Q25: 1901079.6 | R25: 2224320 | S25: =IF((IFERROR(Q25/P25,0))=0,0,(IFERROR(Q25/P25,0)-1)) -> 0.15157401 | T25: =IF((IFERROR(Q25/R25,0))=0,0,(IFERROR(Q25/R25,0)-1)) -> -0.14532097 | V25: 398459.21 | W25: 369485.92 | X25: 618375 | Y25: =IF((IFERROR(W25/V25,0))=0,0,(IFERROR(W25/V25,0)-1)) -> -0.072713315 | Z25: =IF((IFERROR(W25/X25,0))=0,0,(IFERROR(W25/X25,0)-1)) -> -0.40248891
B26: 705-000-000-00 | C26: Gastos Promoción | D26: =Resumen!I27 -> 225000 | E26: =SUMIF('México Summary'!$C:$C,'Resumen (Caps)'!B26,'México Summary'!$AC:$AC) -> 887380 | F26: 863500 | G26: =IF((IFERROR(E26/D26,0))=0,0,(IFERROR(E26/D26,0)-1)) -> 2.9439111 | H26: =IF((IFERROR(E26/F26,0))=0,0,(IFERROR(E26/F26,0)-1)) -> 0.027654893 | P26: 1215514.1 | Q26: 1447993.8 | R26: 1804320
B27: 520-000-000-00 | C27: Comsiones por venta de membresía | D27: =Resumen!I28 -> 1982503.3 | E27: =SUMIF('México Summary'!$C:$C,'Resumen (Caps)'!B27,'México Summary'!$AC:$AC) -> 2061727.9 | F27: 1720639.3 | G27: =IF((IFERROR(E27/D27,0))=0,0,(IFERROR(E27/D27,0)-1)) -> 0.039961902 | H27: =IF((IFERROR(E27/F27,0))=0,0,(IFERROR(E27/F27,0)-1)) -> 0.19823362 | P27: 435339.09 | Q27: 453085.89 | R27: 420000
C28: Events | D28: =D29 -> 8546422.2 | E28: =E29 -> 6727036.8 | F28: =F29 -> 9107000 | G28: =IF((IFERROR(E28/D28,0))=0,0,(IFERROR(E28/D28,0)-1)) -> -0.21288269 | H28: =IF((IFERROR(E28/F28,0))=0,0,(IFERROR(E28/F28,0)-1)) -> -0.26133339 | J28: 1496260.2 | K28: 2660000 | L28: 2956045 | M28: =IF((IFERROR(K28/J28,0))=0,0,(IFERROR(K28/J28,0)-1)) -> 0.7777656 | N28: =IF((IFERROR(K28/L28,0))=0,0,(IFERROR(K28/L28,0)-1)) -> -0.10014902 | P28: 3151924.3 | Q28: 3015000 | R28: 4450000 | S28: =IF((IFERROR(Q28/P28,0))=0,0,(IFERROR(Q28/P28,0)-1)) -> -0.0434415 | T28: =IF((IFERROR(Q28/R28,0))=0,0,(IFERROR(Q28/R28,0)-1)) -> -0.32247191 | V28: 129166.8 | W28: 442000 | X28: 270000 | Y28: =IF((IFERROR(W28/V28,0))=0,0,(IFERROR(W28/V28,0)-1)) -> 2.421932 | Z28: =IF((IFERROR(W28/X28,0))=0,0,(IFERROR(W28/X28,0)-1)) -> 0.63703704
B29: 701-000-000-00 | C29: Costo Eventos | D29: =Resumen!I30 -> 8546422.2 | E29: =SUMIF('México Summary'!$C:$C,'Resumen (Caps)'!B29,'México Summary'!$AC:$AC) -> 6727036.8 | F29: 9107000 | G29: =IF((IFERROR(E29/D29,0))=0,0,(IFERROR(E29/D29,0)-1)) -> -0.21288269 | H29: =IF((IFERROR(E29/F29,0))=0,0,(IFERROR(E29/F29,0)-1)) -> -0.26133339 | P29: 3151924.3 | Q29: 4244536.5 | R29: 4450000
C30: Committees | D30: =SUM(D31:D33) -> 4258755.3 | E30: =SUM(E31:E33) -> 6940491.4 | F30: =SUM(F31:F33) -> 8604867.1 | G30: =IF((IFERROR(E30/D30,0))=0,0,(IFERROR(E30/D30,0)-1)) -> 0.6296995 | H30: =IF((IFERROR(E30/F30,0))=0,0,(IFERROR(E30/F30,0)-1)) -> -0.19342258 | J30: 644237.57 | K30: 1004784.9 | L30: 896480 | M30: =IF((IFERROR(K30/J30,0))=0,0,(IFERROR(K30/J30,0)-1)) -> 0.55964962 | N30: =IF((IFERROR(K30/L30,0))=0,0,(IFERROR(K30/L30,0)-1)) -> 0.12081126 | P30: 1200608.4 | Q30: 1537330.2 | R30: 1744550 | S30: =IF((IFERROR(Q30/P30,0))=0,0,(IFERROR(Q30/P30,0)-1)) -> 0.28045936 | T30: =IF((IFERROR(Q30/R30,0))=0,0,(IFERROR(Q30/R30,0)-1)) -> -0.11878121 | V30: 0 | W30: 24000 | X30: 60000 | Y30: =IF((IFERROR(W30/V30,0))=0,0,(IFERROR(W30/V30,0)-1)) -> 0 | Z30: =IF((IFERROR(W30/X30,0))=0,0,(IFERROR(W30/X30,0)-1)) -> -0.6
B31: 702-000-000-00 | C31: Costo Comités | D31: =Resumen!I32 -> 3073058.1 | E31: =SUMIF('México Summary'!$C:$C,'Resumen (Caps)'!B31,'México Summary'!$AC:$AC) -> 5438618.2 | F31: 7363267.1 | G31: =IF((IFERROR(E31/D31,0))=0,0,(IFERROR(E31/D31,0)-1)) -> 0.76977395 | H31: =IF((IFERROR(E31/F31,0))=0,0,(IFERROR(E31/F31,0)-1)) -> -0.26138517 | P31: 1200608.4 | Q31: 1495707.2 | R31: 1744550
B32: 704-000-000-00 | C32: Costo Economex | D32: =Resumen!I33 -> 1050317.2 | E32: =SUMIF('México Summary'!$C:$C,'Resumen (Caps)'!B32,'México Summary'!$AC:$AC) -> 1299254 | F32: 1081600 | G32: =IF((IFERROR(E32/D32,0))=0,0,(IFERROR(E32/D32,0)-1)) -> 0.23701111 | H32: =IF((IFERROR(E32/F32,0))=0,0,(IFERROR(E32/F32,0)-1)) -> 0.20123336 | P32: 0 | Q32: 0 | R32: 0
B33: 521-000-000-00 | C33: Comisiones EWDP y Economex | D33: =Resumen!I34 -> 135380.03 | E33: =SUMIF('México Summary'!$C:$C,'Resumen (Caps)'!B33,'México Summary'!$AC:$AC) -> 202619.2 | F33: 160000 | G33: =IF((IFERROR(E33/D33,0))=0,0,(IFERROR(E33/D33,0)-1)) -> 0.49666978 | H33: =IF((IFERROR(E33/F33,0))=0,0,(IFERROR(E33/F33,0)-1)) -> 0.26637 | P33: 412057.39 | Q33: 144690 | R33: 1250000
C34: T&IC | D34: =D35 -> 0 | E34: =E35 -> 340000 | F34: =F35 -> 0 | G34: =IF((IFERROR(E34/D34,0))=0,0,(IFERROR(E34/D34,0)-1)) -> 0 | H34: =IF((IFERROR(E34/F34,0))=0,0,(IFERROR(E34/F34,0)-1)) -> 0 | J34: 0 | K34: 25000 | L34: 0 | M34: 1 | N34: =IF((IFERROR(K34/L34,0))=0,0,(IFERROR(K34/L34,0)-1)) -> 0 | P34: 412057.39 | Q34: 230000 | R34: 1250000 | S34: =IF((IFERROR(Q34/P34,0))=0,0,(IFERROR(Q34/P34,0)-1)) -> -0.44182532 | T34: =IF((IFERROR(Q34/R34,0))=0,0,(IFERROR(Q34/R34,0)-1)) -> -0.816 | V34: 0 | W34: 40000 | X34: 0 | Y34: =IF((IFERROR(W34/V34,0))=0,0,(IFERROR(W34/V34,0)-1)) -> 0 | Z34: =IF((IFERROR(W34/X34,0))=0,0,(IFERROR(W34/X34,0)-1)) -> 0
B35: 703-000-000-00 | C35: Costo Trade & Investment Center | D35: =Resumen!I36 -> 0 | E35: =SUMIF('México Summary'!$C:$C,'Resumen (Caps)'!B35,'México Summary'!$AC:$AC) -> 340000 | F35: 0 | G35: =IF((IFERROR(E35/D35,0))=0,0,(IFERROR(E35/D35,0)-1)) -> 0 | H35: =IF((IFERROR(E35/F35,0))=0,0,(IFERROR(E35/F35,0)-1)) -> 0 | P35: 440250 | Q35: 459060 | R35: 286104
C36: Services to Members | D36: =D37+D38 -> 1151300.3 | E36: =E37+E38 -> 1268666.8 | F36: =F37+F38 -> 420000 | G36: =IF((IFERROR(E36/D36,0))=0,0,(IFERROR(E36/D36,0)-1)) -> 0.10194259 | H36: =IF((IFERROR(E36/F36,0))=0,0,(IFERROR(E36/F36,0)-1)) -> 2.0206352 | J36: 292450 | K36: 357108.52 | L36: 283613.4 | M36: =IF((IFERROR(K36/J36,0))=0,0,(IFERROR(K36/J36,0)-1)) -> 0.22109256 | N36: =IF((IFERROR(K36/L36,0))=0,0,(IFERROR(K36/L36,0)-1)) -> 0.25913839 | P36: 440250 | Q36: 459060 | R36: 286104 | S36: =IF((IFERROR(Q36/P36,0))=0,0,(IFERROR(Q36/P36,0)-1)) -> 0.042725724 | T36: =IF((IFERROR(Q36/R36,0))=0,0,(IFERROR(Q36/R36,0)-1)) -> 0.60452143 | V36: 33950 | W36: 49533.5 | X36: 65500 | Y36: =IF((IFERROR(W36/V36,0))=0,0,(IFERROR(W36/V36,0)-1)) -> 0.45901325 | Z36: =IF((IFERROR(W36/X36,0))=0,0,(IFERROR(W36/X36,0)-1)) -> -0.24376336
B37: 601-002-003-00 | C37: Costo Venta Publicaciones | D37: =Resumen!I38 -> 574300 | E37: =SUMIF('México Summary'!$C:$C,'Resumen (Caps)'!B37,'México Summary'!$AC:$AC) -> 542341.8 | F37: 420000 | G37: =IF((IFERROR(E37/D37,0))=0,0,(IFERROR(E37/D37,0)-1)) -> -0.055647223 | H37: =IF((IFERROR(E37/F37,0))=0,0,(IFERROR(E37/F37,0)-1)) -> 0.29129
B38: 601-003-001-00 | C38: Costo Digital Training | D38: =Resumen!I39 -> 577000.27 | E38: =SUMIF('México Summary'!$C:$C,'Resumen (Caps)'!B38,'México Summary'!$AC:$AC) -> 726325 | F38: 0 | G38: =IF((IFERROR(E38/D38,0))=0,0,(IFERROR(E38/D38,0)-1)) -> 0.2587949 | H38: =IF((IFERROR(E38/F38,0))=0,0,(IFERROR(E38/F38,0)-1)) -> 0
C39: Gastos Administrativos | D39: =SUM(D40:D52) -> 4160868.6 | E39: =SUM(E40:E52) -> 4705358 | F39: =SUM(F40:F52) -> 5070086.1 | G39: =IF((IFERROR(E39/D39,0))=0,0,(IFERROR(E39/D39,0)-1)) -> 0.13085955 | H39: =IF((IFERROR(E39/F39,0))=0,0,(IFERROR(E39/F39,0)-1)) -> -0.071937258 | J39: 302430.6 | K39: 496408.94 | L39: 532937.82 | M39: =IF((IFERROR(K39/J39,0))=0,0,(IFERROR(K39/J39,0)-1)) -> 0.64139786 | N39: =IF((IFERROR(K39/L39,0))=0,0,(IFERROR(K39/L39,0)-1)) -> -0.06854248 | P39: 791370.32 | Q39: 995988.15 | R39: 935209.05 | S39: =IF((IFERROR(Q39/P39,0))=0,0,(IFERROR(Q39/P39,0)-1)) -> 0.25856142 | T39: =IF((IFERROR(Q39/R39,0))=0,0,(IFERROR(Q39/R39,0)-1)) -> 0.064989854 | V39: 346977.56 | W39: 1117643.7 | X39: 1615380.4 | Y39: =IF((IFERROR(W39/V39,0))=0,0,(IFERROR(W39/V39,0)-1)) -> 2.2210835 | Z39: =IF((IFERROR(W39/X39,0))=0,0,(IFERROR(W39/X39,0)-1)) -> -0.30812351
B40: 801-001-000-00 | C40: Desarrollo de Negocios | D40: =Resumen!I41 -> 448434.14 | E40: =SUMIF('México Summary'!$C:$C,'Resumen (Caps)'!B40,'México Summary'!$AC:$AC) -> 656495.11 | F40: 579831.32 | G40: =IF((IFERROR(E40/D40,0))=0,0,(IFERROR(E40/D40,0)-1)) -> 0.46397219 | H40: =IF((IFERROR(E40/F40,0))=0,0,(IFERROR(E40/F40,0)-1)) -> 0.1322174 | P40: 3082099.9 | Q40: 4240697.9 | R40: 3404584.7
B41: 801-002-000-00 | C41: Relaciones Externas | D41: =Resumen!I42 -> 0 | E41: =SUMIF('México Summary'!$C:$C,'Resumen (Caps)'!B41,'México Summary'!$AC:$AC) -> 0 | F41: 0 | G41: =IF((IFERROR(E41/D41,0))=0,0,(IFERROR(E41/D41,0)-1)) -> 0 | H41: =IF((IFERROR(E41/F41,0))=0,0,(IFERROR(E41/F41,0)-1)) -> 0
...

Sheet Copia de Resumen (Caps)
D1: MX | J1: GDL | P1: NE | V1: NO
D2: Forecast 9+3 | E2: Ppto. 2026 | F2: Ppto. 2025 | G2: Variación Ppto. 2026 vs Forecast 2025 | H2: Variación Ppto. 2025 vs Ppto. 2026 | J2: Forecast 9+3 | K2: Ppto. 2026 | L2: Ppto. 2025 | M2: Variación Ppto. 2026 vs Forecast 2025 | N2: Variación Ppto. 2025 vs Ppto. 2026 | P2: Forecast 9+3 | Q2: Ppto. 2026 | R2: Ppto. 2025 | S2: Variación Ppto. 2026 vs Forecast 2025 | T2: Variación Ppto. 2025 vs Ppto. 2026 | V2: Forecast 9+3 | W2: Ppto. 2026 | X2: Ppto. 2025 | Y2: Variación Ppto. 2026 vs Forecast 2025 | Z2: Variación Ppto. 2025 vs Ppto. 2026
C4: INCOME | D4: =SUM(D5,D8,D11,D16,D14) -> 63870318 | E4: =SUM(E5,E8,E11,E16,E14) -> 71683976 | F4: =SUM(F5,F8,F11,F16,F14) -> 62529782 | G4: =IF((IFERROR(E4/D4,0))=0,0,(IFERROR(E4/D4,0)-1)) -> 0.1223363 | H4: =IF((IFERROR(E4/F4,0))=0,0,(IFERROR(E4/F4,0)-1)) -> 0.14639734 | J4: =J5+J8+J11+J14+J16 -> 15701008 | K4: =K5+K8+K11+K14+K16 -> 18595805 | L4: =L5+L8+L11+L14+L16 -> 17294316 | M4: =IF((IFERROR(K4/J4,0))=0,0,(IFERROR(K4/J4,0)-1)) -> 0.18437017 | N4: =IF((IFERROR(K4/L4,0))=0,0,(IFERROR(K4/L4,0)-1)) -> 0.075255328 | P4: =P5+P8+P11+P14+P16 -> 34776476 | Q4: =Q5+Q8+Q11+Q14+Q16 -> 39308309 | R4: =R5+R8+R11+R14+R16 -> 34972433 | S4: =IF((IFERROR(Q4/P4,0))=0,0,(IFERROR(Q4/P4,0)-1)) -> 0.13031318 | T4: =IF((IFERROR(Q4/R4,0))=0,0,(IFERROR(Q4/R4,0)-1)) -> 0.12397981 | V4: =V5+V8+V11+V14+V16 -> 6305605.7 | W4: =W5+W8+W11+W14+W16 -> 7584619.4 | X4: =X5+X8+X11+X14+X16 -> 8173413.7 | Y4: =IF((IFERROR(W4/V4,0))=0,0,(IFERROR(W4/V4,0)-1)) -> 0.20283756 | Z4: =IF((IFERROR(W4/X4,0))=0,0,(IFERROR(W4/X4,0)-1)) -> -0.072037743
C5: Membership | D5: =D6+D7 -> 41169436 | E5: =E6+E7 -> 46872450 | F5: =F6+F7 -> 37282030 | G5: =IF((IFERROR(E5/D5,0))=0,0,(IFERROR(E5/D5,0)-1)) -> 0.13852542 | H5: =IF((IFERROR(E5/F5,0))=0,0,(IFERROR(E5/F5,0)-1)) -> 0.25723974 | J5: 11002476 | K5: 12582798 | L5: 10909089 | M5: =IF((IFERROR(K5/J5,0))=0,0,(IFERROR(K5/J5,0)-1)) -> 0.1436333 | N5: =IF((IFERROR(K5/L5,0))=0,0,(IFERROR(K5/L5,0)-1)) -> 0.15342338 | P5: 25760437 | Q5: 29947770 | R5: 24786483 | S5: =IF((IFERROR(Q5/P5,0))=0,0,(IFERROR(Q5/P5,0)-1)) -> 0.16254899 | T5: =IF((IFERROR(Q5/R5,0))=0,0,(IFERROR(Q5/R5,0)-1)) -> 0.2082299 | V5: 5682055.7 | W5: 6828618.2 | X5: 7502413.7 | Y5: =IF((IFERROR(W5/V5,0))=0,0,(IFERROR(W5/V5,0)-1)) -> 0.20178656 | Z5: =IF((IFERROR(W5/X5,0))=0,0,(IFERROR(W5/X5,0)-1)) -> -0.089810493
B6: 401-000-000-00 | C6: Cuotas Netas | D6: 39828015 | E6: =SUMIF('México Summary'!$C:$C,'Copia de Resumen (Caps)'!B6,'México Summary'!$AC:$AC) -> 45370058 | F6: 36117362 | G6: =IF((IFERROR(E6/D6,0))=0,0,(IFERROR(E6/D6,0)-1)) -> 0.13914937 | H6: =IF((IFERROR(E6/F6,0))=0,0,(IFERROR(E6/F6,0)-1)) -> 0.25618416
B7: 402-000-000-00 | C7: Ingresos socios nuevos | D7: 1341420.9 | E7: =SUMIF('México Summary'!$C:$C,'Copia de Resumen (Caps)'!B7,'México Summary'!$AC:$AC) -> 1502391.4 | F7: 1164667.8 | G7: =IF((IFERROR(E7/D7,0))=0,0,(IFERROR(E7/D7,0)-1)) -> 0.12 | H7: =IF((IFERROR(E7/F7,0))=0,0,(IFERROR(E7/F7,0)-1)) -> 0.2899742
C8: Events | D8: =D9+D10 -> 13199629 | E8: =E9+E10 -> 11511191 | F8: =F9+F10 -> 12957002 | G8: =IF((IFERROR(E8/D8,0))=0,0,(IFERROR(E8/D8,0)-1)) -> -0.12791558 | H8: =IF((IFERROR(E8/F8,0))=0,0,(IFERROR(E8/F8,0)-1)) -> -0.1115853 | J8: 3199282.8 | K8: 3901776 | L8: 4100000 | M8: =IF((IFERROR(K8/J8,0))=0,0,(IFERROR(K8/J8,0)-1)) -> 0.21957836 | N8: =IF((IFERROR(K8/L8,0))=0,0,(IFERROR(K8/L8,0)-1)) -> -0.048347308 | P8: 5581851.8 | Q8: 6374997.9 | R8: 5632000 | S8: =IF((IFERROR(Q8/P8,0))=0,0,(IFERROR(Q8/P8,0)-1)) -> 0.14209372 | T8: =IF((IFERROR(Q8/R8,0))=0,0,(IFERROR(Q8/R8,0)-1)) -> 0.13192435 | V8: 509450 | W8: 560395 | X8: 440000 | Y8: =IF((IFERROR(W8/V8,0))=0,0,(IFERROR(W8/V8,0)-1)) -> 0.1 | Z8: =IF((IFERROR(W8/X8,0))=0,0,(IFERROR(W8/X8,0)-1)) -> 0.273625
B9: 407-000-000-00 | C9: Eventos | D9: 2649840.2 | E9: =SUMIF('México Summary'!$C:$C,'Copia de Resumen (Caps)'!B9,'México Summary'!$AC:$AC) -> 1460000 | F9: 2250000 | G9: =IF((IFERROR(E9/D9,0))=0,0,(IFERROR(E9/D9,0)-1)) -> -0.44902337 | H9: =IF((IFERROR(E9/F9,0))=0,0,(IFERROR(E9/F9,0)-1)) -> -0.35111111
B10: 408-000-000-00 | C10: Patrocinios | D10: 10549789 | E10: =SUMIF('México Summary'!$C:$C,'Copia de Resumen (Caps)'!B10,'México Summary'!$AC:$AC) -> 10051191 | F10: 10707002 | G10: =IF((IFERROR(E10/D10,0))=0,0,(IFERROR(E10/D10,0)-1)) -> -0.047261423 | H10: =IF((IFERROR(E10/F10,0))=0,0,(IFERROR(E10/F10,0)-1)) -> -0.061250657
C11: Committees | D11: =D12+D13 -> 8327352.3 | E11: =E12+E13 -> 9775090 | F11: =F12+F13 -> 11450750 | G11: =IF((IFERROR(E11/D11,0))=0,0,(IFERROR(E11/D11,0)-1)) -> 0.1738533 | H11: =IF((IFERROR(E11/F11,0))=0,0,(IFERROR(E11/F11,0)-1)) -> -0.14633627 | J11: 819041.89 | K11: 1347321.1 | L11: 1718000 | M11: =IF((IFERROR(K11/J11,0))=0,0,(IFERROR(K11/J11,0)-1)) -> 0.64499652 | N11: =IF((IFERROR(K11/L11,0))=0,0,(IFERROR(K11/L11,0)-1)) -> -0.2157619 | P11: 1518924.9 | Q11: 1663666.9 | R11: 2593050 | S11: =IF((IFERROR(Q11/P11,0))=0,0,(IFERROR(Q11/P11,0)-1)) -> 0.095292386 | T11: =IF((IFERROR(Q11/R11,0))=0,0,(IFERROR(Q11/R11,0)-1)) -> -0.35841311 | V11: 20000 | W11: 22000 | X11: 100000 | Y11: =IF((IFERROR(W11/V11,0))=0,0,(IFERROR(W11/V11,0)-1)) -> 0.1 | Z11: =IF((IFERROR(W11/X11,0))=0,0,(IFERROR(W11/X11,0)-1)) -> -0.78
B12: 417-000-000-00 | C12: Comités | D12: 7451647.3 | E12: =SUMIF('México Summary'!$C:$C,'Copia de Resumen (Caps)'!B12,'México Summary'!$AC:$AC) -> 8675090 | F12: 10800750 | G12: =IF((IFERROR(E12/D12,0))=0,0,(IFERROR(E12/D12,0)-1)) -> 0.16418419 | H12: =IF((IFERROR(E12/F12,0))=0,0,(IFERROR(E12/F12,0)-1)) -> -0.1968067
B13: 412-000-000-00 | C13: Economex | D13: 875704.99 | E13: =SUMIF('México Summary'!$C:$C,'Copia de Resumen (Caps)'!B13,'México Summary'!$AC:$AC) -> 1100000 | F13: 650000 | G13: =IF((IFERROR(E13/D13,0))=0,0,(IFERROR(E13/D13,0)-1)) -> 0.25613079 | H13: =IF((IFERROR(E13/F13,0))=0,0,(IFERROR(E13/F13,0)-1)) -> 0.69230769
C14: T&IC | D14: =D15 -> 0 | E14: =E15 -> 840000 | F14: =F15 -> 0 | G14: =IF((IFERROR(E14/D14,0))=0,0,(IFERROR(E14/D14,0)-1)) -> 0 | H14: =IF((IFERROR(E14/F14,0))=0,0,(IFERROR(E14/F14,0)-1)) -> 0 | J14: 0 | K14: 49692.8 | L14: 0 | M14: =IF((IFERROR(K14/J14,0))=0,0,(IFERROR(K14/J14,0)-1)) -> 0 | N14: =IF((IFERROR(K14/L14,0))=0,0,(IFERROR(K14/L14,0)-1)) -> 0 | P14: 1040862.1 | Q14: 403754 | R14: 1450000 | S14: =IF((IFERROR(Q14/P14,0))=0,0,(IFERROR(Q14/P14,0)-1)) -> -0.61209654 | T14: =IF((IFERROR(Q14/R14,0))=0,0,(IFERROR(Q14/R14,0)-1)) -> -0.72154897 | V14: 0 | W14: 74539.2 | X14: 0 | Y14: =IF((IFERROR(W14/V14,0))=0,0,(IFERROR(W14/V14,0)-1)) -> 0 | Z14: =IF((IFERROR(W14/X14,0))=0,0,(IFERROR(W14/X14,0)-1)) -> 0
B15: 405-000-000-00 | C15: Trade & Investment Center | D15: 0 | E15: =SUMIF('México Summary'!$C:$C,'Copia de Resumen (Caps)'!B15,'México Summary'!$AC:$AC) -> 840000 | F15: 0 | G15: =IF((IFERROR(E15/D15,0))=0,0,(IFERROR(E15/D15,0)-1)) -> 0 | H15: =IF((IFERROR(E15/F15,0))=0,0,(IFERROR(E15/F15,0)-1)) -> 0
C16: Services to Members | D16: =D17+D19+D18 -> 1173900 | E16: =E17+E19+E18 -> 2685245 | F16: =F17+F19+F18 -> 840000 | G16: =IF((IFERROR(E16/D16,0))=0,0,(IFERROR(E16/D16,0)-1)) -> 1.2874563 | H16: =IF((IFERROR(E16/F16,0))=0,0,(IFERROR(E16/F16,0)-1)) -> 2.1967202 | J16: 680206.7 | K16: 714217.03 | L16: 567226.8 | M16: =IF((IFERROR(K16/J16,0))=0,0,(IFERROR(K16/J16,0)-1)) -> 0.05 | N16: =IF((IFERROR(K16/L16,0))=0,0,(IFERROR(K16/L16,0)-1)) -> 0.25913838 | P16: 874400 | Q16: 918120 | R16: 510900 | S16: =IF((IFERROR(Q16/P16,0))=0,0,(IFERROR(Q16/P16,0)-1)) -> 0.05 | T16: =IF((IFERROR(Q16/R16,0))=0,0,(IFERROR(Q16/R16,0)-1)) -> 0.797064 | V16: 94100 | W16: 99067 | X16: 131000 | Y16: =IF((IFERROR(W16/V16,0))=0,0,(IFERROR(W16/V16,0)-1)) -> 0.052784272 | Z16: =IF((IFERROR(W16/X16,0))=0,0,(IFERROR(W16/X16,0)-1)) -> -0.24376336
B17: 406-001-000-00 | C17: Venta Publicaciones | D17: 1173900 | E17: =SUMIF('México Summary'!$C:$C,'Copia de Resumen (Caps)'!B17,'México Summary'!$AC:$AC) -> 1232595 | F17: 840000 | G17: =IF((IFERROR(E17/D17,0))=0,0,(IFERROR(E17/D17,0)-1)) -> 0.05 | H17: =IF((IFERROR(E17/F17,0))=0,0,(IFERROR(E17/F17,0)-1)) -> 0.467375
B18: 406-002-000-00 | C18: Digital Training | D18: 0 | E18: =SUMIF('México Summary'!$C:$C,'Copia de Resumen (Caps)'!B18,'México Summary'!$AC:$AC) -> 1452650 | F18: 0 | G18: =IF((IFERROR(E18/D18,0))=0,0,(IFERROR(E18/D18,0)-1)) -> 0 | H18: =IF((IFERROR(E18/F18,0))=0,0,(IFERROR(E18/F18,0)-1)) -> 0
B19: 409-000-000-00 | C19: Visas | D19: 0 | E19: =SUMIF('México Summary'!$C:$C,'Copia de Resumen (Caps)'!B19,'México Summary'!$AC:$AC) -> 0 | F19: 0 | G19: =IF((IFERROR(E19/D19,0))=0,0,(IFERROR(E19/D19,0)-1)) -> 0 | H19: =IF((IFERROR(E19/F19,0))=0,0,(IFERROR(E19/F19,0)-1)) -> 0
B20: 450-001-000-00 | C20: Guadalajara Income | D20: 0 | E20: =SUMIF('México Summary'!$C:$C,'Copia de Resumen (Caps)'!B20,'México Summary'!$AC:$AC) -> 0 | F20: 0 | G20: =IF((IFERROR(E20/D20,0))=0,0,(IFERROR(E20/D20,0)-1)) -> 0 | H20: =IF((IFERROR(E20/F20,0))=0,0,(IFERROR(E20/F20,0)-1)) -> 0
B21: 450-002-000-00 | C21: Monterrey Income | D21: 0 | E21: =SUMIF('México Summary'!$C:$C,'Copia de Resumen (Caps)'!B21,'México Summary'!$AC:$AC) -> 0 | F21: 0 | G21: =IF((IFERROR(E21/D21,0))=0,0,(IFERROR(E21/D21,0)-1)) -> 0 | H21: =IF((IFERROR(E21/F21,0))=0,0,(IFERROR(E21/F21,0)-1)) -> 0
B22: 450-003-000-00 | C22: Northwest Income | D22: 0 | E22: =SUMIF('México Summary'!$C:$C,'Copia de Resumen (Caps)'!B22,'México Summary'!$AC:$AC) -> 0 | F22: 0 | G22: =IF((IFERROR(E22/D22,0))=0,0,(IFERROR(E22/D22,0)-1)) -> 0 | H22: =IF((IFERROR(E22/F22,0))=0,0,(IFERROR(E22/F22,0)-1)) -> 0
C23: CONSOLIDATED INCOME | D23: =D22+D21+D20+D4 -> 63870318 | E23: =E22+E21+E20+E4 -> 71683976 | F23: =F22+F21+F20+F4 -> 62529782 | G23: =IF((IFERROR(E23/D23,0))=0,0,(IFERROR(E23/D23,0)-1)) -> 0.1223363 | H23: =IF((IFERROR(E23/F23,0))=0,0,(IFERROR(E23/F23,0)-1)) -> 0.14639734
C24: EXPENSE | D24: =D25+D28+D30+D36+D39+D53+D54+D62 -> 61514669 | E24: =E25+E28+E30+E36+E39+E53+E54+E62+E34 -> 71775247 | F24: =F25+F28+F30+F36+F39+F53+F54+F62 -> 61625391 | G24: =IF((IFERROR(E24/D24,0))=0,0,(IFERROR(E24/D24,0)-1)) -> 0.16679888 | H24: =IF((IFERROR(E24/F24,0))=0,0,(IFERROR(E24/F24,0)-1)) -> 0.1647025 | J24: =J25+J28+J30+J34+J36+J39+J53+J54+J62 -> 15592230 | K24: =K25+K28+K30+K34+K36+K39+K53+K54+K62 -> 18020999 | L24: =L25+L28+L30+L34+L36+L39+L53+L54+L62 -> 16453320 | M24: =IF((IFERROR(K24/J24,0))=0,0,(IFERROR(K24/J24,0)-1)) -> 0.15576791 | N24: =IF((IFERROR(K24/L24,0))=0,0,(IFERROR(K24/L24,0)-1)) -> 0.095280383 | P24: =P25+P28+P30+P34+P36+P39+P53+P54+P62 -> 33952718 | Q24: =Q25+Q28+Q30+Q34+Q36+Q39+Q53+Q54+Q62 -> 38742220 | R24: =R25+R28+R30+R34+R36+R39+R53+R54+R62 -> 33410427 | S24: =IF((IFERROR(Q24/P24,0))=0,0,(IFERROR(Q24/P24,0)-1)) -> 0.14106389 | T24: =IF((IFERROR(Q24/R24,0))=0,0,(IFERROR(Q24/R24,0)-1)) -> 0.15958469 | V24: =V25+V28+V30+V34+V36+V39+V53+V54+V62 -> 4887742.8 | W24: =W25+W28+W30+W34+W36+W39+W53+W54+W62 -> 6337240.5 | X24: =X25+X28+X30+X34+X36+X39+X53+X54+X62 -> 5864476.4 | Y24: =IF((IFERROR(W24/V24,0))=0,0,(IFERROR(W24/V24,0)-1)) -> 0.29655768 | Z24: =IF((IFERROR(W24/X24,0))=0,0,(IFERROR(W24/X24,0)-1)) -> 0.080614883
C25: Membership | D25: =D26+D27 -> 2777026.4 | E25: =E26+E27 -> 2949107.9 | F25: =F26+F27 -> 2584139.3 | G25: =IF((IFERROR(E25/D25,0))=0,0,(IFERROR(E25/D25,0)-1)) -> 0.061966102 | H25: =IF((IFERROR(E25/F25,0))=0,0,(IFERROR(E25/F25,0)-1)) -> 0.14123409 | J25: 482307.62 | K25: 522373.81 | L25: 675870.6 | M25: =IF((IFERROR(K25/J25,0))=0,0,(IFERROR(K25/J25,0)-1)) -> 0.083071863 | N25: =IF((IFERROR(K25/L25,0))=0,0,(IFERROR(K25/L25,0)-1)) -> -0.22710973 | P25: 1793471.4 | Q25: 1901079.7 | R25: 2224320 | S25: =IF((IFERROR(Q25/P25,0))=0,0,(IFERROR(Q25/P25,0)-1)) -> 0.06 | T25: =IF((IFERROR(Q25/R25,0))=0,0,(IFERROR(Q25/R25,0)-1)) -> -0.14532097 | V25: 318541 | W25: 369485.92 | X25: 618375 | Y25: =IF((IFERROR(W25/V25,0))=0,0,(IFERROR(W25/V25,0)-1)) -> 0.15993207 | Z25: =IF((IFERROR(W25/X25,0))=0,0,(IFERROR(W25/X25,0)-1)) -> -0.40248891
B26: 705-000-000-00 | C26: Gastos Promoción | D26: 832000 | E26: =SUMIF('México Summary'!$C:$C,'Copia de Resumen (Caps)'!B26,'México Summary'!$AC:$AC) -> 887380 | F26: 863500 | G26: =IF((IFERROR(E26/D26,0))=0,0,(IFERROR(E26/D26,0)-1)) -> 0.0665625 | H26: =IF((IFERROR(E26/F26,0))=0,0,(IFERROR(E26/F26,0)-1)) -> 0.027654893
B27: 520-000-000-00 | C27: Comsiones por venta de membresía | D27: 1945026.4 | E27: =SUMIF('México Summary'!$C:$C,'Copia de Resumen (Caps)'!B27,'México Summary'!$AC:$AC) -> 2061727.9 | F27: 1720639.3 | G27: =IF((IFERROR(E27/D27,0))=0,0,(IFERROR(E27/D27,0)-1)) -> 0.059999958 | H27: =IF((IFERROR(E27/F27,0))=0,0,(IFERROR(E27/F27,0)-1)) -> 0.19823362
C28: Events | D28: =D29 -> 8552654.8 | E28: =E29 -> 6727036.8 | F28: =F29 -> 9107000 | G28: =IF((IFERROR(E28/D28,0))=0,0,(IFERROR(E28/D28,0)-1)) -> -0.21345629 | H28: =IF((IFERROR(E28/F28,0))=0,0,(IFERROR(E28/F28,0)-1)) -> -0.26133339 | J28: 2341278.1 | K28: 2042171.9 | L28: 2956045 | M28: =IF((IFERROR(K28/J28,0))=0,0,(IFERROR(K28/J28,0)-1)) -> -0.12775339 | N28: =IF((IFERROR(K28/L28,0))=0,0,(IFERROR(K28/L28,0)-1)) -> -0.30915398 | P28: 4183139.5 | Q28: 4244536.5 | R28: 4450000 | S28: =IF((IFERROR(Q28/P28,0))=0,0,(IFERROR(Q28/P28,0)-1)) -> 0.014677242 | T28: =IF((IFERROR(Q28/R28,0))=0,0,(IFERROR(Q28/R28,0)-1)) -> -0.046171573 | V28: 234008.52 | W28: 218797.96 | X28: 270000 | Y28: =IF((IFERROR(W28/V28,0))=0,0,(IFERROR(W28/V28,0)-1)) -> -0.065000026 | Z28: =IF((IFERROR(W28/X28,0))=0,0,(IFERROR(W28/X28,0)-1)) -> -0.18963719
B29: 701-000-000-00 | C29: Costo Eventos | D29: 8552654.8 | E29: =SUMIF('México Summary'!$C:$C,'Copia de Resumen (Caps)'!B29,'México Summary'!$AC:$AC) -> 6727036.8 | F29: 9107000 | G29: =IF((IFERROR(E29/D29,0))=0,0,(IFERROR(E29/D29,0)-1)) -> -0.21345629 | H29: =IF((IFERROR(E29/F29,0))=0,0,(IFERROR(E29/F29,0)-1)) -> -0.26133339
C30: Committees | D30: =SUM(D31:D33) -> 5477932.2 | E30: =SUM(E31:E33) -> 6940491.4 | F30: =SUM(F31:F33) -> 8604867.1 | G30: =IF((IFERROR(E30/D30,0))=0,0,(IFERROR(E30/D30,0)-1)) -> 0.26699111 | H30: =IF((IFERROR(E30/F30,0))=0,0,(IFERROR(E30/F30,0)-1)) -> -0.19342258 | J30: 776370.91 | K30: 776297.49 | L30: 896480 | M30: =IF((IFERROR(K30/J30,0))=0,0,(IFERROR(K30/J30,0)-1)) -> -9.4569489e-05 | N30: =IF((IFERROR(K30/L30,0))=0,0,(IFERROR(K30/L30,0)-1)) -> -0.13406045 | P30: 1413380.4 | Q30: 1495707.2 | R30: 1744550 | S30: =IF((IFERROR(Q30/P30,0))=0,0,(IFERROR(Q30/P30,0)-1)) -> 0.058248158 | T30: =IF((IFERROR(Q30/R30,0))=0,0,(IFERROR(Q30/R30,0)-1)) -> -0.14264008 | V30: 12000 | W30: 13200 | X30: 60000 | Y30: =IF((IFERROR(W30/V30,0))=0,0,(IFERROR(W30/V30,0)-1)) -> 0.1 | Z30: =IF((IFERROR(W30/X30,0))=0,0,(IFERROR(W30/X30,0)-1)) -> -0.78
B31: 702-000-000-00 | C31: Costo Comités | D31: 4236122.3 | E31: =SUMIF('México Summary'!$C:$C,'Copia de Resumen (Caps)'!B31,'México Summary'!$AC:$AC) -> 5438618.2 | F31: 7363267.1 | G31: =IF((IFERROR(E31/D31,0))=0,0,(IFERROR(E31/D31,0)-1)) -> 0.28386715 | H31: =IF((IFERROR(E31/F31,0))=0,0,(IFERROR(E31/F31,0)-1)) -> -0.26138517
B32: 704-000-000-00 | C32: Costo Economex | D32: 1060899.9 | E32: =SUMIF('México Summary'!$C:$C,'Copia de Resumen (Caps)'!B32,'México Summary'!$AC:$AC) -> 1299254 | F32: 1081600 | G32: =IF((IFERROR(E32/D32,0))=0,0,(IFERROR(E32/D32,0)-1)) -> 0.22467156 | H32: =IF((IFERROR(E32/F32,0))=0,0,(IFERROR(E32/F32,0)-1)) -> 0.20123336
B33: 521-000-000-00 | C33: Comisiones EWDP y Economex | D33: 180910 | E33: =SUMIF('México Summary'!$C:$C,'Copia de Resumen (Caps)'!B33,'México Summary'!$AC:$AC) -> 202619.2 | F33: 160000 | G33: =IF((IFERROR(E33/D33,0))=0,0,(IFERROR(E33/D33,0)-1)) -> 0.12 | H33: =IF((IFERROR(E33/F33,0))=0,0,(IFERROR(E33/F33,0)-1)) -> 0.26637
C34: T&IC | D34: =D35 -> 0 | E34: =E35 -> 340000 | F34: =F35 -> 0 | G34: =IF((IFERROR(E34/D34,0))=0,0,(IFERROR(E34/D34,0)-1)) -> 0 | H34: =IF((IFERROR(E34/F34,0))=0,0,(IFERROR(E34/F34,0)-1)) -> 0 | J34: 0 | K34: 17808 | L34: 0 | M34: =IF((IFERROR(K34/J34,0))=0,0,(IFERROR(K34/J34,0)-1)) -> 0 | N34: =IF((IFERROR(K34/L34,0))=0,0,(IFERROR(K34/L34,0)-1)) -> 0 | P34: 723930.21 | Q34: 144690 | R34: 1250000 | S34: =IF((IFERROR(Q34/P34,0))=0,0,(IFERROR(Q34/P34,0)-1)) -> -0.80013267 | T34: =IF((IFERROR(Q34/R34,0))=0,0,(IFERROR(Q34/R34,0)-1)) -> -0.884248 | V34: 0 | W34: 26712 | X34: 0 | Y34: =IF((IFERROR(W34/V34,0))=0,0,(IFERROR(W34/V34,0)-1)) -> 0 | Z34: =IF((IFERROR(W34/X34,0))=0,0,(IFERROR(W34/X34,0)-1)) -> 0
B35: 703-000-000-00 | C35: Costo Trade & Investment Center | D35: 0 | E35: =SUMIF('México Summary'!$C:$C,'Copia de Resumen (Caps)'!B35,'México Summary'!$AC:$AC) -> 340000 | F35: 0 | G35: =IF((IFERROR(E35/D35,0))=0,0,(IFERROR(E35/D35,0)-1)) -> 0 | H35: =IF((IFERROR(E35/F35,0))=0,0,(IFERROR(E35/F35,0)-1)) -> 0
C36: Services to Members | D36: =D37+D38 -> 557700 | E36: =E37+E38 -> 1268666.8 | F36: =F37+F38 -> 420000 | G36: =IF((IFERROR(E36/D36,0))=0,0,(IFERROR(E36/D36,0)-1)) -> 1.2748194 | H36: =IF((IFERROR(E36/F36,0))=0,0,(IFERROR(E36/F36,0)-1)) -> 2.0206352 | J36: 340103.35 | K36: 357108.52 | L36: 283613.4 | M36: =IF((IFERROR(K36/J36,0))=0,0,(IFERROR(K36/J36,0)-1)) -> 0.05 | N36: =IF((IFERROR(K36/L36,0))=0,0,(IFERROR(K36/L36,0)-1)) -> 0.25913838 | P36: 444274 | Q36: 459060 | R36: 286104 | S36: =IF((IFERROR(Q36/P36,0))=0,0,(IFERROR(Q36/P36,0)-1)) -> 0.033281263 | T36: =IF((IFERROR(Q36/R36,0))=0,0,(IFERROR(Q36/R36,0)-1)) -> 0.60452143 | V36: 47050 | W36: 49533.5 | X36: 65500 | Y36: =IF((IFERROR(W36/V36,0))=0,0,(IFERROR(W36/V36,0)-1)) -> 0.052784272 | Z36: =IF((IFERROR(W36/X36,0))=0,0,(IFERROR(W36/X36,0)-1)) -> -0.24376336
B37: 601-002-003-00 | C37: Costo Venta Publicaciones | D37: 557700 | E37: =SUMIF('México Summary'!$C:$C,'Copia de Resumen (Caps)'!B37,'México Summary'!$AC:$AC) -> 542341.8 | F37: 420000 | G37: =IF((IFERROR(E37/D37,0))=0,0,(IFERROR(E37/D37,0)-1)) -> -0.027538462 | H37: =IF((IFERROR(E37/F37,0))=0,0,(IFERROR(E37/F37,0)-1)) -> 0.29129
B38: 601-003-001-00 | C38: Costo Digital Training | D38: 0 | E38: =SUMIF('México Summary'!$C:$C,'Copia de Resumen (Caps)'!B38,'México Summary'!$AC:$AC) -> 726325 | F38: 0 | G38: =IF((IFERROR(E38/D38,0))=0,0,(IFERROR(E38/D38,0)-1)) -> 0 | H38: =IF((IFERROR(E38/F38,0))=0,0,(IFERROR(E38/F38,0)-1)) -> 0
C39: Gastos Administrativos | D39: =SUM(D40:D52) -> 4141199.2 | E39: =SUM(E40:E52) -> 4705358 | F39: =SUM(F40:F52) -> 5070086.1 | G39: =IF((IFERROR(E39/D39,0))=0,0,(IFERROR(E39/D39,0)-1)) -> 0.13623078 | H39: =IF((IFERROR(E39/F39,0))=0,0,(IFERROR(E39/F39,0)-1)) -> -0.071937258 | J39: 402867.07 | K39: 496408.94 | L39: 532937.82 | M39: =IF((IFERROR(K39/J39,0))=0,0,(IFERROR(K39/J39,0)-1)) -> 0.23219042 | N39: =IF((IFERROR(K39/L39,0))=0,0,(IFERROR(K39/L39,0)-1)) -> -0.068542472 | P39: 976028.67 | Q39: 995988.15 | R39: 935209.05 | S39: =IF((IFERROR(Q39/P39,0))=0,0,(IFERROR(Q39/P39,0)-1)) -> 0.020449687 | T39: =IF((IFERROR(Q39/R39,0))=0,0,(IFERROR(Q39/R39,0)-1)) -> 0.064989855 | V39: 703279.36 | W39: 1393114.2 | X39: 1615380.4 | Y39: =IF((IFERROR(W39/V39,0))=0,0,(IFERROR(W39/V39,0)-1)) -> 0.98088316 | Z39: =IF((IFERROR(W39/X39,0))=0,0,(IFERROR(W39/X39,0)-1)) -> -0.13759367
B40: 801-001-000-00 | C40: Desarrollo de Negocios | D40: 477398.26 | E40: =SUMIF('México Summary'!$C:$C,'Copia de Resumen (Caps)'!B40,'México Summary'!$AC:$AC) -> 656495.11 | F40: 579831.32 | G40: =IF((IFERROR(E40/D40,0))=0,0,(IFERROR(E40/D40,0)-1)) -> 0.37515187 | H40: =IF((IFERROR(E40/F40,0))=0,0,(IFERROR(E40/F40,0)-1)) -> 0.1322174
B41: 801-002-000-00 | C41: Relaciones Externas | D41: 0 | E41: =SUMIF('México Summary'!$C:$C,'Copia de Resumen (Caps)'!B41,'México Summary'!$AC:$AC) -> 0 | F41: 0 | G41: =IF((IFERROR(E41/D41,0))=0,0,(IFERROR(E41/D41,0)-1)) -> 0 | H41: =IF((IFERROR(E41/F41,0))=0,0,(IFERROR(E41/F41,0)-1)) -> 0
...

Sheet Copia de Copia de Resumen (Caps
D1: MX | J1: GDL | P1: NE | V1: NO
D2: Forecast 9+3 | E2: Ppto. 2026 | F2: Ppto. 2025 | G2: Variación Ppto. 2026 vs Forecast 2025 | H2: Variación Ppto. 2025 vs Ppto. 2026 | J2: Forecast 9+3 | K2: Ppto. 2026 | L2: Ppto. 2025 | M2: Variación Ppto. 2026 vs Forecast 2025 | N2: Variación Ppto. 2025 vs Ppto. 2026 | P2: Forecast 9+3 | Q2: Ppto. 2026 | R2: Ppto. 2025 | S2: Variación Ppto. 2026 vs Forecast 2025 | T2: Variación Ppto. 2025 vs Ppto. 2026 | V2: Forecast 9+3 | W2: Ppto. 2026 | X2: Ppto. 2025 | Y2: Variación Ppto. 2026 vs Forecast 2025 | Z2: Variación Ppto. 2025 vs Ppto. 2026
C4: INCOME | D4: =SUM(D5,D8,D11,D16,D14) -> 63870318 | E4: =SUM(E5,E8,E11,E16,E14) -> 71683976 | F4: =SUM(F5,F8,F11,F16,F14) -> 62529782 | G4: =IF((IFERROR(E4/D4,0))=0,0,(IFERROR(E4/D4,0)-1)) -> 0.1223363 | H4: =IF((IFERROR(E4/F4,0))=0,0,(IFERROR(E4/F4,0)-1)) -> 0.14639734 | J4: =J5+J8+J11+J14+J16 -> 15701008 | K4: =K5+K8+K11+K14+K16 -> 18595805 | L4: =L5+L8+L11+L14+L16 -> 17294316 | M4: =IF((IFERROR(K4/J4,0))=0,0,(IFERROR(K4/J4,0)-1)) -> 0.18437017 | N4: =IF((IFERROR(K4/L4,0))=0,0,(IFERROR(K4/L4,0)-1)) -> 0.075255328 | P4: =P5+P8+P11+P14+P16 -> 34776476 | Q4: =Q5+Q8+Q11+Q14+Q16 -> 39308309 | R4: =R5+R8+R11+R14+R16 -> 34972433 | S4: =IF((IFERROR(Q4/P4,0))=0,0,(IFERROR(Q4/P4,0)-1)) -> 0.13031318 | T4: =IF((IFERROR(Q4/R4,0))=0,0,(IFERROR(Q4/R4,0)-1)) -> 0.12397981 | V4: =V5+V8+V11+V14+V16 -> 6305605.7 | W4: =W5+W8+W11+W14+W16 -> 7584619.4 | X4: =X5+X8+X11+X14+X16 -> 8173413.7 | Y4: =IF((IFERROR(W4/V4,0))=0,0,(IFERROR(W4/V4,0)-1)) -> 0.20283756 | Z4: =IF((IFERROR(W4/X4,0))=0,0,(IFERROR(W4/X4,0)-1)) -> -0.072037743
C5: Membership | D5: =D6+D7 -> 41169436 | E5: =E6+E7 -> 46872450 | F5: =F6+F7 -> 37282030 | G5: =IF((IFERROR(E5/D5,0))=0,0,(IFERROR(E5/D5,0)-1)) -> 0.13852542 | H5: =IF((IFERROR(E5/F5,0))=0,0,(IFERROR(E5/F5,0)-1)) -> 0.25723974 | J5: 11002476 | K5: 12582798 | L5: 10909089 | M5: =IF((IFERROR(K5/J5,0))=0,0,(IFERROR(K5/J5,0)-1)) -> 0.1436333 | N5: =IF((IFERROR(K5/L5,0))=0,0,(IFERROR(K5/L5,0)-1)) -> 0.15342338 | P5: 25760437 | Q5: 29947770 | R5: 24786483 | S5: =IF((IFERROR(Q5/P5,0))=0,0,(IFERROR(Q5/P5,0)-1)) -> 0.16254899 | T5: =IF((IFERROR(Q5/R5,0))=0,0,(IFERROR(Q5/R5,0)-1)) -> 0.2082299 | V5: 5682055.7 | W5: 6828618.2 | X5: 7502413.7 | Y5: =IF((IFERROR(W5/V5,0))=0,0,(IFERROR(W5/V5,0)-1)) -> 0.20178656 | Z5: =IF((IFERROR(W5/X5,0))=0,0,(IFERROR(W5/X5,0)-1)) -> -0.089810493
B6: 401-000-000-00 | C6: Cuotas Netas | D6: 39828015 | E6: =SUMIF('México Summary'!$C:$C,'Copia de Copia de Resumen (Caps'!B6,'México Summary'!$AC:$AC) -> 45370058 | F6: 36117362 | G6: =IF((IFERROR(E6/D6,0))=0,0,(IFERROR(E6/D6,0)-1)) -> 0.13914937 | H6: =IF((IFERROR(E6/F6,0))=0,0,(IFERROR(E6/F6,0)-1)) -> 0.25618416
B7: 402-000-000-00 | C7: Ingresos socios nuevos | D7: 1341420.9 | E7: =SUMIF('México Summary'!$C:$C,'Copia de Copia de Resumen (Caps'!B7,'México Summary'!$AC:$AC) -> 1502391.4 | F7: 1164667.8 | G7: =IF((IFERROR(E7/D7,0))=0,0,(IFERROR(E7/D7,0)-1)) -> 0.12 | H7: =IF((IFERROR(E7/F7,0))=0,0,(IFERROR(E7/F7,0)-1)) -> 0.2899742
C8: Events | D8: =D9+D10 -> 13199629 | E8: =E9+E10 -> 11511191 | F8: =F9+F10 -> 12957002 | G8: =IF((IFERROR(E8/D8,0))=0,0,(IFERROR(E8/D8,0)-1)) -> -0.12791558 | H8: =IF((IFERROR(E8/F8,0))=0,0,(IFERROR(E8/F8,0)-1)) -> -0.1115853 | J8: 3199282.8 | K8: 3901776 | L8: 4100000 | M8: =IF((IFERROR(K8/J8,0))=0,0,(IFERROR(K8/J8,0)-1)) -> 0.21957836 | N8: =IF((IFERROR(K8/L8,0))=0,0,(IFERROR(K8/L8,0)-1)) -> -0.048347308 | P8: 5581851.8 | Q8: 6374997.9 | R8: 5632000 | S8: =IF((IFERROR(Q8/P8,0))=0,0,(IFERROR(Q8/P8,0)-1)) -> 0.14209372 | T8: =IF((IFERROR(Q8/R8,0))=0,0,(IFERROR(Q8/R8,0)-1)) -> 0.13192435 | V8: 509450 | W8: 560395 | X8: 440000 | Y8: =IF((IFERROR(W8/V8,0))=0,0,(IFERROR(W8/V8,0)-1)) -> 0.1 | Z8: =IF((IFERROR(W8/X8,0))=0,0,(IFERROR(W8/X8,0)-1)) -> 0.273625
B9: 407-000-000-00 | C9: Eventos | D9: 2649840.2 | E9: =SUMIF('México Summary'!$C:$C,'Copia de Copia de Resumen (Caps'!B9,'México Summary'!$AC:$AC) -> 1460000 | F9: 2250000 | G9: =IF((IFERROR(E9/D9,0))=0,0,(IFERROR(E9/D9,0)-1)) -> -0.44902337 | H9: =IF((IFERROR(E9/F9,0))=0,0,(IFERROR(E9/F9,0)-1)) -> -0.35111111
B10: 408-000-000-00 | C10: Patrocinios | D10: 10549789 | E10: =SUMIF('México Summary'!$C:$C,'Copia de Copia de Resumen (Caps'!B10,'México Summary'!$AC:$AC) -> 10051191 | F10: 10707002 | G10: =IF((IFERROR(E10/D10,0))=0,0,(IFERROR(E10/D10,0)-1)) -> -0.047261423 | H10: =IF((IFERROR(E10/F10,0))=0,0,(IFERROR(E10/F10,0)-1)) -> -0.061250657
C11: Committees | D11: =D12+D13 -> 8327352.3 | E11: =E12+E13 -> 9775090 | F11: =F12+F13 -> 11450750 | G11: =IF((IFERROR(E11/D11,0))=0,0,(IFERROR(E11/D11,0)-1)) -> 0.1738533 | H11: =IF((IFERROR(E11/F11,0))=0,0,(IFERROR(E11/F11,0)-1)) -> -0.14633627 | J11: 819041.89 | K11: 1347321.1 | L11: 1718000 | M11: =IF((IFERROR(K11/J11,0))=0,0,(IFERROR(K11/J11,0)-1)) -> 0.64499652 | N11: =IF((IFERROR(K11/L11,0))=0,0,(IFERROR(K11/L11,0)-1)) -> -0.2157619 | P11: 1518924.9 | Q11: 1663666.9 | R11: 2593050 | S11: =IF((IFERROR(Q11/P11,0))=0,0,(IFERROR(Q11/P11,0)-1)) -> 0.095292386 | T11: =IF((IFERROR(Q11/R11,0))=0,0,(IFERROR(Q11/R11,0)-1)) -> -0.35841311 | V11: 20000 | W11: 22000 | X11: 100000 | Y11: =IF((IFERROR(W11/V11,0))=0,0,(IFERROR(W11/V11,0)-1)) -> 0.1 | Z11: =IF((IFERROR(W11/X11,0))=0,0,(IFERROR(W11/X11,0)-1)) -> -0.78
B12: 417-000-000-00 | C12: Comités | D12: 7451647.3 | E12: =SUMIF('México Summary'!$C:$C,'Copia de Copia de Resumen (Caps'!B12,'México Summary'!$AC:$AC) -> 8675090 | F12: 10800750 | G12: =IF((IFERROR(E12/D12,0))=0,0,(IFERROR(E12/D12,0)-1)) -> 0.16418419 | H12: =IF((IFERROR(E12/F12,0))=0,0,(IFERROR(E12/F12,0)-1)) -> -0.1968067
B13: 412-000-000-00 | C13: Economex | D13: 875704.99 | E13: =SUMIF('México Summary'!$C:$C,'Copia de Copia de Resumen (Caps'!B13,'México Summary'!$AC:$AC) -> 1100000 | F13: 650000 | G13: =IF((IFERROR(E13/D13,0))=0,0,(IFERROR(E13/D13,0)-1)) -> 0.25613079 | H13: =IF((IFERROR(E13/F13,0))=0,0,(IFERROR(E13/F13,0)-1)) -> 0.69230769
C14: T&IC | D14: =D15 -> 0 | E14: =E15 -> 840000 | F14: =F15 -> 0 | G14: =IF((IFERROR(E14/D14,0))=0,0,(IFERROR(E14/D14,0)-1)) -> 0 | H14: =IF((IFERROR(E14/F14,0))=0,0,(IFERROR(E14/F14,0)-1)) -> 0 | J14: 0 | K14: 49692.8 | L14: 0 | M14: =IF((IFERROR(K14/J14,0))=0,0,(IFERROR(K14/J14,0)-1)) -> 0 | N14: =IF((IFERROR(K14/L14,0))=0,0,(IFERROR(K14/L14,0)-1)) -> 0 | P14: 1040862.1 | Q14: 403754 | R14: 1450000 | S14: =IF((IFERROR(Q14/P14,0))=0,0,(IFERROR(Q14/P14,0)-1)) -> -0.61209654 | T14: =IF((IFERROR(Q14/R14,0))=0,0,(IFERROR(Q14/R14,0)-1)) -> -0.72154897 | V14: 0 | W14: 74539.2 | X14: 0 | Y14: =IF((IFERROR(W14/V14,0))=0,0,(IFERROR(W14/V14,0)-1)) -> 0 | Z14: =IF((IFERROR(W14/X14,0))=0,0,(IFERROR(W14/X14,0)-1)) -> 0
B15: 405-000-000-00 | C15: Trade & Investment Center | D15: 0 | E15: =SUMIF('México Summary'!$C:$C,'Copia de Copia de Resumen (Caps'!B15,'México Summary'!$AC:$AC) -> 840000 | F15: 0 | G15: =IF((IFERROR(E15/D15,0))=0,0,(IFERROR(E15/D15,0)-1)) -> 0 | H15: =IF((IFERROR(E15/F15,0))=0,0,(IFERROR(E15/F15,0)-1)) -> 0
C16: Services to Members | D16: =D17+D19+D18 -> 1173900 | E16: =E17+E19+E18 -> 2685245 | F16: =F17+F19+F18 -> 840000 | G16: =IF((IFERROR(E16/D16,0))=0,0,(IFERROR(E16/D16,0)-1)) -> 1.2874563 | H16: =IF((IFERROR(E16/F16,0))=0,0,(IFERROR(E16/F16,0)-1)) -> 2.1967202 | J16: 680206.7 | K16: 714217.03 | L16: 567226.8 | M16: =IF((IFERROR(K16/J16,0))=0,0,(IFERROR(K16/J16,0)-1)) -> 0.05 | N16: =IF((IFERROR(K16/L16,0))=0,0,(IFERROR(K16/L16,0)-1)) -> 0.25913838 | P16: 874400 | Q16: 918120 | R16: 510900 | S16: =IF((IFERROR(Q16/P16,0))=0,0,(IFERROR(Q16/P16,0)-1)) -> 0.05 | T16: =IF((IFERROR(Q16/R16,0))=0,0,(IFERROR(Q16/R16,0)-1)) -> 0.797064 | V16: 94100 | W16: 99067 | X16: 131000 | Y16: =IF((IFERROR(W16/V16,0))=0,0,(IFERROR(W16/V16,0)-1)) -> 0.052784272 | Z16: =IF((IFERROR(W16/X16,0))=0,0,(IFERROR(W16/X16,0)-1)) -> -0.24376336
B17: 406-001-000-00 | C17: Venta Publicaciones | D17: 1173900 | E17: =SUMIF('México Summary'!$C:$C,'Copia de Copia de Resumen (Caps'!B17,'México Summary'!$AC:$AC) -> 1232595 | F17: 840000 | G17: =IF((IFERROR(E17/D17,0))=0,0,(IFERROR(E17/D17,0)-1)) -> 0.05 | H17: =IF((IFERROR(E17/F17,0))=0,0,(IFERROR(E17/F17,0)-1)) -> 0.467375
B18: 406-002-000-00 | C18: Digital Training | D18: 0 | E18: =SUMIF('México Summary'!$C:$C,'Copia de Copia de Resumen (Caps'!B18,'México Summary'!$AC:$AC) -> 1452650 | F18: 0 | G18: =IF((IFERROR(E18/D18,0))=0,0,(IFERROR(E18/D18,0)-1)) -> 0 | H18: =IF((IFERROR(E18/F18,0))=0,0,(IFERROR(E18/F18,0)-1)) -> 0
B19: 409-000-000-00 | C19: Visas | D19: 0 | E19: =SUMIF('México Summary'!$C:$C,'Copia de Copia de Resumen (Caps'!B19,'México Summary'!$AC:$AC) -> 0 | F19: 0 | G19: =IF((IFERROR(E19/D19,0))=0,0,(IFERROR(E19/D19,0)-1)) -> 0 | H19: =IF((IFERROR(E19/F19,0))=0,0,(IFERROR(E19/F19,0)-1)) -> 0
B20: 450-001-000-00 | C20: Guadalajara Income | D20: 0 | E20: =SUMIF('México Summary'!$C:$C,'Copia de Copia de Resumen (Caps'!B20,'México Summary'!$AC:$AC) -> 0 | F20: 0 | G20: =IF((IFERROR(E20/D20,0))=0,0,(IFERROR(E20/D20,0)-1)) -> 0 | H20: =IF((IFERROR(E20/F20,0))=0,0,(IFERROR(E20/F20,0)-1)) -> 0
B21: 450-002-000-00 | C21: Monterrey Income | D21: 0 | E21: =SUMIF('México Summary'!$C:$C,'Copia de Copia de Resumen (Caps'!B21,'México Summary'!$AC:$AC) -> 0 | F21: 0 | G21: =IF((IFERROR(E21/D21,0))=0,0,(IFERROR(E21/D21,0)-1)) -> 0 | H21: =IF((IFERROR(E21/F21,0))=0,0,(IFERROR(E21/F21,0)-1)) -> 0
B22: 450-003-000-00 | C22: Northwest Income | D22: 0 | E22: =SUMIF('México Summary'!$C:$C,'Copia de Copia de Resumen (Caps'!B22,'México Summary'!$AC:$AC) -> 0 | F22: 0 | G22: =IF((IFERROR(E22/D22,0))=0,0,(IFERROR(E22/D22,0)-1)) -> 0 | H22: =IF((IFERROR(E22/F22,0))=0,0,(IFERROR(E22/F22,0)-1)) -> 0
C23: CONSOLIDATED INCOME | D23: =D22+D21+D20+D4 -> 63870318 | E23: =E22+E21+E20+E4 -> 71683976 | F23: =F22+F21+F20+F4 -> 62529782 | G23: =IF((IFERROR(E23/D23,0))=0,0,(IFERROR(E23/D23,0)-1)) -> 0.1223363 | H23: =IF((IFERROR(E23/F23,0))=0,0,(IFERROR(E23/F23,0)-1)) -> 0.14639734
C24: EXPENSE | D24: =D25+D28+D30+D36+D39+D53+D54+D62 -> 61514669 | E24: =E25+E28+E30+E36+E39+E53+E54+E62+E34 -> 71775247 | F24: =F25+F28+F30+F36+F39+F53+F54+F62 -> 61625391 | G24: =IF((IFERROR(E24/D24,0))=0,0,(IFERROR(E24/D24,0)-1)) -> 0.16679888 | H24: =IF((IFERROR(E24/F24,0))=0,0,(IFERROR(E24/F24,0)-1)) -> 0.1647025 | J24: =J25+J28+J30+J34+J36+J39+J53+J54+J62 -> 15592230 | K24: =K25+K28+K30+K34+K36+K39+K53+K54+K62 -> 18020999 | L24: =L25+L28+L30+L34+L36+L39+L53+L54+L62 -> 16453320 | M24: =IF((IFERROR(K24/J24,0))=0,0,(IFERROR(K24/J24,0)-1)) -> 0.15576791 | N24: =IF((IFERROR(K24/L24,0))=0,0,(IFERROR(K24/L24,0)-1)) -> 0.095280383 | P24: =P25+P28+P30+P34+P36+P39+P53+P54+P62 -> 33952718 | Q24: =Q25+Q28+Q30+Q34+Q36+Q39+Q53+Q54+Q62 -> 38742220 | R24: =R25+R28+R30+R34+R36+R39+R53+R54+R62 -> 33410427 | S24: =IF((IFERROR(Q24/P24,0))=0,0,(IFERROR(Q24/P24,0)-1)) -> 0.14106389 | T24: =IF((IFERROR(Q24/R24,0))=0,0,(IFERROR(Q24/R24,0)-1)) -> 0.15958469 | V24: =V25+V28+V30+V34+V36+V39+V53+V54+V62 -> 4887742.8 | W24: =W25+W28+W30+W34+W36+W39+W53+W54+W62 -> 6337240.5 | X24: =X25+X28+X30+X34+X36+X39+X53+X54+X62 -> 5864476.4 | Y24: =IF((IFERROR(W24/V24,0))=0,0,(IFERROR(W24/V24,0)-1)) -> 0.29655768 | Z24: =IF((IFERROR(W24/X24,0))=0,0,(IFERROR(W24/X24,0)-1)) -> 0.080614883
