Workbook
Name Payment_Needed: "Pago necesario"
Name Reimbursement: "Reembolso"

Sheet RESUMEN
C3: Real 2026 | D3: Ppto. 2026 | E3: Real 2025 | F3: Variación Ppto. 2026 vs Real 2026 | G3: Variación Real 2025 vs Real 2026 | H3: Ago 24 | I3: Real 2025 | J3: Ppto. 2026 | K3: Ppto. 2025 | L3: Variación Ppto. 2026 vs Real 2025 | M3: Variación Ppto. 2025 vs Ppto. 2026 | O3: Forecast 2026 | P3: Ppto. 2026 | Q3: Real 2025 | R3: Variación Ppto. 2026 vs Real 2026 | S3: Variación Real 2025 vs Real 2026 | U3: Proyectado 2026 | V3: Diferencia
C5: =SUM(C6,C9,C12,C16,C14) -> 0 | D5: =SUM(D6,D9,D12,D16,D14) -> 0 | E5: =SUM(E6,E9,E12,E16,E14) -> 0 | F5: =IF((IFERROR(C5/D5,0))=0,0,(IFERROR(C5/D5,0)-1)) -> 0 | G5: =IF((IFERROR(C5/E5,0))=0,0,(IFERROR(C5/E5,0)-1)) -> 0 | H5: INCOME | I5: =SUM(I6,I9,I12,I16,I14) -> 14195973 | J5: =SUM(J6,J9,J12,J16,J14) -> 17961606 | K5: =SUM(K6,K9,K12,K16,K14) -> 17294316 | L5: =IF((IFERROR(J5/I5,0))=0,0,(IFERROR(J5/I5,0)-1)) -> 0.26526067 | M5: =IF((IFERROR(J5/K5,0))=0,0,(IFERROR(J5/K5,0)-1)) -> 0.038584369 | O5: =SUM(O6,O9,O12,O16,O14) -> 0 | P5: =SUM(P6,P9,P12,P16,P14) -> 0 | Q5: =SUM(Q6,Q9,Q12,Q16,Q14) -> 0 | R5: =IF((IFERROR(O5/P5,0))=0,0,(IFERROR(O5/P5,0)-1)) -> 0 | S5: =IF((IFERROR(O5/Q5,0))=0,0,(IFERROR(O5/Q5,0)-1)) -> 0 | U5: =SUM(U6,U9,U12,U16,U14) -> 18374706 | V5: =SUM(V6,V9,V12,V16,V14) -> -413100.34 | W5: =J5/U5-1 -> -0.02248201
C6: =C7+C8 -> 0 | D6: =D7+D8 -> 0 | E6: =E7+E8 -> 0 | F6: =IF((IFERROR(C6/D6,0))=0,0,(IFERROR(C6/D6,0)-1)) -> 0 | G6: =IF((IFERROR(C6/E6,0))=0,0,(IFERROR(C6/E6,0)-1)) -> 0 | H6: Membership | I6: =I7+I8 -> 10543077 | J6: =J7+J8 -> 11782798 | K6: =K7+K8 -> 10909089 | L6: =IF((IFERROR(J6/I6,0))=0,0,(IFERROR(J6/I6,0)-1)) -> 0.11758631 | M6: =IF((IFERROR(J6/K6,0))=0,0,(IFERROR(J6/K6,0)-1)) -> 0.080090036 | O6: =O7+O8 -> 0 | P6: =P7+P8 -> 0 | Q6: =Q7+Q8 -> 0 | R6: =IF((IFERROR(O6/P6,0))=0,0,(IFERROR(O6/P6,0)-1)) -> 0 | S6: =IF((IFERROR(O6/Q6,0))=0,0,(IFERROR(O6/Q6,0)-1)) -> 0 | U6: 12277769 | V6: =J6-U6 -> -494970.17 | W6: =J6/U6-1 -> -0.040314343
B7: 4e+20 | C7: 0 | D7: 0 | E7: 0 | F7: =IF((IFERROR(C7/D7,0))=0,0,(IFERROR(C7/D7,0)-1)) -> 0 | G7: =IF((IFERROR(C7/E7,0))=0,0,(IFERROR(C7/E7,0)-1)) -> 0 | H7: Cuotas Netas | I7: 10136402 | J7: =SUMIF('PPvsREal Summary'!$C:$C,RESUMEN!B7,'PPvsREal Summary'!$AC:$AC) -> 11272264 | K7: 10052089 | L7: =IF((IFERROR(J7/I7,0))=0,0,(IFERROR(J7/I7,0)-1)) -> 0.11205776 | M7: =IF((IFERROR(J7/K7,0))=0,0,(IFERROR(J7/K7,0)-1)) -> 0.12138525 | O7: 0 | P7: 0 | Q7: 0 | R7: =IF((IFERROR(O7/P7,0))=0,0,(IFERROR(O7/P7,0)-1)) -> 0 | S7: =IF((IFERROR(O7/Q7,0))=0,0,(IFERROR(O7/Q7,0)-1)) -> 0
B8: 4.01e+20 | C8: 0 | D8: 0 | E8: 0 | F8: =IF((IFERROR(C8/D8,0))=0,0,(IFERROR(C8/D8,0)-1)) -> 0 | G8: =IF((IFERROR(C8/E8,0))=0,0,(IFERROR(C8/E8,0)-1)) -> 0 | H8: Ingresos socios nuevos | I8: 406675 | J8: =SUMIF('PPvsREal Summary'!$C:$C,RESUMEN!B8,'PPvsREal Summary'!$AC:$AC) -> 510534 | K8: 857000 | L8: =IF((IFERROR(J8/I8,0))=0,0,(IFERROR(J8/I8,0)-1)) -> 0.25538575 | M8: =IF((IFERROR(J8/K8,0))=0,0,(IFERROR(J8/K8,0)-1)) -> -0.40427771 | O8: 0 | P8: 0 | Q8: 0 | R8: =IF((IFERROR(O8/P8,0))=0,0,(IFERROR(O8/P8,0)-1)) -> 0 | S8: =IF((IFERROR(O8/Q8,0))=0,0,(IFERROR(O8/Q8,0)-1)) -> 0
C9: =C10+C11 -> 0 | D9: =D10+D11 -> 0 | E9: =E10+E11 -> 0 | F9: =IF((IFERROR(C9/D9,0))=0,0,(IFERROR(C9/D9,0)-1)) -> 0 | G9: =IF((IFERROR(C9/E9,0))=0,0,(IFERROR(C9/E9,0)-1)) -> 0 | H9: Events | I9: =I10+I11 -> 2311332.8 | J9: =J10+J11 -> 3820000 | K9: =K10+K11 -> 4100000 | L9: =IF((IFERROR(J9/I9,0))=0,0,(IFERROR(J9/I9,0)-1)) -> 0.65272611 | M9: =IF((IFERROR(J9/K9,0))=0,0,(IFERROR(J9/K9,0)-1)) -> -0.068292683 | O9: =O10+O11 -> 0 | P9: =P10+P11 -> 0 | Q9: =Q10+Q11 -> 0 | R9: =IF((IFERROR(O9/P9,0))=0,0,(IFERROR(O9/P9,0)-1)) -> 0 | S9: =IF((IFERROR(O9/Q9,0))=0,0,(IFERROR(O9/Q9,0)-1)) -> 0 | U9: 3986161 | V9: =J9-U9 -> -166161.04 | W9: =J9/U9-1 -> -0.041684476
B10: 4.05e+20 | C10: 0 | D10: 0 | E10: 0 | F10: =IF((IFERROR(C10/D10,0))=0,0,(IFERROR(C10/D10,0)-1)) -> 0 | G10: =IF((IFERROR(C10/E10,0))=0,0,(IFERROR(C10/E10,0)-1)) -> 0 | H10: Eventos | I10: 2311332.8 | J10: =SUMIF('PPvsREal Summary'!$C:$C,RESUMEN!B10,'PPvsREal Summary'!$AC:$AC) -> 1190000 | K10: 4100000 | L10: =IF((IFERROR(J10/I10,0))=0,0,(IFERROR(J10/I10,0)-1)) -> -0.48514553 | M10: =IF((IFERROR(J10/K10,0))=0,0,(IFERROR(J10/K10,0)-1)) -> -0.7097561 | O10: 0 | P10: 0 | Q10: 0 | R10: =IF((IFERROR(O10/P10,0))=0,0,(IFERROR(O10/P10,0)-1)) -> 0 | S10: =IF((IFERROR(O10/Q10,0))=0,0,(IFERROR(O10/Q10,0)-1)) -> 0 | V10: =J10-U10 -> 1190000
B11: 4.06e+20 | C11: 0 | D11: 0 | E11: 0 | F11: =IF((IFERROR(C11/D11,0))=0,0,(IFERROR(C11/D11,0)-1)) -> 0 | G11: =IF((IFERROR(C11/E11,0))=0,0,(IFERROR(C11/E11,0)-1)) -> 0 | H11: Patrocinios | I11: 0 | J11: =SUMIF('PPvsREal Summary'!$C:$C,RESUMEN!B11,'PPvsREal Summary'!$AC:$AC) -> 2630000 | K11: 0 | L11: =IF((IFERROR(J11/I11,0))=0,0,(IFERROR(J11/I11,0)-1)) -> 0 | M11: =IF((IFERROR(J11/K11,0))=0,0,(IFERROR(J11/K11,0)-1)) -> 0 | O11: 0 | P11: 0 | Q11: 0 | R11: =IF((IFERROR(O11/P11,0))=0,0,(IFERROR(O11/P11,0)-1)) -> 0 | S11: =IF((IFERROR(O11/Q11,0))=0,0,(IFERROR(O11/Q11,0)-1)) -> 0 | V11: =J11-U11 -> 2630000
C12: =C13 -> 0 | D12: =D13 -> 0 | E12: =E13 -> 0 | F12: =IF((IFERROR(C12/D12,0))=0,0,(IFERROR(C12/D12,0)-1)) -> 0 | G12: =IF((IFERROR(C12/E12,0))=0,0,(IFERROR(C12/E12,0)-1)) -> 0 | H12: Committees | I12: =I13 -> 756663.16 | J12: =J13 -> 1594590.7 | K12: =K13 -> 1718000 | L12: =IF((IFERROR(J12/I12,0))=0,0,(IFERROR(J12/I12,0)-1)) -> 1.1073983 | M12: =IF((IFERROR(J12/K12,0))=0,0,(IFERROR(J12/K12,0)-1)) -> -0.07183313 | O12: =O13 -> 0 | P12: =P13 -> 0 | Q12: =Q13 -> 0 | R12: =IF((IFERROR(O12/P12,0))=0,0,(IFERROR(O12/P12,0)-1)) -> 0 | S12: =IF((IFERROR(O12/Q12,0))=0,0,(IFERROR(O12/Q12,0)-1)) -> 0 | U12: 1394945.1 | V12: =J12-U12 -> 199645.56 | W12: =J12/U12-1 -> 0.14312073
B13: 4.04e+20 | C13: 0 | D13: 0 | E13: 0 | F13: =IF((IFERROR(C13/D13,0))=0,0,(IFERROR(C13/D13,0)-1)) -> 0 | G13: =IF((IFERROR(C13/E13,0))=0,0,(IFERROR(C13/E13,0)-1)) -> 0 | H13: Comités | I13: 756663.16 | J13: =SUMIF('PPvsREal Summary'!$C:$C,RESUMEN!B13,'PPvsREal Summary'!$AC:$AC) -> 1594590.7 | K13: 1718000 | L13: =IF((IFERROR(J13/I13,0))=0,0,(IFERROR(J13/I13,0)-1)) -> 1.1073983 | M13: =IF((IFERROR(J13/K13,0))=0,0,(IFERROR(J13/K13,0)-1)) -> -0.07183313 | O13: 0 | P13: 0 | Q13: 0 | R13: =IF((IFERROR(O13/P13,0))=0,0,(IFERROR(O13/P13,0)-1)) -> 0 | S13: =IF((IFERROR(O13/Q13,0))=0,0,(IFERROR(O13/Q13,0)-1)) -> 0 | V13: =J13-U13 -> 1594590.7
C14: =C15 -> 0 | D14: =D15 -> 0 | E14: =E15 -> 0 | F14: =IF((IFERROR(C14/D14,0))=0,0,(IFERROR(C14/D14,0)-1)) -> 0 | G14: =IF((IFERROR(C14/E14,0))=0,0,(IFERROR(C14/E14,0)-1)) -> 0 | H14: T&IC | I14: =I15 -> 0 | J14: =J15 -> 50000 | K14: =K15 -> 0 | L14: =IF((IFERROR(J14/I14,0))=0,0,(IFERROR(J14/I14,0)-1)) -> 0 | M14: =IF((IFERROR(J14/K14,0))=0,0,(IFERROR(J14/K14,0)-1)) -> 0 | O14: =O15 -> 0 | P14: =P15 -> 0 | Q14: =Q15 -> 0 | R14: =IF((IFERROR(O14/P14,0))=0,0,(IFERROR(O14/P14,0)-1)) -> 0 | S14: =IF((IFERROR(O14/Q14,0))=0,0,(IFERROR(O14/Q14,0)-1)) -> 0 | U14: 0 | V14: =J14-U14 -> 50000 | W14: =J14/U14-1 -> #DIV/0!
B15: 4.07e+20 | C15: 0 | D15: 0 | E15: 0 | F15: =IF((IFERROR(C15/D15,0))=0,0,(IFERROR(C15/D15,0)-1)) -> 0 | G15: =IF((IFERROR(C15/E15,0))=0,0,(IFERROR(C15/E15,0)-1)) -> 0 | H15: Trade & Investment Center | I15: 0 | J15: =SUMIF('PPvsREal Summary'!$C:$C,RESUMEN!B15,'PPvsREal Summary'!$AC:$AC) -> 50000 | K15: 0 | L15: =IF((IFERROR(J15/I15,0))=0,0,(IFERROR(J15/I15,0)-1)) -> 0 | M15: =IF((IFERROR(J15/K15,0))=0,0,(IFERROR(J15/K15,0)-1)) -> 0 | O15: 0 | P15: 0 | Q15: 0 | R15: =IF((IFERROR(O15/P15,0))=0,0,(IFERROR(O15/P15,0)-1)) -> 0 | S15: =IF((IFERROR(O15/Q15,0))=0,0,(IFERROR(O15/Q15,0)-1)) -> 0 | V15: =J15-U15 -> 50000
C16: =C17+C18 -> 0 | D16: =D17+D18 -> 0 | E16: =E17+E18 -> 0 | F16: =IF((IFERROR(C16/D16,0))=0,0,(IFERROR(C16/D16,0)-1)) -> 0 | G16: =IF((IFERROR(C16/E16,0))=0,0,(IFERROR(C16/E16,0)-1)) -> 0 | H16: Services to Members | I16: =I17+I18 -> 584900 | J16: =J17+J18 -> 714217.04 | K16: =K17+K18 -> 567226.8 | L16: =IF((IFERROR(J16/I16,0))=0,0,(IFERROR(J16/I16,0)-1)) -> 0.22109255 | M16: =IF((IFERROR(J16/K16,0))=0,0,(IFERROR(J16/K16,0)-1)) -> 0.25913838 | O16: =O17+O18 -> 0 | P16: =P17+P18 -> 0 | Q16: =Q17+Q18 -> 0 | R16: =IF((IFERROR(O16/P16,0))=0,0,(IFERROR(O16/P16,0)-1)) -> 0 | S16: =IF((IFERROR(O16/Q16,0))=0,0,(IFERROR(O16/Q16,0)-1)) -> 0 | U16: 715831.73 | V16: =J16-U16 -> -1614.69 | W16: =J16/U16-1 -> -0.0022556838
B17: 4.03e+20 | C17: 0 | D17: 0 | E17: 0 | F17: =IF((IFERROR(C17/D17,0))=0,0,(IFERROR(C17/D17,0)-1)) -> 0 | G17: =IF((IFERROR(C17/E17,0))=0,0,(IFERROR(C17/E17,0)-1)) -> 0 | H17: Venta Publicaciones | I17: 584900 | J17: =SUMIF('PPvsREal Summary'!$C:$C,RESUMEN!B17,'PPvsREal Summary'!$AC:$AC) -> 714217.04 | K17: 567226.8 | L17: =IF((IFERROR(J17/I17,0))=0,0,(IFERROR(J17/I17,0)-1)) -> 0.22109255 | M17: =IF((IFERROR(J17/K17,0))=0,0,(IFERROR(J17/K17,0)-1)) -> 0.25913838 | O17: 0 | P17: 0 | Q17: 0 | R17: =IF((IFERROR(O17/P17,0))=0,0,(IFERROR(O17/P17,0)-1)) -> 0 | S17: =IF((IFERROR(O17/Q17,0))=0,0,(IFERROR(O17/Q17,0)-1)) -> 0
B18: 4.08e+20 | C18: 0 | D18: 0 | E18: 0 | F18: =IF((IFERROR(C18/D18,0))=0,0,(IFERROR(C18/D18,0)-1)) -> 0 | G18: =IF((IFERROR(C18/E18,0))=0,0,(IFERROR(C18/E18,0)-1)) -> 0 | H18: Visas | I18: 0 | J18: =SUMIF('PPvsREal Summary'!$C:$C,RESUMEN!B18,'PPvsREal Summary'!$AC:$AC) -> 0 | K18: 0 | L18: =IF((IFERROR(J18/I18,0))=0,0,(IFERROR(J18/I18,0)-1)) -> 0 | M18: =IF((IFERROR(J18/K18,0))=0,0,(IFERROR(J18/K18,0)-1)) -> 0 | O18: 0 | P18: 0 | Q18: 0 | R18: =IF((IFERROR(O18/P18,0))=0,0,(IFERROR(O18/P18,0)-1)) -> 0 | S18: =IF((IFERROR(O18/Q18,0))=0,0,(IFERROR(O18/Q18,0)-1)) -> 0
C19: =C20+C23+C25+C30+C32+C35+C36+C28 -> 0 | D19: =D20+D23+D25+D30+D32+D35+D36+D28 -> 0 | E19: =E20+E23+E25+E30+E32+E35+E36+E28 -> 0 | F19: =IF((IFERROR(C19/D19,0))=0,0,(IFERROR(C19/D19,0)-1)) -> 0 | G19: =IF((IFERROR(C19/E19,0))=0,0,(IFERROR(C19/E19,0)-1)) -> 0 | H19: EXPENSE | I19: =I20+I23+I25+I30+I32+I35+I36+I28 -> 14658996 | J19: =J20+J23+J25+J30+J32+J35+J36+J28 -> 17851585 | K19: =K20+K23+K25+K30+K32+K35+K36+K28 -> 16453320 | L19: =IF((IFERROR(J19/I19,0))=0,0,(IFERROR(J19/I19,0)-1)) -> 0.21779036 | M19: =IF((IFERROR(J19/K19,0))=0,0,(IFERROR(J19/K19,0)-1)) -> 0.084983721 | O19: =O20+O23+O25+O30+O32+O35+O36+O28 -> 0 | P19: =P20+P23+P25+P30+P32+P35+P36+P28 -> 0 | Q19: =Q20+Q23+Q25+Q30+Q32+Q35+Q36+Q28 -> 0 | R19: =IF((IFERROR(O19/P19,0))=0,0,(IFERROR(O19/P19,0)-1)) -> 0 | S19: =IF((IFERROR(O19/Q19,0))=0,0,(IFERROR(O19/Q19,0)-1)) -> 0 | U19: =U20+U23+U25+U30+U32+U35+U36+U28 -> 18216153 | V19: =V20+V23+V25+V30+V32+V35+V36+V28 -> -364568.48 | W19: =J19/U19-1 -> -0.020013473
C20: =C21+C22 -> 0 | D20: =D21+D22 -> 0 | E20: =E21+E22 -> 0 | F20: =IF((IFERROR(C20/D20,0))=0,0,(IFERROR(C20/D20,0)-1)) -> 0 | G20: =IF((IFERROR(C20/E20,0))=0,0,(IFERROR(C20/E20,0)-1)) -> 0 | H20: Membership | I20: =I21+I22 -> 567446.96 | J20: =J21+J22 -> 493042.52 | K20: =K21+K22 -> 675870.6 | L20: =IF((IFERROR(J20/I20,0))=0,0,(IFERROR(J20/I20,0)-1)) -> -0.1311214 | M20: =IF((IFERROR(J20/K20,0))=0,0,(IFERROR(J20/K20,0)-1)) -> -0.27050752 | O20: =O21+O22 -> 0 | P20: =P21+P22 -> 0 | Q20: =Q21+Q22 -> 0 | R20: =IF((IFERROR(O20/P20,0))=0,0,(IFERROR(O20/P20,0)-1)) -> 0 | S20: =IF((IFERROR(O20/Q20,0))=0,0,(IFERROR(O20/Q20,0)-1)) -> 0 | U20: 565172.2 | V20: =J20-U20 -> -72129.681 | W20: =J20/U20-1 -> -0.12762426
B21: 7.02e+20 | C21: 0 | D21: 0 | E21: 0 | F21: =IF((IFERROR(C21/D21,0))=0,0,(IFERROR(C21/D21,0)-1)) -> 0 | G21: =IF((IFERROR(C21/E21,0))=0,0,(IFERROR(C21/E21,0)-1)) -> 0 | H21: Gastos Promoción | I21: 40913.02 | J21: =SUMIF('PPvsREal Summary'!$C:$C,RESUMEN!B21,'PPvsREal Summary'!$AC:$AC) -> 33519.558 | K21: 120000 | L21: =IF((IFERROR(J21/I21,0))=0,0,(IFERROR(J21/I21,0)-1)) -> -0.18071171 | M21: =IF((IFERROR(J21/K21,0))=0,0,(IFERROR(J21/K21,0)-1)) -> -0.72067035 | O21: 0 | P21: 0 | Q21: 0 | R21: =IF((IFERROR(O21/P21,0))=0,0,(IFERROR(O21/P21,0)-1)) -> 0 | S21: =IF((IFERROR(O21/Q21,0))=0,0,(IFERROR(O21/Q21,0)-1)) -> 0 | V21: =J21-U21 -> 33519.558
B22: 5.03e+20 | C22: 0 | D22: 0 | E22: 0 | F22: =IF((IFERROR(C22/D22,0))=0,0,(IFERROR(C22/D22,0)-1)) -> 0 | G22: =IF((IFERROR(C22/E22,0))=0,0,(IFERROR(C22/E22,0)-1)) -> 0 | H22: Comisiones por venta de membresías | I22: 526533.94 | J22: =SUMIF('PPvsREal Summary'!$C:$C,RESUMEN!B22,'PPvsREal Summary'!$AC:$AC) -> 459522.96 | K22: 555870.6 | L22: =IF((IFERROR(J22/I22,0))=0,0,(IFERROR(J22/I22,0)-1)) -> -0.12726811 | M22: =IF((IFERROR(J22/K22,0))=0,0,(IFERROR(J22/K22,0)-1)) -> -0.17332746 | O22: 0 | P22: 0 | Q22: 0 | R22: =IF((IFERROR(O22/P22,0))=0,0,(IFERROR(O22/P22,0)-1)) -> 0 | S22: =IF((IFERROR(O22/Q22,0))=0,0,(IFERROR(O22/Q22,0)-1)) -> 0 | V22: =J22-U22 -> 459522.96
C23: =C24 -> 0 | D23: =D24 -> 0 | E23: =E24 -> 0 | F23: =IF((IFERROR(C23/D23,0))=0,0,(IFERROR(C23/D23,0)-1)) -> 0 | G23: =IF((IFERROR(C23/E23,0))=0,0,(IFERROR(C23/E23,0)-1)) -> 0 | H23: Events | I23: =I24 -> 1496260.2 | J23: =J24 -> 2660000 | K23: =K24 -> 2956045 | L23: =IF((IFERROR(J23/I23,0))=0,0,(IFERROR(J23/I23,0)-1)) -> 0.7777656 | M23: =IF((IFERROR(J23/K23,0))=0,0,(IFERROR(J23/K23,0)-1)) -> -0.10014902 | O23: =O24 -> 0 | P23: =P24 -> 0 | Q23: =Q24 -> 0 | R23: =IF((IFERROR(O23/P23,0))=0,0,(IFERROR(O23/P23,0)-1)) -> 0 | S23: =IF((IFERROR(O23/Q23,0))=0,0,(IFERROR(O23/Q23,0)-1)) -> 0 | U23: 2267032.4 | V23: =J23-U23 -> 392967.64 | W23: =J23/U23-1 -> 0.17334011
B24: 7.01e+20 | C24: 0 | D24: 0 | E24: 0 | F24: =IF((IFERROR(C24/D24,0))=0,0,(IFERROR(C24/D24,0)-1)) -> 0 | G24: =IF((IFERROR(C24/E24,0))=0,0,(IFERROR(C24/E24,0)-1)) -> 0 | H24: Costo Eventos | I24: 1496260.2 | J24: =SUMIF('PPvsREal Summary'!$C:$C,RESUMEN!B24,'PPvsREal Summary'!$AC:$AC) -> 2660000 | K24: 2956045 | L24: =IF((IFERROR(J24/I24,0))=0,0,(IFERROR(J24/I24,0)-1)) -> 0.7777656 | M24: =IF((IFERROR(J24/K24,0))=0,0,(IFERROR(J24/K24,0)-1)) -> -0.10014902 | O24: 0 | P24: 0 | Q24: 0 | R24: =IF((IFERROR(O24/P24,0))=0,0,(IFERROR(O24/P24,0)-1)) -> 0 | S24: =IF((IFERROR(O24/Q24,0))=0,0,(IFERROR(O24/Q24,0)-1)) -> 0 | V24: =J24-U24 -> 2660000
C25: =C26+C27 -> 0 | D25: =D26+D27 -> 0 | E25: =E26+E27 -> 0 | F25: =IF((IFERROR(C25/D25,0))=0,0,(IFERROR(C25/D25,0)-1)) -> 0 | G25: =IF((IFERROR(C25/E25,0))=0,0,(IFERROR(C25/E25,0)-1)) -> 0 | H25: Committees | I25: =I26+I27 -> 644237.57 | J25: =J26+J27 -> 1004784.9 | K25: =K26+K27 -> 896480 | L25: =IF((IFERROR(J25/I25,0))=0,0,(IFERROR(J25/I25,0)-1)) -> 0.55964962 | M25: =IF((IFERROR(J25/K25,0))=0,0,(IFERROR(J25/K25,0)-1)) -> 0.12081126 | O25: =O26 -> 0 | P25: =P26 -> 0 | Q25: =Q26 -> 0 | R25: =IF((IFERROR(O25/P25,0))=0,0,(IFERROR(O25/P25,0)-1)) -> 0 | S25: =IF((IFERROR(O25/Q25,0))=0,0,(IFERROR(O25/Q25,0)-1)) -> 0 | U25: 890349.64 | V25: =J25-U25 -> 114435.24 | W25: =J25/U25-1 -> 0.12852843
B26: 5.02e+20 | C26: 0 | D26: 0 | E26: 0 | F26: =IF((IFERROR(C26/D26,0))=0,0,(IFERROR(C26/D26,0)-1)) -> 0 | G26: =IF((IFERROR(C26/E26,0))=0,0,(IFERROR(C26/E26,0)-1)) -> 0 | H26: Costo comités | I26: 644237.57 | J26: =SUMIF('PPvsREal Summary'!$C:$C,RESUMEN!B26,'PPvsREal Summary'!$AC:$AC) -> 1004784.9 | K26: 896480 | L26: =IF((IFERROR(J26/I26,0))=0,0,(IFERROR(J26/I26,0)-1)) -> 0.55964962 | M26: =IF((IFERROR(J26/K26,0))=0,0,(IFERROR(J26/K26,0)-1)) -> 0.12081126 | O26: 0 | P26: 0 | Q26: 0 | R26: =IF((IFERROR(O26/P26,0))=0,0,(IFERROR(O26/P26,0)-1)) -> 0 | S26: =IF((IFERROR(O26/Q26,0))=0,0,(IFERROR(O26/Q26,0)-1)) -> 0 | V26: =J26-U26 -> 1004784.9
B27: 5.04e+20 | C27: 0 | D27: 0 | E27: 0 | F27: =IF((IFERROR(C27/D27,0))=0,0,(IFERROR(C27/D27,0)-1)) -> 0 | G27: =IF((IFERROR(C27/E27,0))=0,0,(IFERROR(C27/E27,0)-1)) -> 0 | H27: Comisiones EWDP | I27: 0 | J27: =SUMIF('PPvsREal Summary'!$C:$C,RESUMEN!B27,'PPvsREal Summary'!$AC:$AC) -> 0 | K27: 0 | L27: =IF((IFERROR(J27/I27,0))=0,0,(IFERROR(J27/I27,0)-1)) -> 0 | M27: =IF((IFERROR(J27/K27,0))=0,0,(IFERROR(J27/K27,0)-1)) -> 0 | O27: 0 | P27: 0 | Q27: 0 | R27: =IF((IFERROR(O27/P27,0))=0,0,(IFERROR(O27/P27,0)-1)) -> 0 | S27: =IF((IFERROR(O27/Q27,0))=0,0,(IFERROR(O27/Q27,0)-1)) -> 0 | V27: =J27-U27 -> 0
C28: =C29 -> 0 | D28: =D29 -> 0 | E28: =E29 -> 0 | F28: =IF((IFERROR(C28/D28,0))=0,0,(IFERROR(C28/D28,0)-1)) -> 0 | G28: =IF((IFERROR(C28/E28,0))=0,0,(IFERROR(C28/E28,0)-1)) -> 0 | H28: T&IC | I28: =I29 -> 0 | J28: =J29 -> 25000 | K28: =K29 -> 0 | L28: =IF((IFERROR(J28/I28,0))=0,0,(IFERROR(J28/I28,0)-1)) -> 0 | M28: =IF((IFERROR(J28/K28,0))=0,0,(IFERROR(J28/K28,0)-1)) -> 0 | O28: =O29 -> 0 | P28: =P29 -> 0 | Q28: =Q29 -> 0 | R28: =IF((IFERROR(O28/P28,0))=0,0,(IFERROR(O28/P28,0)-1)) -> 0 | S28: =IF((IFERROR(O28/Q28,0))=0,0,(IFERROR(O28/Q28,0)-1)) -> 0 | U28: 0 | V28: =J28-U28 -> 25000 | W28: =J28/U28-1 -> #DIV/0!
B29: 7.03e+20 | C29: 0 | D29: 0 | E29: 0 | F29: =IF((IFERROR(C29/D29,0))=0,0,(IFERROR(C29/D29,0)-1)) -> 0 | G29: =IF((IFERROR(C29/E29,0))=0,0,(IFERROR(C29/E29,0)-1)) -> 0 | H29: Costo Trade & Investment Center | I29: 0 | J29: =SUMIF('PPvsREal Summary'!$C:$C,RESUMEN!B29,'PPvsREal Summary'!$AC:$AC) -> 25000 | K29: 0 | L29: =IF((IFERROR(J29/I29,0))=0,0,(IFERROR(J29/I29,0)-1)) -> 0 | M29: =IF((IFERROR(J29/K29,0))=0,0,(IFERROR(J29/K29,0)-1)) -> 0 | O29: 0 | P29: 0 | Q29: 0 | R29: =IF((IFERROR(O29/P29,0))=0,0,(IFERROR(O29/P29,0)-1)) -> 0 | S29: =IF((IFERROR(O29/Q29,0))=0,0,(IFERROR(O29/Q29,0)-1)) -> 0 | V29: =J29-U29 -> 25000
C30: =C31 -> 0 | D30: =D31 -> 0 | E30: =E31 -> 0 | F30: =IF((IFERROR(C30/D30,0))=0,0,(IFERROR(C30/D30,0)-1)) -> 0 | G30: =IF((IFERROR(C30/E30,0))=0,0,(IFERROR(C30/E30,0)-1)) -> 0 | H30: Services to Members | I30: =I31 -> 292450 | J30: =J31 -> 357108.52 | K30: =K31 -> 283613.4 | L30: =IF((IFERROR(J30/I30,0))=0,0,(IFERROR(J30/I30,0)-1)) -> 0.22109255 | M30: =IF((IFERROR(J30/K30,0))=0,0,(IFERROR(J30/K30,0)-1)) -> 0.25913838 | O30: =O31 -> 0 | P30: =P31 -> 0 | Q30: =Q31 -> 0 | R30: =IF((IFERROR(O30/P30,0))=0,0,(IFERROR(O30/P30,0)-1)) -> 0 | S30: =IF((IFERROR(O30/Q30,0))=0,0,(IFERROR(O30/Q30,0)-1)) -> 0 | U30: 444647.32 | V30: =J30-U30 -> -87538.804 | W30: =J30/U30-1 -> -0.19687244
B31: 6.01e+20 | C31: 0 | D31: 0 | E31: 0 | F31: =IF((IFERROR(C31/D31,0))=0,0,(IFERROR(C31/D31,0)-1)) -> 0 | G31: =IF((IFERROR(C31/E31,0))=0,0,(IFERROR(C31/E31,0)-1)) -> 0 | H31: Gastos Venta Publicaciones | I31: 292450 | J31: =SUMIF('PPvsREal Summary'!$C:$C,RESUMEN!B31,'PPvsREal Summary'!$AC:$AC) -> 357108.52 | K31: 283613.4 | L31: =IF((IFERROR(J31/I31,0))=0,0,(IFERROR(J31/I31,0)-1)) -> 0.22109255 | M31: =IF((IFERROR(J31/K31,0))=0,0,(IFERROR(J31/K31,0)-1)) -> 0.25913838 | O31: 0 | P31: 0 | Q31: 0 | R31: =IF((IFERROR(O31/P31,0))=0,0,(IFERROR(O31/P31,0)-1)) -> 0 | S31: =IF((IFERROR(O31/Q31,0))=0,0,(IFERROR(O31/Q31,0)-1)) -> 0 | V31: =J31-U31 -> 357108.52
C32: =C33+C34 -> 0 | D32: =D33+D34 -> 0 | E32: =E33+E34 -> 0 | F32: =IF((IFERROR(C32/D32,0))=0,0,(IFERROR(C32/D32,0)-1)) -> 0 | G32: =IF((IFERROR(C32/E32,0))=0,0,(IFERROR(C32/E32,0)-1)) -> 0 | H32: Gastos G&A | I32: =I33+I34 -> 1780331.8 | J32: =J33+J34 -> 2270680.8 | K32: =K33+K34 -> 2000217.9 | L32: =IF((IFERROR(J32/I32,0))=0,0,(IFERROR(J32/I32,0)-1)) -> 0.27542565 | M32: =IF((IFERROR(J32/K32,0))=0,0,(IFERROR(J32/K32,0)-1)) -> 0.13521673 | O32: =O33+O34 -> 0 | P32: =P33+P34 -> 0 | Q32: =Q33+Q34 -> 0 | R32: =IF((IFERROR(O32/P32,0))=0,0,(IFERROR(O32/P32,0)-1)) -> 0 | S32: =IF((IFERROR(O32/Q32,0))=0,0,(IFERROR(O32/Q32,0)-1)) -> 0 | U32: 1830574.1 | V32: =J32-U32 -> 440106.68 | W32: =J32/U32-1 -> 0.24042003
B33: 8.01e+20 | C33: 0 | D33: 0 | E33: 0 | F33: =IF((IFERROR(C33/D33,0))=0,0,(IFERROR(C33/D33,0)-1)) -> 0 | G33: =IF((IFERROR(C33/E33,0))=0,0,(IFERROR(C33/E33,0)-1)) -> 0 | H33: Gasto de Administración | I33: 302430.6 | J33: =SUMIF('PPvsREal Summary'!$C:$C,RESUMEN!B33,'PPvsREal Summary'!$AC:$AC) -> 496408.94 | K33: 532937.82 | L33: =IF((IFERROR(J33/I33,0))=0,0,(IFERROR(J33/I33,0)-1)) -> 0.64139788 | M33: =IF((IFERROR(J33/K33,0))=0,0,(IFERROR(J33/K33,0)-1)) -> -0.068542472 | O33: 0 | P33: 0 | Q33: 0 | R33: =IF((IFERROR(O33/P33,0))=0,0,(IFERROR(O33/P33,0)-1)) -> 0 | S33: =IF((IFERROR(O33/Q33,0))=0,0,(IFERROR(O33/Q33,0)-1)) -> 0 | V33: =J33-U33 -> 496408.94
B34: 9.01e+20 | C34: 0 | D34: 0 | E34: 0 | F34: =IF((IFERROR(C34/D34,0))=0,0,(IFERROR(C34/D34,0)-1)) -> 0 | G34: =IF((IFERROR(C34/E34,0))=0,0,(IFERROR(C34/E34,0)-1)) -> 0 | H34: Gastos Generales | I34: 1477901.2 | J34: =SUMIF('PPvsREal Summary'!$C:$C,RESUMEN!B34,'PPvsREal Summary'!$AC:$AC) -> 1774271.9 | K34: 1467280.1 | L34: =IF((IFERROR(J34/I34,0))=0,0,(IFERROR(J34/I34,0)-1)) -> 0.20053485 | M34: =IF((IFERROR(J34/K34,0))=0,0,(IFERROR(J34/K34,0)-1)) -> 0.20922509 | O34: 0 | P34: 0 | Q34: 0 | R34: =IF((IFERROR(O34/P34,0))=0,0,(IFERROR(O34/P34,0)-1)) -> 0 | S34: =IF((IFERROR(O34/Q34,0))=0,0,(IFERROR(O34/Q34,0)-1)) -> 0 | V34: =J34-U34 -> 1774271.9
B35: 5.01e+20 | C35: 0 | D35: 0 | E35: 0 | F35: =IF((IFERROR(C35/D35,0))=0,0,(IFERROR(C35/D35,0)-1)) -> 0 | G35: =IF((IFERROR(C35/E35,0))=0,0,(IFERROR(C35/E35,0)-1)) -> 0 | H35: Nómina | I35: 5850740.2 | J35: =SUMIF('PPvsREal Summary'!$C:$C,RESUMEN!B35,'PPvsREal Summary'!$AC:$AC) -> 6711987.8 | K35: 5720425.7 | L35: =IF((IFERROR(J35/I35,0))=0,0,(IFERROR(J35/I35,0)-1)) -> 0.1472032 | M35: =IF((IFERROR(J35/K35,0))=0,0,(IFERROR(J35/K35,0)-1)) -> 0.17333713 | O35: 0 | P35: 0 | Q35: 0 | R35: =IF((IFERROR(O35/P35,0))=0,0,(IFERROR(O35/P35,0)-1)) -> 0 | S35: =IF((IFERROR(O35/Q35,0))=0,0,(IFERROR(O35/Q35,0)-1)) -> 0 | U35: 7550054.4 | V35: =J35-U35 -> -838066.54 | W35: =J35/U35-1 -> -0.11100139
B36: 9.03e+20 | C36: 0 | D36: 0 | E36: 0 | F36: =IF((IFERROR(C36/D36,0))=0,0,(IFERROR(C36/D36,0)-1)) -> 0 | G36: =IF((IFERROR(C36/E36,0))=0,0,(IFERROR(C36/E36,0)-1)) -> 0 | H36: Gastos Corporativos | I36: 4027529.7 | J36: =SUMIF('PPvsREal Summary'!$C:$C,RESUMEN!B36,'PPvsREal Summary'!$AC:$AC) -> 4328980 | K36: 3920667.6 | L36: =IF((IFERROR(J36/I36,0))=0,0,(IFERROR(J36/I36,0)-1)) -> 0.074847429 | M36: =IF((IFERROR(J36/K36,0))=0,0,(IFERROR(J36/K36,0)-1)) -> 0.10414358 | O36: 0 | P36: 0 | Q36: 0 | R36: =IF((IFERROR(O36/P36,0))=0,0,(IFERROR(O36/P36,0)-1)) -> 0 | S36: =IF((IFERROR(O36/Q36,0))=0,0,(IFERROR(O36/Q36,0)-1)) -> 0 | U36: 4668323 | V36: =J36-U36 -> -339343.01 | W36: =J36/U36-1 -> -0.07269056
B37: 9.03016e+20 | C37: 0 | D37: 0 | E37: 0 | F37: =IF((IFERROR(C37/D37,0))=0,0,(IFERROR(C37/D37,0)-1)) -> 0 | G37: =IF((IFERROR(C37/E37,0))=0,0,(IFERROR(C37/E37,0)-1)) -> 0 | H37: Cargos Administrativos | I37: 3024687.9 | J37: 0 | K37: 0 | L37: =IF((IFERROR(J37/I37,0))=0,0,(IFERROR(J37/I37,0)-1)) -> 0 | M37: =IF((IFERROR(J37/K37,0))=0,0,(IFERROR(J37/K37,0)-1)) -> 0 | O37: 0 | P37: 0 | Q37: 0 | R37: =IF((IFERROR(O37/P37,0))=0,0,(IFERROR(O37/P37,0)-1)) -> 0 | S37: =IF((IFERROR(O37/Q37,0))=0,0,(IFERROR(O37/Q37,0)-1)) -> 0
C38: =+C5-C19 -> 0 | D38: =+D5-D19 -> 0 | E38: =+E5-E19 -> 0 | F38: =IF((IFERROR(C38/D38,0))=0,0,(IFERROR(C38/D38,0)-1)) -> 0 | G38: =IF((IFERROR(C38/E38,0))=0,0,(IFERROR(C38/E38,0)-1)) -> 0 | H38: OPERATING RESULTS | I38: =+I5-I19 -> -463023.6 | J38: =+J5-J19 -> 110021.59 | K38: =+K5-K19 -> 840995.69 | L38: =IF((IFERROR(J38/I38,0))=0,0,(IFERROR(J38/I38,0)-1)) -> -1.2376155 | M38: =IF((IFERROR(J38/K38,0))=0,0,(IFERROR(J38/K38,0)-1)) -> -0.86917699 | O38: =+O5-O19 -> 0 | P38: =+P5-P19 -> 0 | Q38: =+Q5-Q19 -> 0 | R38: =IF((IFERROR(O38/P38,0))=0,0,(IFERROR(O38/P38,0)-1)) -> 0 | S38: =IF((IFERROR(O38/Q38,0))=0,0,(IFERROR(O38/Q38,0)-1)) -> 0 | U38: =+U5-U19 -> 158553.44 | V38: =+V5-V19 -> -48531.857 | W38: =J38/U38-1 -> -0.30609147
B39: 9.04e+20 | C39: 0 | D39: 0 | E39: 0 | F39: =IF((IFERROR(C39/D39,0))=0,0,(IFERROR(C39/D39,0)-1)) -> 0 | G39: =IF((IFERROR(C39/E39,0))=0,0,(IFERROR(C39/E39,0)-1)) -> 0 | H39: Member Centricity | I39: 0 | J39: =SUMIF('PPvsREal Summary'!$C:$C,RESUMEN!B39,'PPvsREal Summary'!$AC:$AC) -> 0 | K39: 0 | L39: =IF((IFERROR(J39/I39,0))=0,0,(IFERROR(J39/I39,0)-1)) -> 0 | M39: =IF((IFERROR(J39/K39,0))=0,0,(IFERROR(J39/K39,0)-1)) -> 0 | O39: 0 | P39: 0 | Q39: 0 | R39: =IF((IFERROR(O39/P39,0))=0,0,(IFERROR(O39/P39,0)-1)) -> 0 | S39: =IF((IFERROR(O39/Q39,0))=0,0,(IFERROR(O39/Q39,0)-1)) -> 0 | U39: 0 | V39: =J39-U39 -> 0 | W39: =J39/U39-1 -> #DIV/0!
C40: =C41+C42 -> 0 | D40: =D41+D42 -> 0 | E40: =E41+E42 -> 0 | F40: =IF((IFERROR(C40/D40,0))=0,0,(IFERROR(C40/D40,0)-1)) -> 0 | G40: =IF((IFERROR(C40/E40,0))=0,0,(IFERROR(C40/E40,0)-1)) -> 0 | H40: Other | I40: =I41+I42 -> 215.81 | J40: =J41+J42 -> 0 | K40: =K41+K42 -> 0 | L40: =IF((IFERROR(J40/I40,0))=0,0,(IFERROR(J40/I40,0)-1)) -> 0 | M40: =IF((IFERROR(J40/K40,0))=0,0,(IFERROR(J40/K40,0)-1)) -> 0 | O40: =O41+O42 -> 0 | P40: =P41+P42 -> 0 | Q40: =Q41+Q42 -> 0 | R40: =IF((IFERROR(O40/P40,0))=0,0,(IFERROR(O40/P40,0)-1)) -> 0 | S40: =IF((IFERROR(O40/Q40,0))=0,0,(IFERROR(O40/Q40,0)-1)) -> 0 | U40: 0 | V40: =J40-U40 -> 0 | W40: =J40/U40-1 -> #DIV/0!
B41: 4.02e+20 | C41: 0 | D41: 0 | E41: 0 | F41: =IF((IFERROR(C41/D41,0))=0,0,(IFERROR(C41/D41,0)-1)) -> 0 | G41: =IF((IFERROR(C41/E41,0))=0,0,(IFERROR(C41/E41,0)-1)) -> 0 | H41: Otros ingresos | I41: 215.81 | J41: =SUMIF('PPvsREal Summary'!$C:$C,RESUMEN!B41,'PPvsREal Summary'!$AC:$AC) -> 0 | K41: 0 | L41: =IF((IFERROR(J41/I41,0))=0,0,(IFERROR(J41/I41,0)-1)) -> 0 | M41: =IF((IFERROR(J41/K41,0))=0,0,(IFERROR(J41/K41,0)-1)) -> 0 | O41: 0 | P41: 0 | Q41: 0 | R41: =IF((IFERROR(O41/P41,0))=0,0,(IFERROR(O41/P41,0)-1)) -> 0 | S41: =IF((IFERROR(O41/Q41,0))=0,0,(IFERROR(O41/Q41,0)-1)) -> 0
B42: 4.1e+20 | C42: 0 | D42: 0 | E42: 0 | F42: =IF((IFERROR(C42/D42,0))=0,0,(IFERROR(C42/D42,0)-1)) -> 0 | G42: =IF((IFERROR(C42/E42,0))=0,0,(IFERROR(C42/E42,0)-1)) -> 0 | H42: Utilidad cambiaria | I42: 0 | J42: =SUMIF('PPvsREal Summary'!$C:$C,RESUMEN!B42,'PPvsREal Summary'!$AC:$AC) -> 0 | K42: 0 | L42: =IF((IFERROR(J42/I42,0))=0,0,(IFERROR(J42/I42,0)-1)) -> 0 | M42: =IF((IFERROR(J42/K42,0))=0,0,(IFERROR(J42/K42,0)-1)) -> 0 | O42: 0 | P42: 0 | Q42: 0 | R42: =IF((IFERROR(O42/P42,0))=0,0,(IFERROR(O42/P42,0)-1)) -> 0 | S42: =IF((IFERROR(O42/Q42,0))=0,0,(IFERROR(O42/Q42,0)-1)) -> 0
C43: =C38-C39+C40 -> 0 | D43: =D38-D39+D40 -> 0 | E43: =E38-E39+E40 -> 0 | F43: =IF((IFERROR(C43/D43,0))=0,0,(IFERROR(C43/D43,0)-1)) -> 0 | G43: =IF((IFERROR(C43/E43,0))=0,0,(IFERROR(C43/E43,0)-1)) -> 0 | H43: NET RESULTS | I43: =I38-I39+I40 -> -462807.79 | J43: =J38-J39+J40 -> 110021.59 | K43: =K38-K39+K40 -> 840995.69 | L43: =IF((IFERROR(J43/I43,0))=0,0,(IFERROR(J43/I43,0)-1)) -> -1.2377263 | M43: =IF((IFERROR(J43/K43,0))=0,0,(IFERROR(J43/K43,0)-1)) -> -0.86917699 | O43: =O38-O39+O40 -> 0 | P43: =P38-P39+P40 -> 0 | Q43: =Q38-Q39+Q40 -> 0 | R43: =IF((IFERROR(O43/P43,0))=0,0,(IFERROR(O43/P43,0)-1)) -> 0 | S43: =IF((IFERROR(O43/Q43,0))=0,0,(IFERROR(O43/Q43,0)-1)) -> 0 | U43: =U38-U39+U40 -> 158553.44 | V43: =V38-V39+V40 -> -48531.857 | W43: =J43/U43-1 -> -0.30609147
...

Sheet Gtos. Corporativos
C1: AMERICAN CHAMBER OF COMMERCE OF MEXICO, A.C.
C3: GASTOS CORPORATIVOS 2026 | D3: Real 2025 | E3: Ppto. 2026 | F3: Var. % | G3: Criterio | H3: Mensual | J3: 46023 | K3: 46023 | L3: 46054 | M3: 46054 | N3: 46082 | O3: 46082 | P3: 46113 | Q3: 46113 | R3: 46143 | S3: 46143 | T3: 46174 | U3: 46174 | V3: 46204 | W3: 46204 | X3: 46235 | Y3: 46235 | Z3: 46266 | AA3: 46266 | AB3: 46296 | AC3: 46296 | AD3: 46327 | AE3: 46327 | AF3: 46357 | AG3: 46357
B4: 903-034-000-00 | C4: Seguro Gtos Médicos Mayores | D4: 448491.96 | E4: 432000 | F4: =IFERROR(((E4/D4)-1),1) -> -0.03677203 | G4: Costo Directo | H4: =E4/12 -> 36000 | J4: =H4 -> 36000 | L4: =J4 -> 36000 | N4: =L4 -> 36000 | P4: =N4 -> 36000 | R4: =P4 -> 36000 | T4: =R4 -> 36000 | V4: =T4 -> 36000 | X4: =V4 -> 36000 | Z4: =X4 -> 36000 | AB4: =Z4 -> 36000 | AD4: =AB4 -> 36000 | AF4: =AD4 -> 36000
B5: 903-033-000-00 | C5: Seguro de Vida | D5: 17797.36 | E5: 19288.343 | F5: =IFERROR(((E5/D5)-1),1) -> 0.083775503 | G5: Costo Directo | H5: =E5/12 -> 1607.3619 | J5: =H5 -> 1607.3619 | L5: =J5 -> 1607.3619 | N5: =L5 -> 1607.3619 | P5: =N5 -> 1607.3619 | R5: =P5 -> 1607.3619 | T5: =R5 -> 1607.3619 | V5: =T5 -> 1607.3619 | X5: =V5 -> 1607.3619 | Z5: =X5 -> 1607.3619 | AB5: =Z5 -> 1607.3619 | AD5: =AB5 -> 1607.3619 | AF5: =AD5 -> 1607.3619
B6: 903-002-000-00 | C6: Seguro Empresarial | D6: 17484 | E6: 18083.344 | F6: =IFERROR(((E6/D6)-1),1) -> 0.034279564 | G6: Costo Directo | H6: =E6/12 -> 1506.9453 | J6: =H6 -> 1506.9453 | L6: =J6 -> 1506.9453 | N6: =L6 -> 1506.9453 | P6: =N6 -> 1506.9453 | R6: =P6 -> 1506.9453 | T6: =R6 -> 1506.9453 | V6: =T6 -> 1506.9453 | X6: =V6 -> 1506.9453 | Z6: =X6 -> 1506.9453 | AB6: =Z6 -> 1506.9453 | AD6: =AB6 -> 1506.9453 | AF6: =AD6 -> 1506.9453
B7: 903-029-000-00 | C7: Seguro Gobierno Corporativo | D7: 0 | E7: 8904 | F7: =IFERROR(((E7/D7)-1),1) -> 1 | G7: 0.12 | H7: =E7/12 -> 742 | J7: =H7 -> 742 | L7: =J7 -> 742 | N7: =L7 -> 742 | P7: =N7 -> 742 | R7: =P7 -> 742 | T7: =R7 -> 742 | V7: =T7 -> 742 | X7: =V7 -> 742 | Z7: =X7 -> 742 | AB7: =Z7 -> 742 | AD7: =AB7 -> 742 | AF7: =AD7 -> 742
B8: 903-003-000-00 | C8: Programa de Asistencia Empresarial (PAE) | D8: 9493.16 | E8: 11414.943 | F8: =IFERROR(((E8/D8)-1),1) -> 0.20243869 | G8: Costo Directo | H8: =E8/12 -> 951.24524 | J8: =H8 -> 951.24524 | L8: =J8 -> 951.24524 | N8: =L8 -> 951.24524 | P8: =N8 -> 951.24524 | R8: =P8 -> 951.24524 | T8: =R8 -> 951.24524 | V8: =T8 -> 951.24524 | X8: =V8 -> 951.24524 | Z8: =X8 -> 951.24524 | AB8: =Z8 -> 951.24524 | AD8: =AB8 -> 951.24524 | AF8: =AD8 -> 951.24524
B9: 903-030-000-00 | C9: Dominios | D9: 250.44 | E9: 245.04826 | F9: =IFERROR(((E9/D9)-1),1) -> -0.021529085 | G9: 0.12 | H9: =E9/12 -> 20.420688 | J9: =H9 -> 20.420688 | L9: =J9 -> 20.420688 | N9: =L9 -> 20.420688 | P9: =N9 -> 20.420688 | R9: =P9 -> 20.420688 | T9: =R9 -> 20.420688 | V9: =T9 -> 20.420688 | X9: =V9 -> 20.420688 | Z9: =X9 -> 20.420688 | AB9: =Z9 -> 20.420688 | AD9: =AB9 -> 20.420688 | AF9: =AD9 -> 20.420688
B10: 903-032-000-00 | C10: CRM | D10: 0 | E10: 57461.328 | F10: =IFERROR(((E10/D10)-1),1) -> 1 | G10: 0.12 | H10: =E10/12 -> 4788.444 | J10: =H10 -> 4788.444 | L10: =J10 -> 4788.444 | N10: =L10 -> 4788.444 | P10: =N10 -> 4788.444 | R10: =P10 -> 4788.444 | T10: =R10 -> 4788.444 | V10: =T10 -> 4788.444 | X10: =V10 -> 4788.444 | Z10: =X10 -> 4788.444 | AB10: =Z10 -> 4788.444 | AD10: =AB10 -> 4788.444 | AF10: =AD10 -> 4788.444
B11: 903-018-000-00 | C11: Servicios de Telecomunicaciones | D11: 95628 | E11: 93568.32 | F11: =IFERROR(((E11/D11)-1),1) -> -0.021538462 | G11: 0.12 | H11: =E11/12 -> 7797.36 | J11: =H11 -> 7797.36 | L11: =J11 -> 7797.36 | N11: =L11 -> 7797.36 | P11: =N11 -> 7797.36 | R11: =P11 -> 7797.36 | T11: =R11 -> 7797.36 | V11: =T11 -> 7797.36 | X11: =V11 -> 7797.36 | Z11: =X11 -> 7797.36 | AB11: =Z11 -> 7797.36 | AD11: =AB11 -> 7797.36 | AF11: =AD11 -> 7797.36
B12: 903-031-000-00 | C12: Licencias Generales | D12: 57882.27 | E12: 87034.851 | F12: =IFERROR(((E12/D12)-1),1) -> 0.50365303 | G12: 0.12 | H12: =E12/12 -> 7252.9042 | J12: =H12 -> 7252.9042 | L12: =J12 -> 7252.9042 | N12: =L12 -> 7252.9042 | P12: =N12 -> 7252.9042 | R12: =P12 -> 7252.9042 | T12: =R12 -> 7252.9042 | V12: =T12 -> 7252.9042 | X12: =V12 -> 7252.9042 | Z12: =X12 -> 7252.9042 | AB12: =Z12 -> 7252.9042 | AD12: =AB12 -> 7252.9042 | AF12: =AD12 -> 7252.9042
B13: 903-028-000-00 | C13: Licencias Correos Corporativos | D13: 49328.96 | E13: 50817.672 | F13: =IFERROR(((E13/D13)-1),1) -> 0.03017927 | G13: 0.12 | H13: =E13/12 -> 4234.806 | J13: =H13 -> 4234.806 | L13: =J13 -> 4234.806 | N13: =L13 -> 4234.806 | P13: =N13 -> 4234.806 | R13: =P13 -> 4234.806 | T13: =R13 -> 4234.806 | V13: =T13 -> 4234.806 | X13: =V13 -> 4234.806 | Z13: =X13 -> 4234.806 | AB13: =Z13 -> 4234.806 | AD13: =AB13 -> 4234.806 | AF13: =AD13 -> 4234.806
B14: 903-011-000-00 | C14: Estudio actuarial | D14: 3230.76 | E14: 3161.1744 | F14: =IFERROR(((E14/D14)-1),1) -> -0.021538462 | G14: 0.12 | H14: =E14/12 -> 263.4312 | J14: =H14 -> 263.4312 | L14: =J14 -> 263.4312 | N14: =L14 -> 263.4312 | P14: =N14 -> 263.4312 | R14: =P14 -> 263.4312 | T14: =R14 -> 263.4312 | V14: =T14 -> 263.4312 | X14: =V14 -> 263.4312 | Z14: =X14 -> 263.4312 | AB14: =Z14 -> 263.4312 | AD14: =AB14 -> 263.4312 | AF14: =AD14 -> 263.4312
B15: 903-012-000-00 | C15: Gtos Notariales | D15: 1608 | E15: 1573.7184 | F15: =IFERROR(((E15/D15)-1),1) -> -0.021319403 | G15: 0.12 | H15: =E15/12 -> 131.1432 | J15: =H15 -> 131.1432 | L15: =J15 -> 131.1432 | N15: =L15 -> 131.1432 | P15: =N15 -> 131.1432 | R15: =P15 -> 131.1432 | T15: =R15 -> 131.1432 | V15: =T15 -> 131.1432 | X15: =V15 -> 131.1432 | Z15: =X15 -> 131.1432 | AB15: =Z15 -> 131.1432 | AD15: =AB15 -> 131.1432 | AF15: =AD15 -> 131.1432
B16: 903-017-000-00 | C16: Auditorías Externas | D16: 65005.2 | E16: 63605.088 | F16: =IFERROR(((E16/D16)-1),1) -> -0.021538462 | G16: 0.12 | H16: =E16/12 -> 5300.424 | J16: =H16 -> 5300.424 | L16: =J16 -> 5300.424 | N16: =L16 -> 5300.424 | P16: =N16 -> 5300.424 | R16: =P16 -> 5300.424 | T16: =R16 -> 5300.424 | V16: =T16 -> 5300.424 | X16: =V16 -> 5300.424 | Z16: =X16 -> 5300.424 | AB16: =Z16 -> 5300.424 | AD16: =AB16 -> 5300.424 | AF16: =AD16 -> 5300.424
B17: 903-014-000-00 | C17: Registro de Marcas | D17: 6348 | E17: 6206.3424 | F17: =IFERROR(((E17/D17)-1),1) -> -0.022315312 | G17: 0.12 | H17: =E17/12 -> 517.1952 | J17: =H17 -> 517.1952 | L17: =J17 -> 517.1952 | N17: =L17 -> 517.1952 | P17: =N17 -> 517.1952 | R17: =P17 -> 517.1952 | T17: =R17 -> 517.1952 | V17: =T17 -> 517.1952 | X17: =V17 -> 517.1952 | Z17: =X17 -> 517.1952 | AB17: =Z17 -> 517.1952 | AD17: =AB17 -> 517.1952 | AF17: =AD17 -> 517.1952
B18: 903-015-000-00 | C18: Membresía AACCLA | D18: 50576.11 | E18: 48967.5 | F18: =IFERROR(((E18/D18)-1),1) -> -0.031805735 | G18: 0.12 | H18: =E18/12 -> 4080.625 | J18: =H18 -> 4080.625 | L18: =J18 -> 4080.625 | N18: =L18 -> 4080.625 | P18: =N18 -> 4080.625 | R18: =P18 -> 4080.625 | T18: =R18 -> 4080.625 | V18: =T18 -> 4080.625 | X18: =V18 -> 4080.625 | Z18: =X18 -> 4080.625 | AB18: =Z18 -> 4080.625 | AD18: =AB18 -> 4080.625 | AF18: =AD18 -> 4080.625
C19: Almacén de Archivos | D19: 6782.23 | E19: 0 | F19: =IFERROR(((E19/D19)-1),1) -> -1 | G19: 0 | H19: =E19/12 -> 0 | J19: =H19 -> 0 | L19: =J19 -> 0 | N19: =L19 -> 0 | P19: =N19 -> 0 | R19: =P19 -> 0 | T19: =R19 -> 0 | V19: =T19 -> 0 | X19: =V19 -> 0 | Z19: =X19 -> 0 | AB19: =Z19 -> 0 | AD19: =AB19 -> 0 | AF19: =AD19 -> 0
B20: 903-024-000-00 | C20: T&IC Licencias | D20: 106629.56 | E20: 119174.12 | F20: =IFERROR(((E20/D20)-1),1) -> 0.11764622 | G20: 0.12 | H20: =E20/12 -> 9931.177 | J20: =H20 -> 9931.177 | L20: =J20 -> 9931.177 | N20: =L20 -> 9931.177 | P20: =N20 -> 9931.177 | R20: =P20 -> 9931.177 | T20: =R20 -> 9931.177 | V20: =T20 -> 9931.177 | X20: =V20 -> 9931.177 | Z20: =X20 -> 9931.177 | AB20: =Z20 -> 9931.177 | AD20: =AB20 -> 9931.177 | AF20: =AD20 -> 9931.177
B21: 903-005-000-00 | C21: LinkedIn Herramienta | D21: 57714.01 | E21: 60362.542 | F21: =IFERROR(((E21/D21)-1),1) -> 0.045890624 | G21: Costo Directo | H21: =E21/12 -> 5030.2118 | J21: =H21 -> 5030.2118 | L21: =J21 -> 5030.2118 | N21: =L21 -> 5030.2118 | P21: =N21 -> 5030.2118 | R21: =P21 -> 5030.2118 | T21: =R21 -> 5030.2118 | V21: =T21 -> 5030.2118 | X21: =V21 -> 5030.2118 | Z21: =X21 -> 5030.2118 | AB21: =Z21 -> 5030.2118 | AD21: =AB21 -> 5030.2118 | AF21: =AD21 -> 5030.2118
B22: 903-008-000-00 | C22: Zoom Herramienta | D22: 8591.83 | E22: 8406.8045 | F22: =IFERROR(((E22/D22)-1),1) -> -0.021535056 | G22: 0.12 | H22: =E22/12 -> 700.56704 | J22: =H22 -> 700.56704 | L22: =J22 -> 700.56704 | N22: =L22 -> 700.56704 | P22: =N22 -> 700.56704 | R22: =P22 -> 700.56704 | T22: =R22 -> 700.56704 | V22: =T22 -> 700.56704 | X22: =V22 -> 700.56704 | Z22: =X22 -> 700.56704 | AB22: =Z22 -> 700.56704 | AD22: =AB22 -> 700.56704 | AF22: =AD22 -> 700.56704
B23: 903-019-000-00 | C23: NarwhalHub Herramienta | D23: 0 | E23: 91932.935 | F23: =IFERROR(((E23/D23)-1),1) -> 1 | G23: 0.12 | H23: =E23/12 -> 7661.0779 | J23: =H23 -> 7661.0779 | L23: =J23 -> 7661.0779 | N23: =L23 -> 7661.0779 | P23: =N23 -> 7661.0779 | R23: =P23 -> 7661.0779 | T23: =R23 -> 7661.0779 | V23: =T23 -> 7661.0779 | X23: =V23 -> 7661.0779 | Z23: =X23 -> 7661.0779 | AB23: =Z23 -> 7661.0779 | AD23: =AB23 -> 7661.0779 | AF23: =AD23 -> 7661.0779
B24: 903-026-000-00 | C24: Posicionamiento | D24: 0 | E24: 108374.4 | F24: =IFERROR(((E24/D24)-1),1) -> 1 | G24: 0.12 | H24: =E24/12 -> 9031.2 | J24: =H24 -> 9031.2 | L24: =J24 -> 9031.2 | N24: =L24 -> 9031.2 | P24: =N24 -> 9031.2 | R24: =P24 -> 9031.2 | T24: =R24 -> 9031.2 | V24: =T24 -> 9031.2 | X24: =V24 -> 9031.2 | Z24: =X24 -> 9031.2 | AB24: =Z24 -> 9031.2 | AD24: =AB24 -> 9031.2 | AF24: =AD24 -> 9031.2
B25: 903-016-000-00 | C25: Sueldos y Salarios VPE/Nacionales | D25: 3024687.9 | E25: 3038397.5 | F25: =IFERROR(((E25/D25)-1),1) -> 0.0045325734 | G25: 0.12 | H25: =E25/12 -> 253199.79 | J25: =H25 -> 253199.79 | L25: =J25 -> 253199.79 | N25: =L25 -> 253199.79 | P25: =N25 -> 253199.79 | R25: =P25 -> 253199.79 | T25: =R25 -> 253199.79 | V25: =T25 -> 253199.79 | X25: =V25 -> 253199.79 | Z25: =X25 -> 253199.79 | AB25: =Z25 -> 253199.79 | AD25: =AB25 -> 253199.79 | AF25: =AD25 -> 253199.79
C26: TOTAL CARGOS CORPORATIVOS | D26: =SUM(D4:D25) -> 4027529.7 | E26: =SUM(E4:E25) -> 4328980 | F26: =IFERROR(((E26/D26)-1),1) -> 0.074847429 | H26: =SUM(H4:H25) -> 360748.33 | J26: =SUM(J4:J25) -> 360748.33 | K26: =SUM(K4:K25) -> 0 | L26: =SUM(L4:L25) -> 360748.33 | M26: =SUM(M4:M25) -> 0 | N26: =SUM(N4:N25) -> 360748.33 | O26: =SUM(O4:O25) -> 0 | P26: =SUM(P4:P25) -> 360748.33 | Q26: =SUM(Q4:Q25) -> 0 | ... AG26: =SUM(AG4:AG25) -> 0

Sheet DN
C2: MEMBRESIA | D2: 46023 | E2: 46023 | F2: 46054 | G2: 46054 | H2: 46082 | I2: 46082 | J2: 46113 | K2: 46113 | L2: 46143 | M2: 46143 | N2: 46174 | O2: 46174 | P2: 46204 | Q2: 46204 | R2: 46235 | S2: 46235 | T2: 46266 | U2: 46266 | V2: 46296 | W2: 46296 | X2: 46327 | Y2: 46327 | Z2: 46357 | AA2: 46357 | AB2: 2026
C4: Ingresos Membresía
B5: 400-001-000-00 | C5: Renovaciones | D5: 695531.68 | E5: 0 | F5: 695531.68 | G5: 0 | H5: 695531.68 | I5: 0 | J5: 695531.68 | K5: 0 | L5: 695531.68 | M5: 0 | N5: 695531.68 | O5: 0 | P5: 695531.68 | Q5: 0 | R5: 695531.68 | S5: 0 | T5: 695531.68 | U5: 0 | V5: 695531.68 | W5: 0 | X5: 695531.68 | Y5: 0 | Z5: 695531.68 | AA5: 0 | AB5: =D5+F5+H5+J5+L5+N5+P5+R5+T5+V5+X5+Z5 -> 8346380.2
B6: 400-002-000-00 | C6: Descuentos | D6: -18444.425 | E6: 0 | F6: -18423.995 | G6: 0 | H6: -18402.897 | I6: 0 | J6: -18493.591 | K6: 0 | L6: -19741.292 | M6: 0 | N6: -18391.145 | O6: 0 | P6: -18402.073 | Q6: 0 | R6: -18545.187 | S6: 0 | T6: -18954.145 | U6: 0 | V6: -12255.603 | W6: 0 | X6: -12255.603 | Y6: 0 | Z6: -12264.267 | AA6: 0 | AB6: =D6+F6+H6+J6+L6+N6+P6+R6+T6+V6+X6+Z6 -> -204574.22
B7: 400-005-000-00 | C7: Socios Nuevos | D7: 260871.54 | E7: 0 | F7: 260871.54 | G7: 0 | H7: 260871.54 | I7: 0 | J7: 260871.54 | K7: 0 | L7: 260871.54 | M7: 0 | N7: 260871.54 | O7: 0 | P7: 260871.54 | Q7: 0 | R7: 260871.54 | S7: 0 | T7: 260871.54 | U7: 0 | V7: 260871.54 | W7: 0 | X7: 260871.54 | Y7: 0 | Z7: 260871.54 | AA7: 0 | AB7: =D7+F7+H7+J7+L7+N7+P7+R7+T7+V7+X7+Z7 -> 3130458.5
B8: 401-001-000-00 | C8: Cuotas Suscripción | D8: 42036 | E8: 0 | F8: 74015 | G8: 0 | H8: 25425 | I8: 0 | J8: 27685 | K8: 0 | L8: 0 | M8: 0 | N8: 33335 | O8: 0 | P8: 33335 | Q8: 0 | R8: 18419 | S8: 0 | T8: 34804 | U8: 0 | V8: 67800 | W8: 0 | X8: 80230 | Y8: 0 | Z8: 73450 | AA8: 0 | AB8: =D8+F8+H8+J8+L8+N8+P8+R8+T8+V8+X8+Z8 -> 510534
C9: Suma de Ingresos Membresía | D9: =SUM(D5:D8) -> 979994.8 | E9: =SUM(E5:E8) -> 0 | F9: =SUM(F5:F8) -> 1011994.2 | G9: =SUM(G5:G8) -> 0 | H9: =SUM(H5:H8) -> 963425.32 | I9: =SUM(I5:I8) -> 0 | J9: =SUM(J5:J8) -> 965594.63 | K9: =SUM(K5:K8) -> 0 | ... AB9: =SUM(AB5:AB8) -> 11782798
C11: Gastos Membresía
B12: 702-002-000-00 | C12: Herramienta Sales Force | D12: 0 | E12: 0 | F12: 0 | G12: 0 | H12: 0 | I12: 0 | J12: 0 | K12: 0 | L12: 0 | M12: 0 | N12: 0 | O12: 0 | P12: 0 | Q12: 0 | R12: 0 | S12: 0 | T12: 0 | U12: 0 | V12: 0 | W12: 0 | X12: 0 | Y12: 0 | Z12: 0 | AA12: 0 | AB12: =D12+F12+H12+J12+L12+N12+P12+R12+T12+V12+X12+Z12 -> 0
B13: 503-000-000-00 | C13: Comisiones KAM´s | D13: 38293.58 | E13: 0 | F13: 38293.58 | G13: 0 | H13: 38293.58 | I13: 0 | J13: 38293.58 | K13: 0 | L13: 38293.58 | M13: 0 | N13: 38293.58 | O13: 0 | P13: 38293.58 | Q13: 0 | R13: 38293.58 | S13: 0 | T13: 38293.58 | U13: 0 | V13: 38293.58 | W13: 0 | X13: 38293.58 | Y13: 0 | Z13: 38293.58 | AA13: 0 | AB13: =D13+F13+H13+J13+L13+N13+P13+R13+T13+V13+X13+Z13 -> 459522.96
B14: 702-001-000-00 | C14: Desayunos promoción - Onboarding | D14: 1657.0026 | E14: 0 | F14: 1923.9636 | G14: 0 | H14: 0 | I14: 0 | J14: 860.031 | K14: 0 | L14: 0 | M14: 0 | N14: 4139.247 | O14: 0 | P14: 0 | Q14: 0 | R14: 0 | S14: 0 | T14: 2339.314 | U14: 0 | V14: 0 | W14: 0 | X14: 22600 | Y14: 0 | Z14: 0 | AA14: 0 | AB14: =D14+F14+H14+J14+L14+N14+P14+R14+T14+V14+X14+Z14 -> 33519.558
C15: Suma de Gastos Membresía | D15: =SUM(D12:D14) -> 39950.583 | E15: =SUM(E12:E14) -> 0 | F15: =SUM(F12:F14) -> 40217.544 | G15: =SUM(G12:G14) -> 0 | H15: =SUM(H12:H14) -> 38293.58 | I15: =SUM(I12:I14) -> 0 | J15: =SUM(J12:J14) -> 39153.611 | K15: =SUM(K12:K14) -> 0 | ... AB15: =SUM(AB12:AB14) -> 493042.52
C18: Resultado Membresía | D18: =+D9-D15 -> 940044.21 | E18: =+E9-E15 -> 0 | F18: =+F9-F15 -> 971776.68 | G18: =+G9-G15 -> 0 | H18: =+H9-H15 -> 925131.74 | I18: =+I9-I15 -> 0 | J18: =+J9-J15 -> 926441.02 | K18: =+K9-K15 -> 0 | ... AB18: =+AB9-AB15 -> 11289756

Sheet Comités
C2: COMITÉS | D2: 46023 | E2: 46023 | F2: 46054 | G2: 46054 | H2: 46082 | I2: 46082 | J2: 46113 | K2: 46113 | L2: 46143 | M2: 46143 | N2: 46174 | O2: 46174 | P2: 46204 | Q2: 46204 | R2: 46235 | S2: 46235 | T2: 46266 | U2: 46266 | V2: 46296 | W2: 46296 | X2: 46327 | Y2: 46327 | Z2: 46357 | AA2: 46357 | AB2: 2026
AC3: Agregan Steering Group en Ig. $0 y Eg. $5K
C4: Ingresos Comités | AC4: Agregan Diversidad e Inclusión en Ig. $0 y Eg. $5K
B5: 404-017-000-00 | C5: Agroindustria | D5: 0 | E5: 0 | F5: 0 | G5: 0 | H5: 0 | I5: 0 | J5: 0 | K5: 0 | L5: 0 | M5: 0 | N5: 0 | O5: 0 | P5: 5000 | Q5: 0 | R5: 0 | S5: 0 | T5: 0 | U5: 0 | V5: 0 | W5: 0 | X5: 0 | Y5: 0 | Z5: 0 | AA5: 0 | AB5: =D5+F5+H5+J5+L5+N5+P5+R5+T5+V5+X5+Z5 -> 5000 | AC5: Ig. Y Eg. $5K anuales
B6: 404-005-000-00 | C6: Asuntos Fiscales | D6: 13500 | E6: 0 | F6: 13500 | G6: 0 | H6: 13500 | I6: 0 | J6: 13500 | K6: 0 | L6: 13500 | M6: 0 | N6: 13500 | O6: 0 | P6: 13500 | Q6: 0 | R6: 13500 | S6: 0 | T6: 13500 | U6: 0 | V6: 13500 | W6: 0 | X6: 13500 | Y6: 0 | Z6: 0 | AA6: 0 | AB6: =D6+F6+H6+J6+L6+N6+P6+R6+T6+V6+X6+Z6 -> 148500 | AC6: Ig. $148.5K y Eg. $132K anuales
B7: 404-001-000-00 | C7: Capital Humano y Asuntos Laborales | D7: 13500 | E7: 0 | F7: 13500 | G7: 0 | H7: 13500 | I7: 0 | J7: 13500 | K7: 0 | L7: 13500 | M7: 0 | N7: 13500 | O7: 0 | P7: 13500 | Q7: 0 | R7: 13500 | S7: 0 | T7: 13500 | U7: 0 | V7: 13500 | W7: 0 | X7: 13500 | Y7: 0 | Z7: 0 | AA7: 0 | AB7: =D7+F7+H7+J7+L7+N7+P7+R7+T7+V7+X7+Z7 -> 148500 | AC7: Ig. $148.5K y Eg. $132K anuales
B8: 404-012-000-00 | C8: Diversidad e Inclusión | D8: 0 | E8: 0 | F8: 0 | G8: 0 | H8: 0 | I8: 0 | J8: 0 | K8: 0 | L8: 0 | M8: 0 | N8: 0 | O8: 0 | P8: 0 | Q8: 0 | R8: 0 | S8: 0 | T8: 0 | U8: 0 | V8: 0 | W8: 0 | X8: 0 | Y8: 0 | Z8: 0 | AA8: 0 | AB8: =D8+F8+H8+J8+L8+N8+P8+R8+T8+V8+X8+Z8 -> 0
B9: 404-003-000-00 | C9: Comercio Exterior y Logística | D9: 13500 | E9: 0 | F9: 13500 | G9: 0 | H9: 13500 | I9: 0 | J9: 13500 | K9: 0 | L9: 13500 | M9: 0 | N9: 13500 | O9: 0 | P9: 13500 | Q9: 0 | R9: 13500 | S9: 0 | T9: 13500 | U9: 0 | V9: 13500 | W9: 0 | X9: 13500 | Y9: 0 | Z9: 0 | AA9: 0 | AB9: =D9+F9+H9+J9+L9+N9+P9+R9+T9+V9+X9+Z9 -> 148500 | AC9: Ig. $148.5K y Eg. $132K anuales
B10: 404-013-000-00 | C10: Innovación y TICs | D10: 0 | E10: 0 | F10: 0 | G10: 0 | H10: 0 | I10: 0 | J10: 0 | K10: 0 | L10: 0 | M10: 0 | N10: 0 | O10: 0 | P10: 0 | Q10: 0 | R10: 0 | S10: 0 | T10: 0 | U10: 0 | V10: 0 | W10: 0 | X10: 0 | Y10: 0 | Z10: 0 | AA10: 0 | AB10: =D10+F10+H10+J10+L10+N10+P10+R10+T10+V10+X10+Z10 -> 0 | AC10: Ig. $0 y Eg. $0 anuales
B11: 404-007-000-00 | C11: Legalidad y Estado de Derecho | D11: 0 | E11: 0 | F11: 0 | G11: 0 | H11: 0 | I11: 0 | J11: 0 | K11: 0 | L11: 0 | M11: 0 | N11: 0 | O11: 0 | P11: 0 | Q11: 0 | R11: 0 | S11: 0 | T11: 0 | U11: 0 | V11: 0 | W11: 0 | X11: 0 | Y11: 0 | Z11: 0 | AA11: 0 | AB11: =D11+F11+H11+J11+L11+N11+P11+R11+T11+V11+X11+Z11 -> 0 | AC11: Ig. $0 y Eg. $0 anuales
B12: 404-016-000-00 | C12: Salud | D12: 0 | E12: 0 | F12: 0 | G12: 0 | H12: 0 | I12: 0 | J12: 0 | K12: 0 | L12: 0 | M12: 0 | N12: 0 | O12: 0 | P12: 0 | Q12: 0 | R12: 0 | S12: 0 | T12: 0 | U12: 0 | V12: 0 | W12: 0 | X12: 0 | Y12: 0 | Z12: 0 | AA12: 0 | AB12: =D12+F12+H12+J12+L12+N12+P12+R12+T12+V12+X12+Z12 -> 0 | AC12: Ig. $0 y Eg. $0 anuales
B13: 404-004-000-00 | C13: Seguridad | D13: 0 | E13: 0 | F13: 0 | G13: 0 | H13: 0 | I13: 0 | J13: 0 | K13: 0 | L13: 0 | M13: 0 | N13: 0 | O13: 0 | P13: 0 | Q13: 0 | R13: 0 | S13: 0 | T13: 0 | U13: 0 | V13: 0 | W13: 0 | X13: 0 | Y13: 0 | Z13: 0 | AA13: 0 | AB13: =D13+F13+H13+J13+L13+N13+P13+R13+T13+V13+X13+Z13 -> 0 | AC13: Ig. $0 y Eg. $0 anuales
B14: 404-008-000-00 | C14: Sustentabilidad y Responsabilidad Social | D14: 0 | E14: 0 | F14: 0 | G14: 0 | H14: 0 | I14: 0 | J14: 0 | K14: 0 | L14: 0 | M14: 0 | N14: 0 | O14: 0 | P14: 0 | Q14: 0 | R14: 0 | S14: 0 | T14: 0 | U14: 0 | V14: 0 | W14: 0 | X14: 0 | Y14: 0 | Z14: 0 | AA14: 0 | AB14: =D14+F14+H14+J14+L14+N14+P14+R14+T14+V14+X14+Z14 -> 0 | AC14: Ig. $0 y Eg. $0 anuales
B15: 404-009-000-00 | C15: Turismo | D15: 0 | E15: 0 | F15: 0 | G15: 0 | H15: 0 | I15: 0 | J15: 0 | K15: 0 | L15: 0 | M15: 0 | N15: 0 | O15: 0 | P15: 0 | Q15: 0 | R15: 0 | S15: 0 | T15: 0 | U15: 0 | V15: 0 | W15: 0 | X15: 0 | Y15: 0 | Z15: 0 | AA15: 0 | AB15: =D15+F15+H15+J15+L15+N15+P15+R15+T15+V15+X15+Z15 -> 0 | AC15: Ig. $0 y Eg. $0 anuales
B16: 404-018-000-00 | C16: Programa de Mentoría (EWDP) | D16: 0 | E16: 0 | F16: 0 | G16: 0 | H16: 0 | I16: 0 | J16: 0 | K16: 0 | L16: =71500+71428.57 -> 142928.57 | M16: 0 | N16: =215416.66+71428.57 -> 286845.23 | O16: 0 | P16: =167749.99+71428.57 -> 239178.56 | Q16: 0 | R16: =11916.66+71428.57+100000 -> 183345.23 | S16: 0 | T16: =11916.66+71428.57 -> 83345.23 | U16: 0 | V16: =0+71428.57 -> 71428.57 | W16: 0 | X16: =0+71428.57 -> 71428.57 | Y16: 0 | Z16: 0 | AA16: 0 | AB16: =D16+F16+H16+J16+L16+N16+P16+R16+T16+V16+X16+Z16 -> 1078500 | AC16: Quedan igual
C17: Suma de Ingresos Comités | D17: =SUM(D5:D16) -> 40500 | E17: =SUM(E5:E16) -> 0 | F17: =SUM(F5:F16) -> 40500 | G17: =SUM(G5:G16) -> 0 | H17: =SUM(H5:H16) -> 40500 | I17: =SUM(I5:I16) -> 0 | J17: =SUM(J5:J16) -> 40500 | K17: =SUM(K5:K16) -> 0 | ... AB17: =SUM(AB5:AB16) -> 1529000
C19: Gastos Comités
B20: 502-014-000-00 | C20: Agroindustria | D20: 0 | E20: 0 | F20: 500 | G20: 0 | H20: 500 | I20: 0 | J20: 500 | K20: 0 | L20: 500 | M20: 0 | N20: 500 | O20: 0 | P20: 500 | Q20: 0 | R20: 500 | S20: 0 | T20: 500 | U20: 0 | V20: 500 | W20: 0 | X20: 500 | Y20: 0 | Z20: 0 | AA20: 0 | AB20: =D20+F20+H20+J20+L20+N20+P20+R20+T20+V20+X20+Z20 -> 5000
B21: 502-005-000-00 | C21: Asuntos Fiscales | D21: 12000 | E21: 0 | F21: 12000 | G21: 0 | H21: 12000 | I21: 0 | J21: 12000 | K21: 0 | L21: 12000 | M21: 0 | N21: 12000 | O21: 0 | P21: 12000 | Q21: 0 | R21: 12000 | S21: 0 | T21: 12000 | U21: 0 | V21: 12000 | W21: 0 | X21: 12000 | Y21: 0 | Z21: 0 | AA21: 0 | AB21: =D21+F21+H21+J21+L21+N21+P21+R21+T21+V21+X21+Z21 -> 132000
B22: 502-001-000-00 | C22: Capital Humano y Asuntos Laborales | D22: 12000 | E22: 0 | F22: 12000 | G22: 0 | H22: 12000 | I22: 0 | J22: 12000 | K22: 0 | L22: 12000 | M22: 0 | N22: 12000 | O22: 0 | P22: 12000 | Q22: 0 | R22: 12000 | S22: 0 | T22: 12000 | U22: 0 | V22: 12000 | W22: 0 | X22: 12000 | Y22: 0 | Z22: 0 | AA22: 0 | AB22: =D22+F22+H22+J22+L22+N22+P22+R22+T22+V22+X22+Z22 -> 132000
B23: 502-008-000-00 | C23: Diversidad e Inclusión | D23: 0 | E23: 0 | F23: 500 | G23: 0 | H23: 500 | I23: 0 | J23: 500 | K23: 0 | L23: 500 | M23: 0 | N23: 500 | O23: 0 | P23: 500 | Q23: 0 | R23: 500 | S23: 0 | T23: 500 | U23: 0 | V23: 500 | W23: 0 | X23: 500 | Y23: 0 | Z23: 0 | AA23: 0 | AB23: =D23+F23+H23+J23+L23+N23+P23+R23+T23+V23+X23+Z23 -> 5000
B24: 502-003-000-00 | C24: Comercio Exterior y Logística | D24: 12000 | E24: 0 | F24: 12000 | G24: 0 | H24: 12000 | I24: 0 | J24: 12000 | K24: 0 | L24: 12000 | M24: 0 | N24: 12000 | O24: 0 | P24: 12000 | Q24: 0 | R24: 12000 | S24: 0 | T24: 12000 | U24: 0 | V24: 12000 | W24: 0 | X24: 12000 | Y24: 0 | Z24: 0 | AA24: 0 | AB24: =D24+F24+H24+J24+L24+N24+P24+R24+T24+V24+X24+Z24 -> 132000
B25: 502-013-000-00 | C25: Innovación y TICs | D25: 0 | E25: 0 | F25: 500 | G25: 0 | H25: 500 | I25: 0 | J25: 500 | K25: 0 | L25: 500 | M25: 0 | N25: 500 | O25: 0 | P25: 500 | Q25: 0 | R25: 500 | S25: 0 | T25: 500 | U25: 0 | V25: 500 | W25: 0 | X25: 500 | Y25: 0 | Z25: 0 | AA25: 0 | AB25: =D25+F25+H25+J25+L25+N25+P25+R25+T25+V25+X25+Z25 -> 5000
B26: 502-007-000-00 | C26: Legalidad y Estado de Derecho | D26: 0 | E26: 0 | F26: 500 | G26: 0 | H26: 500 | I26: 0 | J26: 500 | K26: 0 | L26: 500 | M26: 0 | N26: 500 | O26: 0 | P26: 500 | Q26: 0 | R26: 500 | S26: 0 | T26: 500 | U26: 0 | V26: 500 | W26: 0 | X26: 500 | Y26: 0 | Z26: 0 | AA26: 0 | AB26: =D26+F26+H26+J26+L26+N26+P26+R26+T26+V26+X26+Z26 -> 5000
B27: 502-016-000-00 | C27: Salud | D27: 0 | E27: 0 | F27: 500 | G27: 0 | H27: 500 | I27: 0 | J27: 500 | K27: 0 | L27: 500 | M27: 0 | N27: 500 | O27: 0 | P27: 500 | Q27: 0 | R27: 500 | S27: 0 | T27: 500 | U27: 0 | V27: 500 | W27: 0 | X27: 500 | Y27: 0 | Z27: 0 | AA27: 0 | AB27: =D27+F27+H27+J27+L27+N27+P27+R27+T27+V27+X27+Z27 -> 5000
B28: 502-004-000-00 | C28: Seguridad | D28: 0 | E28: 0 | F28: 500 | G28: 0 | H28: 500 | I28: 0 | J28: 500 | K28: 0 | L28: 500 | M28: 0 | N28: 500 | O28: 0 | P28: 500 | Q28: 0 | R28: 500 | S28: 0 | T28: 500 | U28: 0 | V28: 500 | W28: 0 | X28: 500 | Y28: 0 | Z28: 0 | AA28: 0 | AB28: =D28+F28+H28+J28+L28+N28+P28+R28+T28+V28+X28+Z28 -> 5000
B29: 502-002-000-00 | C29: Sustentabilidad y Responsabilidad Social | D29: 0 | E29: 0 | F29: 500 | G29: 0 | H29: 500 | I29: 0 | J29: 500 | K29: 0 | L29: 500 | M29: 0 | N29: 500 | O29: 0 | P29: 500 | Q29: 0 | R29: 500 | S29: 0 | T29: 500 | U29: 0 | V29: 500 | W29: 0 | X29: 500 | Y29: 0 | Z29: 0 | AA29: 0 | AB29: =D29+F29+H29+J29+L29+N29+P29+R29+T29+V29+X29+Z29 -> 5000
B30: 502-009-000-00 | C30: Turismo | D30: 0 | E30: 0 | F30: 500 | G30: 0 | H30: 500 | I30: 0 | J30: 500 | K30: 0 | L30: 500 | M30: 0 | N30: 500 | O30: 0 | P30: 500 | Q30: 0 | R30: 500 | S30: 0 | T30: 500 | U30: 0 | V30: 500 | W30: 0 | X30: 500 | Y30: 0 | Z30: 0 | AA30: 0 | AB30: =D30+F30+H30+J30+L30+N30+P30+R30+T30+V30+X30+Z30 -> 5000
B31: 502-010-000-00 | C31: Steering Group | D31: 0 | F31: 500 | G31: 0 | H31: 500 | I31: 0 | J31: 500 | K31: 0 | L31: 500 | M31: 0 | N31: 500 | O31: 0 | P31: 500 | Q31: 0 | R31: 500 | S31: 0 | T31: 500 | U31: 0 | V31: 500 | W31: 0 | X31: 500 | Y31: 0 | Z31: 0 | AA31: 0 | AB31: =D31+F31+H31+J31+L31+N31+P31+R31+T31+V31+X31+Z31 -> 5000
B32: 502-017-000-00 | C32: Programa de Mentoría (EWDP) | D32: 0 | E32: 0 | F32: 0 | G32: 0 | H32: 0 | I32: 0 | J32: 0 | K32: 0 | L32: 357564.9 | M32: 0 | N32: 3352.745 | O32: 0 | P32: 4062.531 | Q32: 0 | R32: 72123.964 | S32: 0 | T32: 5170.869 | U32: 0 | V32: 0 | W32: 0 | X32: 0 | Y32: 0 | Z32: 44000 | AA32: 0 | AB32: =D32+F32+H32+J32+L32+N32+P32+R32+T32+V32+X32+Z32 -> 486275.01 | AC32: Quedan igual
C33: Suma de Gastos Comités | D33: =SUM(D20:D32) -> 36000 | E33: =SUM(E20:E32) -> 0 | F33: =SUM(F20:F32) -> 40500 | G33: =SUM(G20:G32) -> 0 | H33: =SUM(H20:H32) -> 40500 | I33: =SUM(I20:I32) -> 0 | J33: =SUM(J20:J32) -> 40500 | K33: =SUM(K20:K32) -> 0 | ... AB33: =SUM(AB20:AB32) -> 927275.01
C35: Resultado Operativo Comités | D35: =+D17-D33 -> 4500 | E35: =+E17-E33 -> 0 | F35: =+F17-F33 -> 0 | G35: =+G17-G33 -> 0 | H35: =+H17-H33 -> 0 | I35: =+I17-I33 -> 0 | J35: =+J17-J33 -> 0 | K35: =+K17-K33 -> 0 | ... AB35: =+AB17-AB33 -> 601724.95
B37: 504-000-000-00 | C37: Comisiones EWDP | D37: 0 | E37: 0 | F37: 0 | G37: 0 | H37: 0 | I37: 0 | J37: 0 | K37: 0 | L37: 0 | M37: 0 | N37: 0 | O37: 0 | P37: 0 | Q37: 0 | R37: 0 | S37: 0 | T37: 0 | U37: 0 | V37: 0 | W37: 0 | X37: 0 | Y37: 0 | Z37: 0 | AA37: 0 | AB37: =D37+F37+H37+J37+L37+N37+P37+R37+T37+V37+X37+Z37 -> 0
C39: Resultado Comités | D39: =D35-D37 -> 4500 | E39: =E35-E37 -> 0 | F39: =F35-F37 -> 0 | G39: =G35-G37 -> 0 | H39: =H35-H37 -> 0 | I39: =I35-I37 -> 0 | J39: =J35-J37 -> 0 | K39: =K35-K37 -> 0 | ... AB39: =AB35-AB37 -> 601724.95 | AC39: $512K
AB41: =AB17+'Dirección'!AB7 -> 1594590.7
C42: Nota: Los eventos y comités deberán presupuestarse al menos en punto de equilibrio. | AB42: =AB33+'Dirección'!AB12 -> 1004784.9

Sheet T&IC
C2: Trade & Investment Center | D2: 46023 | E2: 46023 | F2: 46054 | G2: 46054 | H2: 46082 | I2: 46082 | J2: 46113 | K2: 46113 | L2: 46143 | M2: 46143 | N2: 46174 | O2: 46174 | P2: 46204 | Q2: 46204 | R2: 46235 | S2: 46235 | T2: 46266 | U2: 46266 | V2: 46296 | W2: 46296 | X2: 46327 | Y2: 46327 | Z2: 46357 | AA2: 46357 | AB2: 2026
C4: Ingresos T&IC
AC5: No se considera Selec USA
B6: 407-001-000-00 | C6: SemiconWest | D6: 0 | E6: 0 | F6: 0 | G6: 0 | H6: 0 | I6: 0 | J6: 0 | K6: 0 | L6: 0 | M6: 0 | N6: 0 | O6: 0 | P6: 0 | Q6: 0 | R6: 0 | S6: 0 | T6: 0 | U6: 0 | V6: 50000 | W6: 0 | X6: 0 | Y6: 0 | Z6: 0 | AA6: 0 | AB6: =D6+F6+H6+J6+L6+N6+P6+R6+T6+V6+X6+Z6 -> 50000 | AC6: Cierran en $50K | AE6: No procede
B7: 407-002-000-00 | C7: Ingresos 2 | D7: 0 | E7: 0 | F7: 0 | G7: 0 | H7: 0 | I7: 0 | J7: 0 | K7: 0 | L7: 0 | M7: 0 | N7: 0 | O7: 0 | P7: 0 | Q7: 0 | R7: 0 | S7: 0 | T7: 0 | U7: 0 | V7: 0 | W7: 0 | X7: 0 | Y7: 0 | Z7: 0 | AA7: 0 | AB7: =D7+F7+H7+J7+L7+N7+P7+R7+T7+V7+X7+Z7 -> 0
C8: Suma de Ingresos T&IC | D8: =SUM(D6:D7) -> 0 | E8: =SUM(E6:E7) -> 0 | F8: =SUM(F6:F7) -> 0 | G8: =SUM(G6:G7) -> 0 | H8: =SUM(H6:H7) -> 0 | I8: =SUM(I6:I7) -> 0 | J8: =SUM(J6:J7) -> 0 | K8: =SUM(K6:K7) -> 0 | ... AB8: =SUM(AB6:AB7) -> 50000
C10: Gastos T&IC
B11: 703-001-000-00 | C11: SemiconWest | D11: 0 | E11: 0 | F11: 0 | G11: 0 | H11: 0 | I11: 0 | J11: 0 | K11: 0 | L11: 0 | M11: 0 | N11: 0 | O11: 0 | P11: 0 | Q11: 0 | R11: 0 | S11: 0 | T11: 0 | U11: 0 | V11: 25000 | W11: 0 | X11: 0 | Y11: 0 | Z11: 0 | AA11: 0 | AB11: =D11+F11+H11+J11+L11+N11+P11+R11+T11+V11+X11+Z11 -> 25000 | AC11: Cierran en $25K | AE11: No procede
B12: 703-002-000-00 | C12: Gastos 2 | D12: 0 | E12: 0 | F12: 0 | G12: 0 | H12: 0 | I12: 0 | J12: 0 | K12: 0 | L12: 0 | M12: 0 | N12: 0 | O12: 0 | P12: 0 | Q12: 0 | R12: 0 | S12: 0 | T12: 0 | U12: 0 | V12: 0 | W12: 0 | X12: 0 | Y12: 0 | Z12: 0 | AA12: 0 | AB12: =D12+F12+H12+J12+L12+N12+P12+R12+T12+V12+X12+Z12 -> 0
C13: Suma de Gastos T&IC | D13: =SUM(D11:D12) -> 0 | E13: =SUM(E11:E12) -> 0 | F13: =SUM(F11:F12) -> 0 | G13: =SUM(G11:G12) -> 0 | H13: =SUM(H11:H12) -> 0 | I13: =SUM(I11:I12) -> 0 | J13: =SUM(J11:J12) -> 0 | K13: =SUM(K11:K12) -> 0 | ... AB13: =SUM(AB11:AB12) -> 25000
C16: Resultado T&IC | D16: =D8-D13 -> 0 | E16: =E8-E13 -> 0 | F16: =F8-F13 -> 0 | G16: =G8-G13 -> 0 | H16: =H8-H13 -> 0 | I16: =I8-I13 -> 0 | J16: =J8-J13 -> 0 | K16: =K8-K13 -> 0 | ... AB16: =AB8-AB13 -> 25000 | AC16: $25K

Sheet Eventos
C2: EVENTOS | D2: 46023 | E2: 46023 | F2: 46054 | G2: 46054 | H2: 46082 | I2: 46082 | J2: 46113 | K2: 46113 | L2: 46143 | M2: 46143 | N2: 46174 | O2: 46174 | P2: 46204 | Q2: 46204 | R2: 46235 | S2: 46235 | T2: 46266 | U2: 46266 | V2: 46296 | W2: 46296 | X2: 46327 | Y2: 46327 | Z2: 46357 | AA2: 46357 | AB2: 2026
C4: Ingresos Eventos
C5: Boletaje
B6: 405-002-000-00 | C6: Asamblea Anual | D6: 0 | E6: 0 | F6: 0 | G6: 0 | H6: 220000 | I6: 0 | J6: 30000 | K6: 0 | L6: 0 | M6: 0 | N6: 0 | O6: 0 | P6: 0 | Q6: 0 | R6: 0 | S6: 0 | T6: 0 | U6: 0 | V6: 0 | W6: 0 | X6: 0 | Y6: 0 | Z6: 0 | AA6: 0 | AB6: =D6+F6+H6+J6+L6+N6+P6+R6+T6+V6+X6+Z6 -> 250000 | AD6: =AB6+AB21-AB38 -> 150000
B7: 405-001-000-00 | C7: Torneo Golf | D7: 475000 | E7: 0 | F7: 25000 | G7: 0 | H7: 0 | I7: 0 | J7: 0 | K7: 0 | L7: 0 | M7: 0 | N7: 0 | O7: 0 | P7: 0 | Q7: 0 | R7: 0 | S7: 0 | T7: 0 | U7: 0 | V7: 0 | W7: 0 | X7: 0 | Y7: 0 | Z7: 0 | AA7: 0 | AB7: =D7+F7+H7+J7+L7+N7+P7+R7+T7+V7+X7+Z7 -> 500000 | AD7: =AB7+AB22-AB39 -> 150000
B8: 405-009-000-00 | C8: Cumbre Empresarios | D8: 0 | E8: 0 | F8: 0 | G8: 0 | H8: 0 | I8: 0 | J8: 0 | K8: 0 | L8: 0 | M8: 0 | N8: 0 | O8: 0 | P8: 0 | Q8: 0 | R8: 0 | S8: 0 | T8: 0 | U8: 0 | V8: 90000 | W8: 0 | X8: 10000 | Y8: 0 | Z8: 0 | AA8: 0 | AB8: =D8+F8+H8+J8+L8+N8+P8+R8+T8+V8+X8+Z8 -> 100000 | AD8: =AB8+AB23-AB40 -> 150000
B9: 405-010-000-00 | C9: Foros (Talento) | D9: 0 | E9: 0 | F9: 0 | G9: 0 | H9: 60000 | I9: 0 | J9: 0 | K9: 0 | L9: 0 | M9: 0 | N9: 0 | O9: 0 | P9: 0 | Q9: 0 | R9: 0 | S9: 0 | T9: 0 | U9: 0 | V9: 0 | W9: 0 | X9: 0 | Y9: 0 | Z9: 0 | AA9: 0 | AB9: =D9+F9+H9+J9+L9+N9+P9+R9+T9+V9+X9+Z9 -> 60000 | AD9: =AB9+AB24-AB41 -> 120000
B10: 405-013-000-00 | C10: The North America Week | D10: 0 | E10: 0 | F10: 0 | G10: 0 | H10: 0 | I10: 0 | J10: 0 | K10: 0 | L10: 35000 | M10: 0 | N10: 5000 | O10: 0 | P10: 0 | Q10: 0 | R10: 0 | S10: 0 | T10: 0 | U10: 0 | V10: 0 | W10: 0 | X10: 0 | Y10: 0 | Z10: 0 | AA10: 0 | AB10: =D10+F10+H10+J10+L10+N10+P10+R10+T10+V10+X10+Z10 -> 40000 | AD10: =AB10+AB25-AB42 -> 150000
B11: 405-014-000-00 | C11: Jalisco Travel Fest | D11: 0 | E11: 0 | F11: 0 | G11: 0 | H11: 0 | I11: 0 | J11: 0 | K11: 0 | L11: 40000 | M11: 0 | N11: 0 | O11: 0 | P11: 0 | Q11: 0 | R11: 0 | S11: 0 | T11: 0 | U11: 0 | V11: 0 | W11: 0 | X11: 0 | Y11: 0 | Z11: 0 | AA11: 0 | AB11: =D11+F11+H11+J11+L11+N11+P11+R11+T11+V11+X11+Z11 -> 40000 | AD11: =AB11+AB26-AB43 -> 110000
B12: 405-005-000-00 | C12: Open House | D12: 0 | E12: 0 | F12: 0 | G12: 0 | H12: 0 | I12: 0 | J12: 0 | K12: 0 | L12: 0 | M12: 0 | N12: 0 | O12: 0 | P12: 0 | Q12: 0 | R12: 0 | S12: 0 | T12: 0 | U12: 0 | V12: 0 | W12: 0 | X12: 0 | Y12: 0 | Z12: 0 | AA12: 0 | AB12: =D12+F12+H12+J12+L12+N12+P12+R12+T12+V12+X12+Z12 -> 0 | AD12: =AB12+AB27-AB44 -> 150000
B13: 405-007-000-00 | C13: Extend Our Reach | D13: 0 | E13: 0 | F13: 0 | G13: 0 | H13: 0 | I13: 0 | J13: 0 | K13: 0 | L13: 0 | M13: 0 | N13: 0 | O13: 0 | P13: 0 | Q13: 0 | R13: 0 | S13: 0 | T13: 0 | U13: 0 | V13: 0 | W13: 0 | X13: 0 | Y13: 0 | Z13: 0 | AA13: 0 | AB13: =D13+F13+H13+J13+L13+N13+P13+R13+T13+V13+X13+Z13 -> 0 | AD13: =AB13+AB28-AB45 -> 0
B14: 405-004-000-00 | C14: Cocteles | D14: 0 | E14: 0 | F14: 0 | G14: 0 | H14: 0 | I14: 0 | J14: 0 | K14: 0 | L14: 0 | M14: 0 | N14: 0 | O14: 0 | P14: 0 | Q14: 0 | R14: 0 | S14: 0 | T14: 0 | U14: 0 | V14: 0 | W14: 0 | X14: 0 | Y14: 0 | Z14: 0 | AA14: 0 | AB14: =D14+F14+H14+J14+L14+N14+P14+R14+T14+V14+X14+Z14 -> 0 | AD14: =AB14+AB29-AB46 -> 0
B15: 405-015-000-00 | C15: Cena Gala | D15: 0 | E15: 0 | F15: 0 | G15: 0 | H15: 0 | I15: 0 | J15: 0 | K15: 0 | L15: 0 | M15: 0 | N15: 0 | O15: 0 | P15: 0 | Q15: 0 | R15: 0 | S15: 0 | T15: 0 | U15: 0 | V15: 0 | W15: 0 | X15: 0 | Y15: 0 | Z15: 200000 | AA15: 0 | AB15: =D15+F15+H15+J15+L15+N15+P15+R15+T15+V15+X15+Z15 -> 200000 | AD15: =AB15+AB30-AB47 -> 150000
B16: 405-016-000-00 | C16: Top Circle | D16: 0 | E16: 0 | F16: 0 | G16: 0 | H16: 0 | I16: 0 | J16: 0 | K16: 0 | L16: 0 | M16: 0 | N16: 0 | O16: 0 | P16: 0 | Q16: 0 | R16: 0 | S16: 0 | T16: 0 | U16: 0 | V16: 0 | W16: 0 | X16: 0 | Y16: 0 | Z16: 0 | AA16: 0 | AB16: =D16+F16+H16+J16+L16+N16+P16+R16+T16+V16+X16+Z16 -> 0 | AD16: =AB16+AB31-AB49 -> 50000
B17: 405-012-000-00 | C17: Jornada de Reforestación | D17: 0 | E17: 0 | F17: 0 | G17: 0 | H17: 0 | I17: 0 | J17: 0 | K17: 0 | L17: 0 | M17: 0 | N17: 0 | O17: 0 | P17: 0 | Q17: 0 | R17: 0 | S17: 0 | T17: 0 | U17: 0 | V17: 0 | W17: 0 | X17: 0 | Y17: 0 | Z17: 0 | AA17: 0 | AB17: =D17+F17+H17+J17+L17+N17+P17+R17+T17+V17+X17+Z17 -> 0 | AD17: =AB17+AB32-AB49 -> 0
C18: Ingresos Boletaje | D18: =SUM(D6:D17) -> 475000 | E18: =SUM(E6:E17) -> 0 | F18: =SUM(F6:F17) -> 25000 | G18: =SUM(G6:G17) -> 0 | H18: =SUM(H6:H17) -> 280000 | I18: =SUM(I6:I17) -> 0 | J18: =SUM(J6:J17) -> 30000 | K18: =SUM(K6:K17) -> 0 | ... AB18: =SUM(AB6:AB17) -> 1190000
C20: Patrocinios
B21: 406-002-000-00 | C21: Asamblea Anual | D21: 0 | E21: 0 | F21: 0 | G21: 0 | H21: 300000 | I21: 0 | J21: 50000 | K21: 0 | L21: 0 | M21: 0 | N21: 0 | O21: 0 | P21: 0 | Q21: 0 | R21: 0 | S21: 0 | T21: 0 | U21: 0 | V21: 0 | W21: 0 | X21: 0 | Y21: 0 | Z21: 0 | AA21: 0 | AB21: =D21+F21+H21+J21+L21+N21+P21+R21+T21+V21+X21+Z21 -> 350000
